Workbook

Sheet Kubiņu masa
B4: 45393
E5: mo-abs sausa, žavskapī 50C/3h
B7: Gaisa mitrums: | E7: 0.5 | H7: 0.6 | K7: 0.7 | M7: 0.8 | P7: 0.9 | S7: 0.95
B8: Temperatūra: | D8: 23oC | E8: 23oC | F8: 23oC | G8: 23oC | H8: 23oC | I8: 23oC | J8: 23oC | K8: 23oC | L8: 23oC | M8: 23oC | N8: 23oC | O8: 23oC | P8: 23oC | Q8: 23oC | R8: 23oC | S8: 23oC | T8: 23oC | U8: 23oC
B9: Paraugi | D9: 45608 | E9: 45609 | F9: 15.11.24 | G9: 19.11.24 | H9: 20.11.24 | I9: 22.11.24 | J9: 25.11.24 | K9: 26.11.24 | L9: 27.11.24 | M9: 29.11.24 | N9: 02.12.24 | O9: 03.12.24 | P9: 04.12.24 | Q9: 06.12.24 | R9: 09.12.24 | S9: 10.12.24 | T9: 11.12.24 | U9: 16.12.24
A10: apstrāde | D10: mo*
A11: bez apstrādes | B11: Sl1 | C11: 316 | D11: 6.617 | E11: 6.98 | F11: 6.98 | G11: 6.96 | H11: 7.04 | I11: 7.05 | J11: 7.05 | K11: 7.15 | L11: 7.15 | M11: 7.35 | N11: 7.35 | O11: 7.35 | P11: 7.63 | Q11: 7.69 | R11: 7.69 | S11: 7.94 | T11: 7.95 | U11: 7.87
C12: 320 | D12: 6.473 | E12: 6.84 | F12: 6.84 | G12: 6.83 | H12: 6.89 | I12: 6.92 | J12: 6.92 | K12: 6.99 | L12: 6.98 | M12: 7.19 | N12: 7.19 | O12: 7.2 | P12: 7.46 | Q12: 7.54 | R12: 7.54 | S12: 7.76 | T12: 7.78 | U12: 7.68
C13: 325 | D13: 6.128 | E13: 6.46 | F13: 6.46 | G13: 6.47 | H13: 6.45 | I13: 6.54 | J13: 6.54 | K13: 6.61 | L13: 6.51 | M13: 6.81 | N13: 6.81 | O13: 6.81 | P13: 7.05 | Q13: 7.15 | R13: 7.13 | S13: 7.35 | T13: 7.35 | U13: 7.27
B14: Sl2 | C14: 332 | D14: 3.74 | E14: 3.94 | F14: 3.94 | G14: 3.91 | H14: 3.94 | I14: 4 | J14: 3.97 | K14: 4.02 | L14: 4.01 | M14: 4.15 | N14: 4.15 | O14: 4.14 | P14: 4.31 | Q14: 4.36 | R14: 4.35 | S14: 4.52 | T14: 4.51 | U14: 4.4
C15: 336 | D15: 3.827 | E15: 4.04 | F15: 4.04 | G15: 4.02 | H15: 4.07 | I15: 4.09 | J15: 4.07 | K15: 4.14 | L15: 4.12 | M15: 4.25 | N15: 4.25 | O15: 4.24 | P15: 4.41 | Q15: 4.47 | R15: 4.45 | S15: 4.61 | T15: 4.6 | U15: 4.49
C16: 341 | D16: 3.634 | E16: 3.84 | F16: 3.83 | G16: 3.83 | H16: 3.86 | I16: 3.86 | J16: 3.85 | K16: 3.92 | L16: 3.9 | M16: 4.04 | N16: 4.04 | O16: 4.03 | P16: 4.17 | Q16: 4.26 | R16: 4.22 | S16: 4.4 | T16: 4.36 | U16: 4.3
B17: Sl3 | C17: 348 | D17: 5.153 | E17: 5.41 | F17: 5.43 | G17: 5.42 | H17: 5.44 | I17: 5.47 | J17: 5.46 | K17: 5.54 | L17: 5.53 | M17: 5.7 | N17: 5.7 | O17: 5.71 | P17: 5.95 | Q17: 6 | R17: 5.99 | S17: 6.18 | T17: 6.16 | U17: 6.09
C18: 352 | D18: 5.241 | E18: 5.54 | F18: 5.52 | G18: 5.52 | H18: 5.56 | I18: 5.58 | J18: 5.57 | K18: 5.65 | L18: 5.64 | M18: 5.81 | N18: 5.81 | O18: 5.82 | P18: 6.05 | Q18: 6.12 | R18: 6.1 | S18: 6.29 | T18: 6.3 | U18: 6.23
C19: 357 | D19: 5.155 | E19: 5.43 | F19: 5.4 | G19: 5.43 | H19: 5.48 | I19: 5.48 | J19: 5.49 | K19: 5.55 | L19: 5.57 | M19: 5.72 | N19: 5.72 | O19: 5.72 | P19: 5.93 | Q19: 5.99 | R19: 5.98 | S19: 6.19 | T19: 6.2 | U19: 6.06
B20: Sl4 | C20: 368 | D20: 5.737 | E20: 6.05 | F20: 6.02 | G20: 6.04 | H20: 6.1 | I20: 6.13 | J20: 6.12 | K20: 6.2 | L20: 6.19 | M20: 6.36 | N20: 6.36 | O20: 6.35 | P20: 6.51 | Q20: 6.59 | R20: 6.58 | S20: 6.74 | T20: 6.72 | U20: 6.74
C21: 372 | D21: 6.177 | E21: 6.53 | F21: 6.49 | G21: 6.51 | H21: 6.58 | I21: 6.6 | J21: 6.58 | K21: 6.69 | L21: 6.68 | M21: 6.86 | N21: 6.86 | O21: 6.85 | P21: 7.03 | Q21: 7.1 | R21: 7.09 | S21: 7.28 | T21: 7.28 | U21: 7.28
C22: 377 | D22: 6.033 | E22: 6.33 | F22: 6.33 | G22: 6.35 | H22: 6.42 | I22: 6.44 | J22: 6.44 | K22: 6.52 | L22: 6.5 | M22: 6.7 | N22: 6.7 | O22: 6.68 | P22: 6.84 | Q22: 6.92 | R22: 6.91 | S22: 7.13 | T22: 7.1 | U22: 7.09
B23: Sa1 | C23: 384 | D23: 2.877 | E23: 3.01 | F23: 2.97 | G23: 3 | H23: 3.04 | I23: 3.05 | J23: 3.02 | K23: 3.07 | L23: 3.06 | M23: 3.18 | N23: 3.18 | O23: 3.16 | P23: 3.31 | Q23: 3.34 | R23: 3.34 | S23: 3.54 | T23: 3.46 | U23: 3.4
C24: 387 | D24: 3.04 | E24: 3.19 | F24: 3.17 | G24: 3.17 | H24: 3.21 | I24: 3.22 | J24: 3.2 | K24: 3.25 | L24: 3.25 | M24: 3.34 | N24: 3.34 | O24: 3.35 | P24: 3.5 | Q24: 3.55 | R24: 3.54 | S24: 3.71 | T24: 3.7 | U24: 3.59
C25: 392 | D25: 3.161 | E25: 3.31 | F25: 3.29 | G25: 3.32 | H25: 3.34 | I25: 3.35 | J25: 3.33 | K25: 3.38 | L25: 3.37 | M25: 3.48 | N25: 3.48 | O25: 3.47 | P25: 3.61 | Q25: 3.69 | R25: 3.67 | S25: 3.85 | T25: 3.82 | U25: 3.73
B26: Sa2 | C26: 399 | D26: 3.139 | E26: 3.28 | F26: 3.29 | G26: 3.29 | H26: 3.33 | I26: 3.34 | J26: 3.32 | K26: 3.36 | L26: 3.36 | M26: 3.48 | N26: 3.48 | O26: 3.48 | P26: 3.6 | Q26: 3.68 | R26: 3.65 | S26: 3.84 | T26: 3.77 | U26: 3.61
C27: 403 | D27: 3.21 | E27: 3.39 | F27: 3.36 | G27: 3.37 | H27: 3.41 | I27: 3.41 | J27: 3.39 | K27: 3.45 | L27: 3.44 | M27: 3.56 | N27: 3.56 | O27: 3.55 | P27: 3.66 | Q27: 3.74 | R27: 3.71 | S27: 3.9 | T27: 3.89 | U27: 3.78
C28: 408 | D28: 3.124 | E28: 3.29 | F28: 3.27 | G28: 3.25 | H28: 3.3 | I28: 3.31 | J28: 3.3 | K28: 3.34 | L28: 3.33 | M28: 3.42 | N28: 3.42 | O28: 3.44 | P28: 3.54 | Q28: 3.65 | R28: 3.5 | S28: 3.78 | T28: 3.74 | U28: 3.65
B29: Sa3 | C29: 419 | D29: 4.028 | E29: 4.19 | F29: 4.22 | G29: 4.24 | H29: 4.26 | I29: 4.28 | J29: 4.26 | K29: 4.31 | L29: 4.29 | M29: 4.4 | N29: 4.4 | O29: 4.41 | P29: 4.59 | Q29: 4.67 | R29: 4.66 | S29: 4.84 | T29: 4.82 | U29: 4.71
C30: 423 | D30: 4.088 | E30: 4.3 | F30: 4.28 | G30: 4.29 | H30: 4.31 | I30: 4.34 | J30: 4.33 | K30: 4.38 | L30: 4.37 | M30: 4.47 | N30: 4.47 | O30: 4.48 | P30: 4.63 | Q30: 4.74 | R30: 4.71 | S30: 4.89 | T30: 4.89 | U30: 4.74
C31: 428 | D31: 3.837 | E31: 4.04 | F31: 4.01 | G31: 4.02 | H31: 4.07 | I31: 4.08 | J31: 4.06 | K31: 4.1 | L31: 4.09 | M31: 4.19 | N31: 4.19 | O31: 4.2 | P31: 4.34 | Q31: 4.42 | R31: 4.4 | S31: 4.57 | T31: 4.58 | U31: 4.37
B32: Sa4 | C32: 439 | D32: 2.877 | E32: 3 | F32: 2.99 | G32: 3 | H32: 3.03 | I32: 3.04 | J32: 3.02 | K32: 3.06 | L32: 3.04 | M32: 3.12 | N32: 3.12 | O32: 3.12 | P32: 3.25 | Q32: 3.27 | R32: 3.25 | S32: 3.35 | T32: 3.34 | U32: 3.3
C33: 443 | D33: 2.91 | E33: 3.02 | F33: 3.03 | G33: 3.04 | H33: 3.05 | I33: 3.09 | J33: 3.05 | K33: 3.08 | L33: 3.07 | M33: 3.16 | N33: 3.16 | O33: 3.15 | P33: 3.28 | Q33: 3.3 | R33: 3.28 | S33: 3.38 | T33: 3.36 | U33: 3.32
C34: 448 | D34: 2.843 | E34: 2.97 | F34: 2.93 | G34: 2.95 | H34: 2.98 | I34: 3 | J34: 2.96 | K34: 3 | L34: 3 | M34: 3.06 | N34: 3.06 | O34: 3.06 | P34: 3.15 | Q34: 3.21 | R34: 3.17 | S34: 3.28 | T34: 3.29 | U34: 3.23
A35: hito apstrāde | B35: Sl11 | C35: 295 | D35: 5.055 | E35: 5.13 | F35: 5.1 | G35: 5.1 | H35: 5.15 | I35: 5.16 | J35: 5.14 | K35: 5.24 | L35: 5.25 | M35: 5.37 | N35: 5.37 | O35: 5.38 | P35: 5.64 | Q35: 5.66 | R35: 5.67 | S35: 5.9 | T35: 5.94 | U35: 5.71
C36: 298 | D36: 5.408 | E36: 5.5 | F36: 5.69 | G36: 5.68 | H36: 5.73 | I36: 5.74 | J36: 5.73 | K36: 5.84 | L36: 5.83 | M36: 6 | N36: 6 | O36: 5.99 | P36: 6.29 | Q36: 6.32 | R36: 6.31 | S36: 6.58 | T36: 6.6 | U36: 6.41
C37: 301 | D37: 5.218 | E37: 5.71 | F37: 5.49 | G37: 5.48 | H37: 5.53 | I37: 5.54 | J37: 5.54 | K37: 5.64 | L37: 5.65 | M37: 5.79 | N37: 5.79 | O37: 5.79 | P37: 6.07 | Q37: 6.09 | R37: 6.09 | S37: 6.34 | T37: 6.37 | U37: 6.2
B38: Sl - 22 | C38: 6 | D38: 3.724 | E38: 3.92 | F38: 3.95 | G38: 3.95 | H38: 3.99 | I38: 4 | J38: 3.98 | K38: 4.08 | L38: 4.08 | M38: 4.22 | N38: 4.21 | O38: 4.21 | P38: 4.44 | Q38: 4.47 | R38: 4.45 | S38: 4.7 | T38: 4.69 | U38: 4.36
C39: 10 | D39: 3.671 | E39: 3.88 | F39: 3.88 | G39: 3.87 | H39: 3.92 | I39: 3.92 | J39: 3.9 | K39: 4 | L39: 3.99 | M39: 4.11 | N39: 4.12 | O39: 4.11 | P39: 4.29 | Q39: 4.38 | R39: 4.35 | S39: 4.56 | T39: 4.56 | U39: 4.32
C40: 14 | D40: 3.865 | E40: 4.11 | F40: 4.08 | G40: 4.07 | H40: 4.12 | I40: 4.13 | J40: 4.11 | K40: 4.22 | L40: 4.21 | M40: 4.35 | N40: 4.34 | O40: 4.33 | P40: 4.55 | Q40: 4.61 | R40: 4.58 | S40: 4.82 | T40: 4.81 | U40: 4.61
B41: Sl - 23 | C41: 26 | D41: 4.22 | E41: 4.49 | F41: 4.46 | G41: 4.46 | H41: 4.51 | I41: 4.52 | J41: 4.49 | K41: 4.6 | L41: 4.6 | M41: 4.77 | N41: 4.75 | O41: 4.72 | P41: 5.04 | Q41: 5.09 | R41: 5.07 | S41: 5.4 | T41: 5.78 | U41: 5.1
C42: 30 | D42: 4.196 | E42: 4.44 | F42: 4.44 | G42: 4.45 | H42: 4.49 | I42: 4.51 | J42: 4.47 | K42: 4.58 | L42: 4.59 | M42: 4.73 | N42: 4.72 | O42: 4.71 | P42: 5.02 | Q42: 5.07 | R42: 5.05 | S42: 5.38 | T42: 5.37 | U42: 5.02
C43: 34 | D43: 4.231 | E43: 4.47 | F43: 4.47 | G43: 4.48 | H43: 4.51 | I43: 4.54 | J43: 4.5 | K43: 4.63 | L43: 4.62 | M43: 4.76 | N43: 4.76 | O43: 4.74 | P43: 5.03 | Q43: 5.07 | R43: 5.05 | S43: 5.3 | T43: 5.32 | U43: 4.92
B44: Sl - 31 | C44: 46 | D44: 5.044 | E44: 5.34 | F44: 5.35 | G44: 5.32 | H44: 5.35 | I44: 5.4 | J44: 5.37 | K44: 5.48 | L44: 5.47 | M44: 5.63 | N44: 5.64 | O44: 5.62 | P44: 5.86 | Q44: 5.92 | R44: 5.9 | S44: 6.1 | T44: 6.13 | U44: 5.98
...

Sheet Masas izmaiņa %
B1: Gaisa mitrums: | E1: 0.5 | H1: 0.6 | K1: 0.7 | M1: 0.8 | P1: 0.9 | S1: 0.95
B2: Temperatūra: | D2: 23oC | E2: 23oC | F2: 23oC | G2: 23oC | H2: 23oC | I2: 23oC | J2: 23oC | K2: 23oC | L2: 23oC | M2: 23oC | N2: 23oC | O2: 23oC | P2: 23oC | Q2: 23oC | R2: 23oC | S2: 23oC | T2: 23oC | U2: 23oC
B3: Paraugi | D3: 45608 | E3: 45609 | F3: 15.11.24 | G3: 19.11.24 | H3: 20.11.24 | I3: 22.11.24 | J3: 25.11.24 | K3: 26.11.24 | L3: 27.11.24 | M3: 29.11.24 | N3: 02.12.24 | O3: 03.12.24 | P3: 04.12.24 | Q3: 06.12.24 | R3: 09.12.24 | S3: 10.12.24 | T3: 11.12.24 | U3: 16.12.24
A4: apstrāde | D4: mo*
A5: bez apstrādes | B5: Sl1 | C5: 316 | D5: =('Kubiņu masa'!D11-'Kubiņu masa'!$D11)/'Kubiņu masa'!$D11*100 -> 0 | E5: =('Kubiņu masa'!E11-'Kubiņu masa'!$D11)/'Kubiņu masa'!$D11*100 -> 5.4858697 | F5: =('Kubiņu masa'!F11-'Kubiņu masa'!$D11)/'Kubiņu masa'!$D11*100 -> 5.4858697 | G5: =('Kubiņu masa'!G11-'Kubiņu masa'!$D11)/'Kubiņu masa'!$D11*100 -> 5.183618 | H5: =('Kubiņu masa'!H11-'Kubiņu masa'!$D11)/'Kubiņu masa'!$D11*100 -> 6.3926251 | I5: =('Kubiņu masa'!I11-'Kubiņu masa'!$D11)/'Kubiņu masa'!$D11*100 -> 6.5437509 | J5: =('Kubiņu masa'!J11-'Kubiņu masa'!$D11)/'Kubiņu masa'!$D11*100 -> 6.5437509 | K5: =('Kubiņu masa'!K11-'Kubiņu masa'!$D11)/'Kubiņu masa'!$D11*100 -> 8.0550098 | ... U5: =('Kubiņu masa'!U11-'Kubiņu masa'!$D11)/'Kubiņu masa'!$D11*100 -> 18.936074
C6: 320 | D6: =('Kubiņu masa'!D12-'Kubiņu masa'!$D12)/'Kubiņu masa'!$D12*100 -> 0 | E6: =('Kubiņu masa'!E12-'Kubiņu masa'!$D12)/'Kubiņu masa'!$D12*100 -> 5.6697049 | F6: =('Kubiņu masa'!F12-'Kubiņu masa'!$D12)/'Kubiņu masa'!$D12*100 -> 5.6697049 | G6: =('Kubiņu masa'!G12-'Kubiņu masa'!$D12)/'Kubiņu masa'!$D12*100 -> 5.5152171 | H6: =('Kubiņu masa'!H12-'Kubiņu masa'!$D12)/'Kubiņu masa'!$D12*100 -> 6.4421443 | I6: =('Kubiņu masa'!I12-'Kubiņu masa'!$D12)/'Kubiņu masa'!$D12*100 -> 6.9056079 | J6: =('Kubiņu masa'!J12-'Kubiņu masa'!$D12)/'Kubiņu masa'!$D12*100 -> 6.9056079 | K6: =('Kubiņu masa'!K12-'Kubiņu masa'!$D12)/'Kubiņu masa'!$D12*100 -> 7.987023 | ... U6: =('Kubiņu masa'!U12-'Kubiņu masa'!$D12)/'Kubiņu masa'!$D12*100 -> 18.646686
C7: 325 | D7: =('Kubiņu masa'!D13-'Kubiņu masa'!$D13)/'Kubiņu masa'!$D13*100 -> 0 | E7: =('Kubiņu masa'!E13-'Kubiņu masa'!$D13)/'Kubiņu masa'!$D13*100 -> 5.4177546 | F7: =('Kubiņu masa'!F13-'Kubiņu masa'!$D13)/'Kubiņu masa'!$D13*100 -> 5.4177546 | G7: =('Kubiņu masa'!G13-'Kubiņu masa'!$D13)/'Kubiņu masa'!$D13*100 -> 5.5809399 | H7: =('Kubiņu masa'!H13-'Kubiņu masa'!$D13)/'Kubiņu masa'!$D13*100 -> 5.2545692 | I7: =('Kubiņu masa'!I13-'Kubiņu masa'!$D13)/'Kubiņu masa'!$D13*100 -> 6.7232376 | J7: =('Kubiņu masa'!J13-'Kubiņu masa'!$D13)/'Kubiņu masa'!$D13*100 -> 6.7232376 | K7: =('Kubiņu masa'!K13-'Kubiņu masa'!$D13)/'Kubiņu masa'!$D13*100 -> 7.8655352 | ... U7: =('Kubiņu masa'!U13-'Kubiņu masa'!$D13)/'Kubiņu masa'!$D13*100 -> 18.63577
B8: Sl2 | C8: 332 | D8: =('Kubiņu masa'!D14-'Kubiņu masa'!$D14)/'Kubiņu masa'!$D14*100 -> 0 | E8: =('Kubiņu masa'!E14-'Kubiņu masa'!$D14)/'Kubiņu masa'!$D14*100 -> 5.3475936 | F8: =('Kubiņu masa'!F14-'Kubiņu masa'!$D14)/'Kubiņu masa'!$D14*100 -> 5.3475936 | G8: =('Kubiņu masa'!G14-'Kubiņu masa'!$D14)/'Kubiņu masa'!$D14*100 -> 4.5454545 | H8: =('Kubiņu masa'!H14-'Kubiņu masa'!$D14)/'Kubiņu masa'!$D14*100 -> 5.3475936 | I8: =('Kubiņu masa'!I14-'Kubiņu masa'!$D14)/'Kubiņu masa'!$D14*100 -> 6.9518717 | J8: =('Kubiņu masa'!J14-'Kubiņu masa'!$D14)/'Kubiņu masa'!$D14*100 -> 6.1497326 | K8: =('Kubiņu masa'!K14-'Kubiņu masa'!$D14)/'Kubiņu masa'!$D14*100 -> 7.486631 | ... U8: =('Kubiņu masa'!U14-'Kubiņu masa'!$D14)/'Kubiņu masa'!$D14*100 -> 17.647059
C9: 336 | D9: =('Kubiņu masa'!D15-'Kubiņu masa'!$D15)/'Kubiņu masa'!$D15*100 -> 0 | E9: =('Kubiņu masa'!E15-'Kubiņu masa'!$D15)/'Kubiņu masa'!$D15*100 -> 5.5657173 | F9: =('Kubiņu masa'!F15-'Kubiņu masa'!$D15)/'Kubiņu masa'!$D15*100 -> 5.5657173 | G9: =('Kubiņu masa'!G15-'Kubiņu masa'!$D15)/'Kubiņu masa'!$D15*100 -> 5.0431147 | H9: =('Kubiņu masa'!H15-'Kubiņu masa'!$D15)/'Kubiņu masa'!$D15*100 -> 6.3496211 | I9: =('Kubiņu masa'!I15-'Kubiņu masa'!$D15)/'Kubiņu masa'!$D15*100 -> 6.8722237 | J9: =('Kubiņu masa'!J15-'Kubiņu masa'!$D15)/'Kubiņu masa'!$D15*100 -> 6.3496211 | K9: =('Kubiņu masa'!K15-'Kubiņu masa'!$D15)/'Kubiņu masa'!$D15*100 -> 8.1787301 | ... U9: =('Kubiņu masa'!U15-'Kubiņu masa'!$D15)/'Kubiņu masa'!$D15*100 -> 17.324275
C10: 341 | D10: =('Kubiņu masa'!D16-'Kubiņu masa'!$D16)/'Kubiņu masa'!$D16*100 -> 0 | E10: =('Kubiņu masa'!E16-'Kubiņu masa'!$D16)/'Kubiņu masa'!$D16*100 -> 5.6686846 | F10: =('Kubiņu masa'!F16-'Kubiņu masa'!$D16)/'Kubiņu masa'!$D16*100 -> 5.3935058 | G10: =('Kubiņu masa'!G16-'Kubiņu masa'!$D16)/'Kubiņu masa'!$D16*100 -> 5.3935058 | H10: =('Kubiņu masa'!H16-'Kubiņu masa'!$D16)/'Kubiņu masa'!$D16*100 -> 6.2190424 | I10: =('Kubiņu masa'!I16-'Kubiņu masa'!$D16)/'Kubiņu masa'!$D16*100 -> 6.2190424 | J10: =('Kubiņu masa'!J16-'Kubiņu masa'!$D16)/'Kubiņu masa'!$D16*100 -> 5.9438635 | K10: =('Kubiņu masa'!K16-'Kubiņu masa'!$D16)/'Kubiņu masa'!$D16*100 -> 7.8701156 | ... U10: =('Kubiņu masa'!U16-'Kubiņu masa'!$D16)/'Kubiņu masa'!$D16*100 -> 18.326912
B11: Sl3 | C11: 348 | D11: =('Kubiņu masa'!D17-'Kubiņu masa'!$D17)/'Kubiņu masa'!$D17*100 -> 0 | E11: =('Kubiņu masa'!E17-'Kubiņu masa'!$D17)/'Kubiņu masa'!$D17*100 -> 4.987386 | F11: =('Kubiņu masa'!F17-'Kubiņu masa'!$D17)/'Kubiņu masa'!$D17*100 -> 5.3755094 | G11: =('Kubiņu masa'!G17-'Kubiņu masa'!$D17)/'Kubiņu masa'!$D17*100 -> 5.1814477 | H11: =('Kubiņu masa'!H17-'Kubiņu masa'!$D17)/'Kubiņu masa'!$D17*100 -> 5.5695711 | I11: =('Kubiņu masa'!I17-'Kubiņu masa'!$D17)/'Kubiņu masa'!$D17*100 -> 6.1517563 | J11: =('Kubiņu masa'!J17-'Kubiņu masa'!$D17)/'Kubiņu masa'!$D17*100 -> 5.9576945 | K11: =('Kubiņu masa'!K17-'Kubiņu masa'!$D17)/'Kubiņu masa'!$D17*100 -> 7.5101882 | ... U11: =('Kubiņu masa'!U17-'Kubiņu masa'!$D17)/'Kubiņu masa'!$D17*100 -> 18.183582
C12: 352 | D12: =('Kubiņu masa'!D18-'Kubiņu masa'!$D18)/'Kubiņu masa'!$D18*100 -> 0 | E12: =('Kubiņu masa'!E18-'Kubiņu masa'!$D18)/'Kubiņu masa'!$D18*100 -> 5.7050181 | F12: =('Kubiņu masa'!F18-'Kubiņu masa'!$D18)/'Kubiņu masa'!$D18*100 -> 5.3234116 | G12: =('Kubiņu masa'!G18-'Kubiņu masa'!$D18)/'Kubiņu masa'!$D18*100 -> 5.3234116 | H12: =('Kubiņu masa'!H18-'Kubiņu masa'!$D18)/'Kubiņu masa'!$D18*100 -> 6.0866247 | I12: =('Kubiņu masa'!I18-'Kubiņu masa'!$D18)/'Kubiņu masa'!$D18*100 -> 6.4682313 | J12: =('Kubiņu masa'!J18-'Kubiņu masa'!$D18)/'Kubiņu masa'!$D18*100 -> 6.277428 | K12: =('Kubiņu masa'!K18-'Kubiņu masa'!$D18)/'Kubiņu masa'!$D18*100 -> 7.8038542 | ... U12: =('Kubiņu masa'!U18-'Kubiņu masa'!$D18)/'Kubiņu masa'!$D18*100 -> 18.870445
C13: 357 | D13: =('Kubiņu masa'!D19-'Kubiņu masa'!$D19)/'Kubiņu masa'!$D19*100 -> 0 | E13: =('Kubiņu masa'!E19-'Kubiņu masa'!$D19)/'Kubiņu masa'!$D19*100 -> 5.3346266 | F13: =('Kubiņu masa'!F19-'Kubiņu masa'!$D19)/'Kubiņu masa'!$D19*100 -> 4.7526673 | G13: =('Kubiņu masa'!G19-'Kubiņu masa'!$D19)/'Kubiņu masa'!$D19*100 -> 5.3346266 | H13: =('Kubiņu masa'!H19-'Kubiņu masa'!$D19)/'Kubiņu masa'!$D19*100 -> 6.3045587 | I13: =('Kubiņu masa'!I19-'Kubiņu masa'!$D19)/'Kubiņu masa'!$D19*100 -> 6.3045587 | J13: =('Kubiņu masa'!J19-'Kubiņu masa'!$D19)/'Kubiņu masa'!$D19*100 -> 6.4985451 | K13: =('Kubiņu masa'!K19-'Kubiņu masa'!$D19)/'Kubiņu masa'!$D19*100 -> 7.6624636 | ... U13: =('Kubiņu masa'!U19-'Kubiņu masa'!$D19)/'Kubiņu masa'!$D19*100 -> 17.555771
B14: Sl4 | C14: 368 | D14: =('Kubiņu masa'!D20-'Kubiņu masa'!$D20)/'Kubiņu masa'!$D20*100 -> 0 | E14: =('Kubiņu masa'!E20-'Kubiņu masa'!$D20)/'Kubiņu masa'!$D20*100 -> 5.4558131 | F14: =('Kubiņu masa'!F20-'Kubiņu masa'!$D20)/'Kubiņu masa'!$D20*100 -> 4.9328918 | G14: =('Kubiņu masa'!G20-'Kubiņu masa'!$D20)/'Kubiņu masa'!$D20*100 -> 5.281506 | H14: =('Kubiņu masa'!H20-'Kubiņu masa'!$D20)/'Kubiņu masa'!$D20*100 -> 6.3273488 | I14: =('Kubiņu masa'!I20-'Kubiņu masa'!$D20)/'Kubiņu masa'!$D20*100 -> 6.8502702 | J14: =('Kubiņu masa'!J20-'Kubiņu masa'!$D20)/'Kubiņu masa'!$D20*100 -> 6.675963 | K14: =('Kubiņu masa'!K20-'Kubiņu masa'!$D20)/'Kubiņu masa'!$D20*100 -> 8.0704201 | ... U14: =('Kubiņu masa'!U20-'Kubiņu masa'!$D20)/'Kubiņu masa'!$D20*100 -> 17.483005
C15: 372 | D15: =('Kubiņu masa'!D21-'Kubiņu masa'!$D21)/'Kubiņu masa'!$D21*100 -> 0 | E15: =('Kubiņu masa'!E21-'Kubiņu masa'!$D21)/'Kubiņu masa'!$D21*100 -> 5.7147483 | F15: =('Kubiņu masa'!F21-'Kubiņu masa'!$D21)/'Kubiņu masa'!$D21*100 -> 5.0671847 | G15: =('Kubiņu masa'!G21-'Kubiņu masa'!$D21)/'Kubiņu masa'!$D21*100 -> 5.3909665 | H15: =('Kubiņu masa'!H21-'Kubiņu masa'!$D21)/'Kubiņu masa'!$D21*100 -> 6.5242027 | I15: =('Kubiņu masa'!I21-'Kubiņu masa'!$D21)/'Kubiņu masa'!$D21*100 -> 6.8479845 | J15: =('Kubiņu masa'!J21-'Kubiņu masa'!$D21)/'Kubiņu masa'!$D21*100 -> 6.5242027 | K15: =('Kubiņu masa'!K21-'Kubiņu masa'!$D21)/'Kubiņu masa'!$D21*100 -> 8.3050024 | ... U15: =('Kubiņu masa'!U21-'Kubiņu masa'!$D21)/'Kubiņu masa'!$D21*100 -> 17.856565
C16: 377 | D16: =('Kubiņu masa'!D22-'Kubiņu masa'!$D22)/'Kubiņu masa'!$D22*100 -> 0 | E16: =('Kubiņu masa'!E22-'Kubiņu masa'!$D22)/'Kubiņu masa'!$D22*100 -> 4.9229239 | F16: =('Kubiņu masa'!F22-'Kubiņu masa'!$D22)/'Kubiņu masa'!$D22*100 -> 4.9229239 | G16: =('Kubiņu masa'!G22-'Kubiņu masa'!$D22)/'Kubiņu masa'!$D22*100 -> 5.2544339 | H16: =('Kubiņu masa'!H22-'Kubiņu masa'!$D22)/'Kubiņu masa'!$D22*100 -> 6.414719 | I16: =('Kubiņu masa'!I22-'Kubiņu masa'!$D22)/'Kubiņu masa'!$D22*100 -> 6.7462291 | J16: =('Kubiņu masa'!J22-'Kubiņu masa'!$D22)/'Kubiņu masa'!$D22*100 -> 6.7462291 | K16: =('Kubiņu masa'!K22-'Kubiņu masa'!$D22)/'Kubiņu masa'!$D22*100 -> 8.0722692 | ... U16: =('Kubiņu masa'!U22-'Kubiņu masa'!$D22)/'Kubiņu masa'!$D22*100 -> 17.520305
B17: Sa1 | C17: 384 | D17: =('Kubiņu masa'!D23-'Kubiņu masa'!$D23)/'Kubiņu masa'!$D23*100 -> 0 | E17: =('Kubiņu masa'!E23-'Kubiņu masa'!$D23)/'Kubiņu masa'!$D23*100 -> 4.622871 | F17: =('Kubiņu masa'!F23-'Kubiņu masa'!$D23)/'Kubiņu masa'!$D23*100 -> 3.2325339 | G17: =('Kubiņu masa'!G23-'Kubiņu masa'!$D23)/'Kubiņu masa'!$D23*100 -> 4.2752868 | H17: =('Kubiņu masa'!H23-'Kubiņu masa'!$D23)/'Kubiņu masa'!$D23*100 -> 5.6656239 | I17: =('Kubiņu masa'!I23-'Kubiņu masa'!$D23)/'Kubiņu masa'!$D23*100 -> 6.0132082 | J17: =('Kubiņu masa'!J23-'Kubiņu masa'!$D23)/'Kubiņu masa'!$D23*100 -> 4.9704553 | K17: =('Kubiņu masa'!K23-'Kubiņu masa'!$D23)/'Kubiņu masa'!$D23*100 -> 6.7083768 | ... U17: =('Kubiņu masa'!U23-'Kubiņu masa'!$D23)/'Kubiņu masa'!$D23*100 -> 18.178658
C18: 387 | D18: =('Kubiņu masa'!D24-'Kubiņu masa'!$D24)/'Kubiņu masa'!$D24*100 -> 0 | E18: =('Kubiņu masa'!E24-'Kubiņu masa'!$D24)/'Kubiņu masa'!$D24*100 -> 4.9342105 | F18: =('Kubiņu masa'!F24-'Kubiņu masa'!$D24)/'Kubiņu masa'!$D24*100 -> 4.2763158 | G18: =('Kubiņu masa'!G24-'Kubiņu masa'!$D24)/'Kubiņu masa'!$D24*100 -> 4.2763158 | H18: =('Kubiņu masa'!H24-'Kubiņu masa'!$D24)/'Kubiņu masa'!$D24*100 -> 5.5921053 | I18: =('Kubiņu masa'!I24-'Kubiņu masa'!$D24)/'Kubiņu masa'!$D24*100 -> 5.9210526 | J18: =('Kubiņu masa'!J24-'Kubiņu masa'!$D24)/'Kubiņu masa'!$D24*100 -> 5.2631579 | K18: =('Kubiņu masa'!K24-'Kubiņu masa'!$D24)/'Kubiņu masa'!$D24*100 -> 6.9078947 | ... U18: =('Kubiņu masa'!U24-'Kubiņu masa'!$D24)/'Kubiņu masa'!$D24*100 -> 18.092105
C19: 392 | D19: =('Kubiņu masa'!D25-'Kubiņu masa'!$D25)/'Kubiņu masa'!$D25*100 -> 0 | E19: =('Kubiņu masa'!E25-'Kubiņu masa'!$D25)/'Kubiņu masa'!$D25*100 -> 4.7136982 | F19: =('Kubiņu masa'!F25-'Kubiņu masa'!$D25)/'Kubiņu masa'!$D25*100 -> 4.080987 | G19: =('Kubiņu masa'!G25-'Kubiņu masa'!$D25)/'Kubiņu masa'!$D25*100 -> 5.0300538 | H19: =('Kubiņu masa'!H25-'Kubiņu masa'!$D25)/'Kubiņu masa'!$D25*100 -> 5.6627649 | I19: =('Kubiņu masa'!I25-'Kubiņu masa'!$D25)/'Kubiņu masa'!$D25*100 -> 5.9791205 | J19: =('Kubiņu masa'!J25-'Kubiņu masa'!$D25)/'Kubiņu masa'!$D25*100 -> 5.3464094 | K19: =('Kubiņu masa'!K25-'Kubiņu masa'!$D25)/'Kubiņu masa'!$D25*100 -> 6.9281873 | ... U19: =('Kubiņu masa'!U25-'Kubiņu masa'!$D25)/'Kubiņu masa'!$D25*100 -> 18.000633
B20: Sa2 | C20: 399 | D20: =('Kubiņu masa'!D26-'Kubiņu masa'!$D26)/'Kubiņu masa'!$D26*100 -> 0 | E20: =('Kubiņu masa'!E26-'Kubiņu masa'!$D26)/'Kubiņu masa'!$D26*100 -> 4.4918764 | F20: =('Kubiņu masa'!F26-'Kubiņu masa'!$D26)/'Kubiņu masa'!$D26*100 -> 4.8104492 | G20: =('Kubiņu masa'!G26-'Kubiņu masa'!$D26)/'Kubiņu masa'!$D26*100 -> 4.8104492 | H20: =('Kubiņu masa'!H26-'Kubiņu masa'!$D26)/'Kubiņu masa'!$D26*100 -> 6.0847404 | I20: =('Kubiņu masa'!I26-'Kubiņu masa'!$D26)/'Kubiņu masa'!$D26*100 -> 6.4033132 | J20: =('Kubiņu masa'!J26-'Kubiņu masa'!$D26)/'Kubiņu masa'!$D26*100 -> 5.7661676 | K20: =('Kubiņu masa'!K26-'Kubiņu masa'!$D26)/'Kubiņu masa'!$D26*100 -> 7.0404587 | ... U20: =('Kubiņu masa'!U26-'Kubiņu masa'!$D26)/'Kubiņu masa'!$D26*100 -> 15.004779
C21: 403 | D21: =('Kubiņu masa'!D27-'Kubiņu masa'!$D27)/'Kubiņu masa'!$D27*100 -> 0 | E21: =('Kubiņu masa'!E27-'Kubiņu masa'!$D27)/'Kubiņu masa'!$D27*100 -> 5.6074766 | F21: =('Kubiņu masa'!F27-'Kubiņu masa'!$D27)/'Kubiņu masa'!$D27*100 -> 4.6728972 | G21: =('Kubiņu masa'!G27-'Kubiņu masa'!$D27)/'Kubiņu masa'!$D27*100 -> 4.9844237 | H21: =('Kubiņu masa'!H27-'Kubiņu masa'!$D27)/'Kubiņu masa'!$D27*100 -> 6.2305296 | I21: =('Kubiņu masa'!I27-'Kubiņu masa'!$D27)/'Kubiņu masa'!$D27*100 -> 6.2305296 | J21: =('Kubiņu masa'!J27-'Kubiņu masa'!$D27)/'Kubiņu masa'!$D27*100 -> 5.6074766 | K21: =('Kubiņu masa'!K27-'Kubiņu masa'!$D27)/'Kubiņu masa'!$D27*100 -> 7.4766355 | ... U21: =('Kubiņu masa'!U27-'Kubiņu masa'!$D27)/'Kubiņu masa'!$D27*100 -> 17.757009
C22: 408 | D22: =('Kubiņu masa'!D28-'Kubiņu masa'!$D28)/'Kubiņu masa'!$D28*100 -> 0 | E22: =('Kubiņu masa'!E28-'Kubiņu masa'!$D28)/'Kubiņu masa'!$D28*100 -> 5.3137004 | F22: =('Kubiņu masa'!F28-'Kubiņu masa'!$D28)/'Kubiņu masa'!$D28*100 -> 4.6734955 | G22: =('Kubiņu masa'!G28-'Kubiņu masa'!$D28)/'Kubiņu masa'!$D28*100 -> 4.0332907 | H22: =('Kubiņu masa'!H28-'Kubiņu masa'!$D28)/'Kubiņu masa'!$D28*100 -> 5.6338028 | I22: =('Kubiņu masa'!I28-'Kubiņu masa'!$D28)/'Kubiņu masa'!$D28*100 -> 5.9539052 | J22: =('Kubiņu masa'!J28-'Kubiņu masa'!$D28)/'Kubiņu masa'!$D28*100 -> 5.6338028 | K22: =('Kubiņu masa'!K28-'Kubiņu masa'!$D28)/'Kubiņu masa'!$D28*100 -> 6.9142125 | ... U22: =('Kubiņu masa'!U28-'Kubiņu masa'!$D28)/'Kubiņu masa'!$D28*100 -> 16.837388
B23: Sa3 | C23: 419 | D23: =('Kubiņu masa'!D29-'Kubiņu masa'!$D29)/'Kubiņu masa'!$D29*100 -> 0 | E23: =('Kubiņu masa'!E29-'Kubiņu masa'!$D29)/'Kubiņu masa'!$D29*100 -> 4.0218471 | F23: =('Kubiņu masa'!F29-'Kubiņu masa'!$D29)/'Kubiņu masa'!$D29*100 -> 4.7666336 | G23: =('Kubiņu masa'!G29-'Kubiņu masa'!$D29)/'Kubiņu masa'!$D29*100 -> 5.2631579 | H23: =('Kubiņu masa'!H29-'Kubiņu masa'!$D29)/'Kubiņu masa'!$D29*100 -> 5.7596822 | I23: =('Kubiņu masa'!I29-'Kubiņu masa'!$D29)/'Kubiņu masa'!$D29*100 -> 6.2562066 | J23: =('Kubiņu masa'!J29-'Kubiņu masa'!$D29)/'Kubiņu masa'!$D29*100 -> 5.7596822 | K23: =('Kubiņu masa'!K29-'Kubiņu masa'!$D29)/'Kubiņu masa'!$D29*100 -> 7.000993 | ... U23: =('Kubiņu masa'!U29-'Kubiņu masa'!$D29)/'Kubiņu masa'!$D29*100 -> 16.93148
C24: 423 | D24: =('Kubiņu masa'!D30-'Kubiņu masa'!$D30)/'Kubiņu masa'!$D30*100 -> 0 | E24: =('Kubiņu masa'!E30-'Kubiņu masa'!$D30)/'Kubiņu masa'!$D30*100 -> 5.18591 | F24: =('Kubiņu masa'!F30-'Kubiņu masa'!$D30)/'Kubiņu masa'!$D30*100 -> 4.6966732 | G24: =('Kubiņu masa'!G30-'Kubiņu masa'!$D30)/'Kubiņu masa'!$D30*100 -> 4.9412916 | H24: =('Kubiņu masa'!H30-'Kubiņu masa'!$D30)/'Kubiņu masa'!$D30*100 -> 5.4305284 | I24: =('Kubiņu masa'!I30-'Kubiņu masa'!$D30)/'Kubiņu masa'!$D30*100 -> 6.1643836 | J24: =('Kubiņu masa'!J30-'Kubiņu masa'!$D30)/'Kubiņu masa'!$D30*100 -> 5.9197652 | K24: =('Kubiņu masa'!K30-'Kubiņu masa'!$D30)/'Kubiņu masa'!$D30*100 -> 7.1428571 | ... U24: =('Kubiņu masa'!U30-'Kubiņu masa'!$D30)/'Kubiņu masa'!$D30*100 -> 15.949119
C25: 428 | D25: =('Kubiņu masa'!D31-'Kubiņu masa'!$D31)/'Kubiņu masa'!$D31*100 -> 0 | E25: =('Kubiņu masa'!E31-'Kubiņu masa'!$D31)/'Kubiņu masa'!$D31*100 -> 5.2905916 | F25: =('Kubiņu masa'!F31-'Kubiņu masa'!$D31)/'Kubiņu masa'!$D31*100 -> 4.5087308 | G25: =('Kubiņu masa'!G31-'Kubiņu masa'!$D31)/'Kubiņu masa'!$D31*100 -> 4.7693511 | H25: =('Kubiņu masa'!H31-'Kubiņu masa'!$D31)/'Kubiņu masa'!$D31*100 -> 6.0724524 | I25: =('Kubiņu masa'!I31-'Kubiņu masa'!$D31)/'Kubiņu masa'!$D31*100 -> 6.3330727 | J25: =('Kubiņu masa'!J31-'Kubiņu masa'!$D31)/'Kubiņu masa'!$D31*100 -> 5.8118322 | K25: =('Kubiņu masa'!K31-'Kubiņu masa'!$D31)/'Kubiņu masa'!$D31*100 -> 6.8543133 | ... U25: =('Kubiņu masa'!U31-'Kubiņu masa'!$D31)/'Kubiņu masa'!$D31*100 -> 13.891061
B26: Sa4 | C26: 439 | D26: =('Kubiņu masa'!D32-'Kubiņu masa'!$D32)/'Kubiņu masa'!$D32*100 -> 0 | E26: =('Kubiņu masa'!E32-'Kubiņu masa'!$D32)/'Kubiņu masa'!$D32*100 -> 4.2752868 | F26: =('Kubiņu masa'!F32-'Kubiņu masa'!$D32)/'Kubiņu masa'!$D32*100 -> 3.9277025 | G26: =('Kubiņu masa'!G32-'Kubiņu masa'!$D32)/'Kubiņu masa'!$D32*100 -> 4.2752868 | H26: =('Kubiņu masa'!H32-'Kubiņu masa'!$D32)/'Kubiņu masa'!$D32*100 -> 5.3180396 | I26: =('Kubiņu masa'!I32-'Kubiņu masa'!$D32)/'Kubiņu masa'!$D32*100 -> 5.6656239 | J26: =('Kubiņu masa'!J32-'Kubiņu masa'!$D32)/'Kubiņu masa'!$D32*100 -> 4.9704553 | K26: =('Kubiņu masa'!K32-'Kubiņu masa'!$D32)/'Kubiņu masa'!$D32*100 -> 6.3607925 | ... U26: =('Kubiņu masa'!U32-'Kubiņu masa'!$D32)/'Kubiņu masa'!$D32*100 -> 14.702815
C27: 443 | D27: =('Kubiņu masa'!D33-'Kubiņu masa'!$D33)/'Kubiņu masa'!$D33*100 -> 0 | E27: =('Kubiņu masa'!E33-'Kubiņu masa'!$D33)/'Kubiņu masa'!$D33*100 -> 3.7800687 | F27: =('Kubiņu masa'!F33-'Kubiņu masa'!$D33)/'Kubiņu masa'!$D33*100 -> 4.1237113 | G27: =('Kubiņu masa'!G33-'Kubiņu masa'!$D33)/'Kubiņu masa'!$D33*100 -> 4.467354 | H27: =('Kubiņu masa'!H33-'Kubiņu masa'!$D33)/'Kubiņu masa'!$D33*100 -> 4.8109966 | I27: =('Kubiņu masa'!I33-'Kubiņu masa'!$D33)/'Kubiņu masa'!$D33*100 -> 6.185567 | J27: =('Kubiņu masa'!J33-'Kubiņu masa'!$D33)/'Kubiņu masa'!$D33*100 -> 4.8109966 | K27: =('Kubiņu masa'!K33-'Kubiņu masa'!$D33)/'Kubiņu masa'!$D33*100 -> 5.8419244 | ... U27: =('Kubiņu masa'!U33-'Kubiņu masa'!$D33)/'Kubiņu masa'!$D33*100 -> 14.089347
C28: 448 | D28: =('Kubiņu masa'!D34-'Kubiņu masa'!$D34)/'Kubiņu masa'!$D34*100 -> 0 | E28: =('Kubiņu masa'!E34-'Kubiņu masa'!$D34)/'Kubiņu masa'!$D34*100 -> 4.4671122 | F28: =('Kubiņu masa'!F34-'Kubiņu masa'!$D34)/'Kubiņu masa'!$D34*100 -> 3.0601477 | G28: =('Kubiņu masa'!G34-'Kubiņu masa'!$D34)/'Kubiņu masa'!$D34*100 -> 3.76363 | H28: =('Kubiņu masa'!H34-'Kubiņu masa'!$D34)/'Kubiņu masa'!$D34*100 -> 4.8188533 | I28: =('Kubiņu masa'!I34-'Kubiņu masa'!$D34)/'Kubiņu masa'!$D34*100 -> 5.5223356 | J28: =('Kubiņu masa'!J34-'Kubiņu masa'!$D34)/'Kubiņu masa'!$D34*100 -> 4.1153711 | K28: =('Kubiņu masa'!K34-'Kubiņu masa'!$D34)/'Kubiņu masa'!$D34*100 -> 5.5223356 | ... U28: =('Kubiņu masa'!U34-'Kubiņu masa'!$D34)/'Kubiņu masa'!$D34*100 -> 13.612381
A29: hito apstrāde | B29: Sl11 | C29: 295 | D29: =('Kubiņu masa'!D35-'Kubiņu masa'!$D35)/'Kubiņu masa'!$D35*100 -> 0 | E29: =('Kubiņu masa'!E35-'Kubiņu masa'!$D35)/'Kubiņu masa'!$D35*100 -> 1.4836795 | F29: =('Kubiņu masa'!F35-'Kubiņu masa'!$D35)/'Kubiņu masa'!$D35*100 -> 0.89020772 | G29: =('Kubiņu masa'!G35-'Kubiņu masa'!$D35)/'Kubiņu masa'!$D35*100 -> 0.89020772 | H29: =('Kubiņu masa'!H35-'Kubiņu masa'!$D35)/'Kubiņu masa'!$D35*100 -> 1.8793274 | I29: =('Kubiņu masa'!I35-'Kubiņu masa'!$D35)/'Kubiņu masa'!$D35*100 -> 2.0771513 | J29: =('Kubiņu masa'!J35-'Kubiņu masa'!$D35)/'Kubiņu masa'!$D35*100 -> 1.6815035 | K29: =('Kubiņu masa'!K35-'Kubiņu masa'!$D35)/'Kubiņu masa'!$D35*100 -> 3.6597428 | ... U29: =('Kubiņu masa'!U35-'Kubiņu masa'!$D35)/'Kubiņu masa'!$D35*100 -> 12.957468
C30: 298 | D30: =('Kubiņu masa'!D36-'Kubiņu masa'!$D36)/'Kubiņu masa'!$D36*100 -> 0 | E30: =('Kubiņu masa'!E36-'Kubiņu masa'!$D36)/'Kubiņu masa'!$D36*100 -> 1.7011834 | F30: =('Kubiņu masa'!F36-'Kubiņu masa'!$D36)/'Kubiņu masa'!$D36*100 -> 5.214497 | G30: =('Kubiņu masa'!G36-'Kubiņu masa'!$D36)/'Kubiņu masa'!$D36*100 -> 5.0295858 | H30: =('Kubiņu masa'!H36-'Kubiņu masa'!$D36)/'Kubiņu masa'!$D36*100 -> 5.954142 | I30: =('Kubiņu masa'!I36-'Kubiņu masa'!$D36)/'Kubiņu masa'!$D36*100 -> 6.1390533 | J30: =('Kubiņu masa'!J36-'Kubiņu masa'!$D36)/'Kubiņu masa'!$D36*100 -> 5.954142 | K30: =('Kubiņu masa'!K36-'Kubiņu masa'!$D36)/'Kubiņu masa'!$D36*100 -> 7.9881657 | ... U30: =('Kubiņu masa'!U36-'Kubiņu masa'!$D36)/'Kubiņu masa'!$D36*100 -> 18.528107
C31: 301 | D31: =('Kubiņu masa'!D37-'Kubiņu masa'!$D37)/'Kubiņu masa'!$D37*100 -> 0 | E31: =('Kubiņu masa'!E37-'Kubiņu masa'!$D37)/'Kubiņu masa'!$D37*100 -> 9.4289 | F31: =('Kubiņu masa'!F37-'Kubiņu masa'!$D37)/'Kubiņu masa'!$D37*100 -> 5.2127252 | G31: =('Kubiņu masa'!G37-'Kubiņu masa'!$D37)/'Kubiņu masa'!$D37*100 -> 5.0210809 | H31: =('Kubiņu masa'!H37-'Kubiņu masa'!$D37)/'Kubiņu masa'!$D37*100 -> 5.9793024 | I31: =('Kubiņu masa'!I37-'Kubiņu masa'!$D37)/'Kubiņu masa'!$D37*100 -> 6.1709467 | J31: =('Kubiņu masa'!J37-'Kubiņu masa'!$D37)/'Kubiņu masa'!$D37*100 -> 6.1709467 | K31: =('Kubiņu masa'!K37-'Kubiņu masa'!$D37)/'Kubiņu masa'!$D37*100 -> 8.0873898 | ... U31: =('Kubiņu masa'!U37-'Kubiņu masa'!$D37)/'Kubiņu masa'!$D37*100 -> 18.819471
B32: Sl - 22 | C32: 6 | D32: =('Kubiņu masa'!D38-'Kubiņu masa'!$D38)/'Kubiņu masa'!$D38*100 -> 0 | E32: =('Kubiņu masa'!E38-'Kubiņu masa'!$D38)/'Kubiņu masa'!$D38*100 -> 5.2631579 | F32: =('Kubiņu masa'!F38-'Kubiņu masa'!$D38)/'Kubiņu masa'!$D38*100 -> 6.0687433 | G32: =('Kubiņu masa'!G38-'Kubiņu masa'!$D38)/'Kubiņu masa'!$D38*100 -> 6.0687433 | H32: =('Kubiņu masa'!H38-'Kubiņu masa'!$D38)/'Kubiņu masa'!$D38*100 -> 7.1428571 | I32: =('Kubiņu masa'!I38-'Kubiņu masa'!$D38)/'Kubiņu masa'!$D38*100 -> 7.4113856 | J32: =('Kubiņu masa'!J38-'Kubiņu masa'!$D38)/'Kubiņu masa'!$D38*100 -> 6.8743287 | K32: =('Kubiņu masa'!K38-'Kubiņu masa'!$D38)/'Kubiņu masa'!$D38*100 -> 9.5596133 | ... U32: =('Kubiņu masa'!U38-'Kubiņu masa'!$D38)/'Kubiņu masa'!$D38*100 -> 17.07841
C33: 10 | D33: =('Kubiņu masa'!D39-'Kubiņu masa'!$D39)/'Kubiņu masa'!$D39*100 -> 0 | E33: =('Kubiņu masa'!E39-'Kubiņu masa'!$D39)/'Kubiņu masa'!$D39*100 -> 5.6932716 | F33: =('Kubiņu masa'!F39-'Kubiņu masa'!$D39)/'Kubiņu masa'!$D39*100 -> 5.6932716 | G33: =('Kubiņu masa'!G39-'Kubiņu masa'!$D39)/'Kubiņu masa'!$D39*100 -> 5.4208662 | H33: =('Kubiņu masa'!H39-'Kubiņu masa'!$D39)/'Kubiņu masa'!$D39*100 -> 6.7828929 | I33: =('Kubiņu masa'!I39-'Kubiņu masa'!$D39)/'Kubiņu masa'!$D39*100 -> 6.7828929 | J33: =('Kubiņu masa'!J39-'Kubiņu masa'!$D39)/'Kubiņu masa'!$D39*100 -> 6.2380823 | K33: =('Kubiņu masa'!K39-'Kubiņu masa'!$D39)/'Kubiņu masa'!$D39*100 -> 8.9621357 | ... U33: =('Kubiņu masa'!U39-'Kubiņu masa'!$D39)/'Kubiņu masa'!$D39*100 -> 17.679107
C34: 14 | D34: =('Kubiņu masa'!D40-'Kubiņu masa'!$D40)/'Kubiņu masa'!$D40*100 -> 0 | E34: =('Kubiņu masa'!E40-'Kubiņu masa'!$D40)/'Kubiņu masa'!$D40*100 -> 6.3389392 | F34: =('Kubiņu masa'!F40-'Kubiņu masa'!$D40)/'Kubiņu masa'!$D40*100 -> 5.5627426 | G34: =('Kubiņu masa'!G40-'Kubiņu masa'!$D40)/'Kubiņu masa'!$D40*100 -> 5.3040103 | H34: =('Kubiņu masa'!H40-'Kubiņu masa'!$D40)/'Kubiņu masa'!$D40*100 -> 6.5976714 | I34: =('Kubiņu masa'!I40-'Kubiņu masa'!$D40)/'Kubiņu masa'!$D40*100 -> 6.8564036 | J34: =('Kubiņu masa'!J40-'Kubiņu masa'!$D40)/'Kubiņu masa'!$D40*100 -> 6.3389392 | K34: =('Kubiņu masa'!K40-'Kubiņu masa'!$D40)/'Kubiņu masa'!$D40*100 -> 9.1849935 | ... U34: =('Kubiņu masa'!U40-'Kubiņu masa'!$D40)/'Kubiņu masa'!$D40*100 -> 19.27555
B35: Sl - 23 | C35: 26 | D35: =('Kubiņu masa'!D41-'Kubiņu masa'!$D41)/'Kubiņu masa'!$D41*100 -> 0 | E35: =('Kubiņu masa'!E41-'Kubiņu masa'!$D41)/'Kubiņu masa'!$D41*100 -> 6.3981043 | F35: =('Kubiņu masa'!F41-'Kubiņu masa'!$D41)/'Kubiņu masa'!$D41*100 -> 5.6872038 | G35: =('Kubiņu masa'!G41-'Kubiņu masa'!$D41)/'Kubiņu masa'!$D41*100 -> 5.6872038 | H35: =('Kubiņu masa'!H41-'Kubiņu masa'!$D41)/'Kubiņu masa'!$D41*100 -> 6.8720379 | I35: =('Kubiņu masa'!I41-'Kubiņu masa'!$D41)/'Kubiņu masa'!$D41*100 -> 7.1090047 | J35: =('Kubiņu masa'!J41-'Kubiņu masa'!$D41)/'Kubiņu masa'!$D41*100 -> 6.3981043 | K35: =('Kubiņu masa'!K41-'Kubiņu masa'!$D41)/'Kubiņu masa'!$D41*100 -> 9.0047393 | ... U35: =('Kubiņu masa'!U41-'Kubiņu masa'!$D41)/'Kubiņu masa'!$D41*100 -> 20.853081
C36: 30 | D36: =('Kubiņu masa'!D42-'Kubiņu masa'!$D42)/'Kubiņu masa'!$D42*100 -> 0 | E36: =('Kubiņu masa'!E42-'Kubiņu masa'!$D42)/'Kubiņu masa'!$D42*100 -> 5.815062 | F36: =('Kubiņu masa'!F42-'Kubiņu masa'!$D42)/'Kubiņu masa'!$D42*100 -> 5.815062 | G36: =('Kubiņu masa'!G42-'Kubiņu masa'!$D42)/'Kubiņu masa'!$D42*100 -> 6.0533842 | H36: =('Kubiņu masa'!H42-'Kubiņu masa'!$D42)/'Kubiņu masa'!$D42*100 -> 7.006673 | I36: =('Kubiņu masa'!I42-'Kubiņu masa'!$D42)/'Kubiņu masa'!$D42*100 -> 7.4833174 | J36: =('Kubiņu masa'!J42-'Kubiņu masa'!$D42)/'Kubiņu masa'!$D42*100 -> 6.5300286 | K36: =('Kubiņu masa'!K42-'Kubiņu masa'!$D42)/'Kubiņu masa'!$D42*100 -> 9.1515729 | ... U36: =('Kubiņu masa'!U42-'Kubiņu masa'!$D42)/'Kubiņu masa'!$D42*100 -> 19.63775
C37: 34 | D37: =('Kubiņu masa'!D43-'Kubiņu masa'!$D43)/'Kubiņu masa'!$D43*100 -> 0 | E37: =('Kubiņu masa'!E43-'Kubiņu masa'!$D43)/'Kubiņu masa'!$D43*100 -> 5.6487828 | F37: =('Kubiņu masa'!F43-'Kubiņu masa'!$D43)/'Kubiņu masa'!$D43*100 -> 5.6487828 | G37: =('Kubiņu masa'!G43-'Kubiņu masa'!$D43)/'Kubiņu masa'!$D43*100 -> 5.8851335 | H37: =('Kubiņu masa'!H43-'Kubiņu masa'!$D43)/'Kubiņu masa'!$D43*100 -> 6.5941858 | I37: =('Kubiņu masa'!I43-'Kubiņu masa'!$D43)/'Kubiņu masa'!$D43*100 -> 7.303238 | J37: =('Kubiņu masa'!J43-'Kubiņu masa'!$D43)/'Kubiņu masa'!$D43*100 -> 6.357835 | K37: =('Kubiņu masa'!K43-'Kubiņu masa'!$D43)/'Kubiņu masa'!$D43*100 -> 9.4303947 | ... U37: =('Kubiņu masa'!U43-'Kubiņu masa'!$D43)/'Kubiņu masa'!$D43*100 -> 16.284566
B38: Sl - 31 | C38: 46 | D38: =('Kubiņu masa'!D44-'Kubiņu masa'!$D44)/'Kubiņu masa'!$D44*100 -> 0 | E38: =('Kubiņu masa'!E44-'Kubiņu masa'!$D44)/'Kubiņu masa'!$D44*100 -> 5.8683584 | F38: =('Kubiņu masa'!F44-'Kubiņu masa'!$D44)/'Kubiņu masa'!$D44*100 -> 6.0666138 | G38: =('Kubiņu masa'!G44-'Kubiņu masa'!$D44)/'Kubiņu masa'!$D44*100 -> 5.4718477 | H38: =('Kubiņu masa'!H44-'Kubiņu masa'!$D44)/'Kubiņu masa'!$D44*100 -> 6.0666138 | I38: =('Kubiņu masa'!I44-'Kubiņu masa'!$D44)/'Kubiņu masa'!$D44*100 -> 7.0578906 | J38: =('Kubiņu masa'!J44-'Kubiņu masa'!$D44)/'Kubiņu masa'!$D44*100 -> 6.4631245 | K38: =('Kubiņu masa'!K44-'Kubiņu masa'!$D44)/'Kubiņu masa'!$D44*100 -> 8.6439334 | ... U38: =('Kubiņu masa'!U44-'Kubiņu masa'!$D44)/'Kubiņu masa'!$D44*100 -> 18.556701
C39: 50 | D39: =('Kubiņu masa'!D45-'Kubiņu masa'!$D45)/'Kubiņu masa'!$D45*100 -> 0 | E39: =('Kubiņu masa'!E45-'Kubiņu masa'!$D45)/'Kubiņu masa'!$D45*100 -> 5.5647994 | F39: =('Kubiņu masa'!F45-'Kubiņu masa'!$D45)/'Kubiņu masa'!$D45*100 -> 5.7496765 | G39: =('Kubiņu masa'!G45-'Kubiņu masa'!$D45)/'Kubiņu masa'!$D45*100 -> 5.7496765 | H39: =('Kubiņu masa'!H45-'Kubiņu masa'!$D45)/'Kubiņu masa'!$D45*100 -> 6.6740617 | I39: =('Kubiņu masa'!I45-'Kubiņu masa'!$D45)/'Kubiņu masa'!$D45*100 -> 7.0438159 | J39: =('Kubiņu masa'!J45-'Kubiņu masa'!$D45)/'Kubiņu masa'!$D45*100 -> 6.4891847 | K39: =('Kubiņu masa'!K45-'Kubiņu masa'!$D45)/'Kubiņu masa'!$D45*100 -> 8.8925864 | ... U39: =('Kubiņu masa'!U45-'Kubiņu masa'!$D45)/'Kubiņu masa'!$D45*100 -> 17.766685
C40: 54 | D40: =('Kubiņu masa'!D46-'Kubiņu masa'!$D46)/'Kubiņu masa'!$D46*100 -> 0 | E40: =('Kubiņu masa'!E46-'Kubiņu masa'!$D46)/'Kubiņu masa'!$D46*100 -> 5.7004831 | F40: =('Kubiņu masa'!F46-'Kubiņu masa'!$D46)/'Kubiņu masa'!$D46*100 -> 5.8937198 | G40: =('Kubiņu masa'!G46-'Kubiņu masa'!$D46)/'Kubiņu masa'!$D46*100 -> 5.1207729 | H40: =('Kubiņu masa'!H46-'Kubiņu masa'!$D46)/'Kubiņu masa'!$D46*100 -> 6.47343 | I40: =('Kubiņu masa'!I46-'Kubiņu masa'!$D46)/'Kubiņu masa'!$D46*100 -> 6.6666667 | J40: =('Kubiņu masa'!J46-'Kubiņu masa'!$D46)/'Kubiņu masa'!$D46*100 -> 6.2801932 | K40: =('Kubiņu masa'!K46-'Kubiņu masa'!$D46)/'Kubiņu masa'!$D46*100 -> 8.4057971 | ... U40: =('Kubiņu masa'!U46-'Kubiņu masa'!$D46)/'Kubiņu masa'!$D46*100 -> 17.101449
...

Sheet Statistikai
A1: Slāņu_skaits | B1: Substrate | C1: id | D1: rh | E1: Date | F1: humidity% | G1: masa | H1: udens | I1: tilpumprocenti
A2: 0 | B2: BSD1 | C2: 316 | D2: 0 | E2: 45608 | F2: 0 | G2: 6.617 | H2: =G2-G2 -> 0 | I2: =H2/27*100 -> 0
A3: 0 | B3: BSD1 | C3: 320 | D3: 0 | E3: 45608 | F3: 0 | G3: 6.473 | H3: =G3-G3 -> 0 | I3: =H3/27*100 -> 0
A4: 0 | B4: BSD1 | C4: 325 | D4: 0 | E4: 45608 | F4: 0 | G4: 6.128 | H4: =G4-G4 -> 0 | I4: =H4/27*100 -> 0
A5: 0 | B5: BSD2 | C5: 332 | D5: 0 | E5: 45608 | F5: 0 | G5: 3.74 | H5: =G5-G5 -> 0 | I5: =H5/27*100 -> 0
A6: 0 | B6: BSD2 | C6: 336 | D6: 0 | E6: 45608 | F6: 0 | G6: 3.827 | H6: =G6-G6 -> 0 | I6: =H6/27*100 -> 0
A7: 0 | B7: BSD2 | C7: 341 | D7: 0 | E7: 45608 | F7: 0 | G7: 3.634 | H7: =G7-G7 -> 0 | I7: =H7/27*100 -> 0
A8: 0 | B8: BSD3 | C8: 348 | D8: 0 | E8: 45608 | F8: 0 | G8: 5.153 | H8: =G8-G8 -> 0 | I8: =H8/27*100 -> 0
A9: 0 | B9: BSD3 | C9: 352 | D9: 0 | E9: 45608 | F9: 0 | G9: 5.241 | H9: =G9-G9 -> 0 | I9: =H9/27*100 -> 0
A10: 0 | B10: BSD3 | C10: 357 | D10: 0 | E10: 45608 | F10: 0 | G10: 5.155 | H10: =G10-G10 -> 0 | I10: =H10/27*100 -> 0
A11: 0 | B11: BSD4 | C11: 368 | D11: 0 | E11: 45608 | F11: 0 | G11: 5.737 | H11: =G11-G11 -> 0 | I11: =H11/27*100 -> 0
A12: 0 | B12: BSD4 | C12: 372 | D12: 0 | E12: 45608 | F12: 0 | G12: 6.177 | H12: =G12-G12 -> 0 | I12: =H12/27*100 -> 0
A13: 0 | B13: BSD4 | C13: 377 | D13: 0 | E13: 45608 | F13: 0 | G13: 6.033 | H13: =G13-G13 -> 0 | I13: =H13/27*100 -> 0
... A70: 4 | B70: WS4 | C70: 223 | D70: 0 | E70: 45608 | F70: 0 | G70: 2.808 | H70: =G70-G70 -> 0 | I70: =H70/27*100 -> 0
A71: 0 | B71: BSD1 | C71: 316 | D71: 50 | E71: 45609 | F71: 5.4858697 | G71: 6.98 | H71: =G71-G2 -> 0.363 | I71: =H71/27*100 -> 1.3444444
A72: 0 | B72: BSD1 | C72: 320 | D72: 50 | E72: 45609 | F72: 5.6697049 | G72: 6.84 | H72: =G72-G3 -> 0.367 | I72: =H72/27*100 -> 1.3592593
A73: 0 | B73: BSD1 | C73: 325 | D73: 50 | E73: 45609 | F73: 5.4177546 | G73: 6.46 | H73: =G73-G4 -> 0.332 | I73: =H73/27*100 -> 1.2296296
A74: 0 | B74: BSD2 | C74: 332 | D74: 50 | E74: 45609 | F74: 5.3475936 | G74: 3.94 | H74: =G74-G5 -> 0.2 | I74: =H74/27*100 -> 0.74074074
A75: 0 | B75: BSD2 | C75: 336 | D75: 50 | E75: 45609 | F75: 5.5657173 | G75: 4.04 | H75: =G75-G6 -> 0.213 | I75: =H75/27*100 -> 0.78888889
A76: 0 | B76: BSD2 | C76: 341 | D76: 50 | E76: 45609 | F76: 5.6686846 | G76: 3.84 | H76: =G76-G7 -> 0.206 | I76: =H76/27*100 -> 0.76296296
A77: 0 | B77: BSD3 | C77: 348 | D77: 50 | E77: 45609 | F77: 4.987386 | G77: 5.41 | H77: =G77-G8 -> 0.257 | I77: =H77/27*100 -> 0.95185185
A78: 0 | B78: BSD3 | C78: 352 | D78: 50 | E78: 45609 | F78: 5.7050181 | G78: 5.54 | H78: =G78-G9 -> 0.299 | I78: =H78/27*100 -> 1.1074074
A79: 0 | B79: BSD3 | C79: 357 | D79: 50 | E79: 45609 | F79: 5.3346266 | G79: 5.43 | H79: =G79-G10 -> 0.275 | I79: =H79/27*100 -> 1.0185185
A80: 0 | B80: BSD4 | C80: 368 | D80: 50 | E80: 45609 | F80: 5.4558131 | G80: 6.05 | H80: =G80-G11 -> 0.313 | I80: =H80/27*100 -> 1.1592593
A81: 0 | B81: BSD4 | C81: 372 | D81: 50 | E81: 45609 | F81: 5.7147483 | G81: 6.53 | H81: =G81-G12 -> 0.353 | I81: =H81/27*100 -> 1.3074074
A82: 0 | B82: BSD4 | C82: 377 | D82: 50 | E82: 45609 | F82: 4.9229239 | G82: 6.33 | H82: =G82-G13 -> 0.297 | I82: =H82/27*100 -> 1.1
... A139: 4 | B139: WS4 | C139: 223 | D139: 50 | E139: 45609 | F139: 5.4131054 | G139: 2.96 | H139: =G139-G70 -> 0.152 | I139: =H139/27*100 -> 0.56296296
A140: 0 | B140: BSD1 | C140: 316 | D140: 50 | E140: 45611 | F140: 5.4858697 | G140: 6.98 | H140: =G140-G2 -> 0.363 | I140: =H140/27*100 -> 1.3444444
A141: 0 | B141: BSD1 | C141: 320 | D141: 50 | E141: 45611 | F141: 5.6697049 | G141: 6.84 | H141: =G141-G3 -> 0.367 | I141: =H141/27*100 -> 1.3592593
A142: 0 | B142: BSD1 | C142: 325 | D142: 50 | E142: 45611 | F142: 5.4177546 | G142: 6.46 | H142: =G142-G4 -> 0.332 | I142: =H142/27*100 -> 1.2296296
A143: 0 | B143: BSD2 | C143: 332 | D143: 50 | E143: 45611 | F143: 5.3475936 | G143: 3.94 | H143: =G143-G5 -> 0.2 | I143: =H143/27*100 -> 0.74074074
A144: 0 | B144: BSD2 | C144: 336 | D144: 50 | E144: 45611 | F144: 5.5657173 | G144: 4.04 | H144: =G144-G6 -> 0.213 | I144: =H144/27*100 -> 0.78888889
A145: 0 | B145: BSD2 | C145: 341 | D145: 50 | E145: 45611 | F145: 5.3935058 | G145: 3.83 | H145: =G145-G7 -> 0.196 | I145: =H145/27*100 -> 0.72592593
A146: 0 | B146: BSD3 | C146: 348 | D146: 50 | E146: 45611 | F146: 5.3755094 | G146: 5.43 | H146: =G146-G8 -> 0.277 | I146: =H146/27*100 -> 1.0259259
A147: 0 | B147: BSD3 | C147: 352 | D147: 50 | E147: 45611 | F147: 5.3234116 | G147: 5.52 | H147: =G147-G9 -> 0.279 | I147: =H147/27*100 -> 1.0333333
A148: 0 | B148: BSD3 | C148: 357 | D148: 50 | E148: 45611 | F148: 4.7526673 | G148: 5.4 | H148: =G148-G10 -> 0.245 | I148: =H148/27*100 -> 0.90740741
A149: 0 | B149: BSD4 | C149: 368 | D149: 50 | E149: 45611 | F149: 4.9328918 | G149: 6.02 | H149: =G149-G11 -> 0.283 | I149: =H149/27*100 -> 1.0481481
A150: 0 | B150: BSD4 | C150: 372 | D150: 50 | E150: 45611 | F150: 5.0671847 | G150: 6.49 | H150: =G150-G12 -> 0.313 | I150: =H150/27*100 -> 1.1592593
A151: 0 | B151: BSD4 | C151: 377 | D151: 50 | E151: 45611 | F151: 4.9229239 | G151: 6.33 | H151: =G151-G13 -> 0.297 | I151: =H151/27*100 -> 1.1
... A208: 4 | B208: WS4 | C208: 223 | D208: 50 | E208: 45611 | F208: 6.4814815 | G208: 2.99 | H208: =G208-G70 -> 0.182 | I208: =H208/27*100 -> 0.67407407
...

Sheet Mean_SD
A1: slanu_skaits | B1: substrats | C1: gaisa_mitrums | D1: mean_udens_sat | E1: sd_udens_sat
A2: 0 | B2: BSD1 | C2: 50 | D2: 5.5788382 | E2: 0.091935619
A3: 0 | B3: BSD1 | C3: 60 | D3: 6.7241988 | E3: 0.1809304
A4: 0 | B4: BSD1 | C4: 70 | D4: 7.9691894 | E4: 0.095987932
A5: 0 | B5: BSD1 | C5: 80 | D5: 11.146013 | E5: 0.078230319
A6: 0 | B6: BSD1 | C6: 90 | D6: 16.45907 | E6: 0.23186471
A7: 0 | B7: BSD1 | C7: 95 | D7: 20.092633 | E7: 0.13314303
A8: 0 | B8: BSD2 | C8: 50 | D8: 5.5273318 | E8: 0.16395106
A9: 0 | B9: BSD2 | C9: 60 | D9: 6.6810459 | E9: 0.40208381
A10: 0 | B10: BSD2 | C10: 70 | D10: 7.8451589 | E10: 0.34672382
A11: 0 | B11: BSD2 | C11: 80 | D11: 11.062624 | E11: 0.10517531
A12: 0 | B12: BSD2 | C12: 90 | D12: 16.86847 | E12: 0.32944708
A13: 0 | B13: BSD2 | C13: 95 | D13: 20.798069 | E13: 0.31339337
... A139: 4 | B139: WSz3 | C139: 95 | D139: 24.851177 | E139: 0.64968916
