Workbook

Sheet Kubiņu masa
B1: 24.11.25
E2: mo-abs sausa, žavskapī 50C/3h
B4: Gaisa mitrums: | D4: 0 | E4: 0.5 | G4: 0.6 | I4: 0.7 | K4: 0.8 | N4: 0.9 | Q4: pelējuma augšana 95% rh
B5: Temperatūra: | D5: 23oC | E5: 23oC | F5: 23oC | G5: 23oC | H5: 23oC | I5: 23oC | J5: 23oC | K5: 23oC | L5: 23oC | M5: 23oC | N5: 23oC | O5: 23oC | P5: 23oC
B6: Paraugi | D6: 24.11.25 | E6: 45987 | F6: 45989 | G6: 45992 | H6: 45994 | I6: 45999 | J6: 46000 | K6: 46001 | L6: 46006 | M6: 46007 | N6: 46010 | O6: 46013 | P6: 23.20.2025
A7: apstrāde | D7: mo*
A8: sub | B8: Sl1 | C8: 9 | D8: 6.89 | E8: 7.16 | F8: 7.16 | G8: 7.21 | H8: 7.2 | I8: 7.3 | J8: 7.3 | K8: 7.45 | L8: 7.47 | M8: 7.47 | N8: 7.74 | O8: 7.74 | P8: 7.75 | Q8: daudz
C9: 27 | D9: 7.21 | E9: 7.46 | F9: 7.46 | G9: 7.51 | H9: 7.51 | I9: 7.61 | J9: 7.61 | K9: 7.75 | L9: 7.77 | M9: 7.78 | N9: 8.03 | O9: 8.04 | P9: 8.05 | Q9: daudz
C10: 106 | D10: 7.15 | E10: 7.4 | F10: 7.4 | G10: 7.44 | H10: 7.44 | I10: 7.54 | J10: 7.54 | K10: 7.68 | L10: 7.7 | M10: 7.7 | N10: 7.95 | O10: 7.96 | P10: 7.97 | Q10: daudz
B11: Sl2 | C11: 39 | D11: 5.9 | E11: 6.09 | F11: 6.09 | G11: 6.13 | H11: 6.12 | I11: 6.2 | J11: 6.2 | K11: 6.31 | L11: 6.32 | M11: 6.32 | N11: 6.53 | O11: 6.53 | P11: 6.54 | Q11: daudz
C12: 55 | D12: 6.12 | E12: 6.32 | F12: 6.32 | G12: 6.36 | H12: 6.36 | I12: 6.44 | J12: 6.44 | K12: 6.56 | L12: 6.57 | M12: 6.57 | N12: 6.8 | O12: 6.79 | P12: 6.8 | Q12: daudz
C13: 122 | D13: 6.18 | E13: 6.38 | F13: 6.37 | G13: 6.41 | H13: 6.41 | I13: 6.48 | J13: 6.49 | K13: 6.6 | L13: 6.61 | M13: 6.61 | N13: 6.82 | O13: 6.83 | P13: 6.84 | Q13: daudz
B14: Sl3 | C14: 66 | D14: 7.23 | E14: 7.48 | F14: 7.48 | G14: 7.53 | H14: 7.53 | I14: 7.61 | J14: 7.62 | K14: 7.76 | L14: 7.78 | M14: 7.78 | N14: 8.04 | O14: 8.04 | P14: 8.05 | Q14: daudz
C15: 142 | D15: 7.6 | E15: 7.88 | F15: 7.87 | G15: 7.93 | H15: 7.93 | I15: 8.02 | J15: 8.02 | K15: 8.17 | L15: 8.19 | M15: 8.2 | N15: 8.48 | O15: 8.49 | P15: 8.49 | Q15: daudz
C16: 147 | D16: 7.42 | E16: 7.69 | F16: 7.69 | G16: 7.74 | H16: 7.74 | I16: 7.83 | J16: 7.84 | K16: 7.99 | L16: 8.01 | M16: 8 | N16: 8.27 | O16: 8.28 | P16: 8.29 | Q16: daudz
B17: Sl4 | C17: 75 | D17: 7.58 | E17: 7.83 | F17: 7.83 | G17: 7.88 | H17: 7.88 | I17: 7.97 | J17: 7.97 | K17: 8.1 | L17: 8.13 | M17: 8.12 | N17: 8.35 | O17: 8.35 | P17: 8.37 | Q17: maz
C18: 81 | D18: 7.62 | E18: 7.87 | F18: 7.88 | G18: 7.92 | H18: 7.92 | I18: 8.01 | J18: 8.01 | K18: 8.14 | L18: 8.16 | M18: 8.16 | N18: 8.4 | O18: 8.39 | P18: 8.41 | Q18: nav
C19: 91 | D19: 7.82 | E19: 8.07 | F19: 8.07 | G19: 8.12 | H19: 8.12 | I19: 8.21 | J19: 8.21 | K19: 8.34 | L19: 8.37 | M19: 8.36 | N19: 8.59 | O19: 8.6 | P19: 8.61 | Q19: nav
B20: Sa1 | C20: 285 | D20: 3.85 | E20: 3.96 | F20: 3.96 | G20: 3.99 | H20: 3.99 | I20: 4.04 | J20: 4.04 | K20: 4.13 | L20: 4.13 | M20: 4.13 | N20: 4.31 | O20: 4.3 | P20: 4.31 | Q20: daudz
C21: 322 | D21: 3.99 | E21: 4.12 | F21: 4.11 | G21: 4.14 | H21: 4.14 | I21: 4.19 | J21: 4.2 | K21: 4.29 | L21: 4.29 | M21: 4.29 | N21: 4.48 | O21: 4.48 | P21: 4.49 | Q21: daudz
C22: 323 | D22: 4.21 | E22: 4.34 | F22: 4.34 | G22: 4.35 | H22: 4.35 | I22: 4.4 | J22: 4.41 | K22: 4.5 | L22: 4.5 | M22: 4.5 | N22: 4.69 | O22: 4.69 | P22: 4.7 | Q22: daudz
B23: Sa2 | C23: 267 | D23: 4.99 | E23: 5.15 | F23: 5.15 | G23: 5.17 | H23: 5.17 | I23: 5.22 | J23: 5.23 | K23: 5.33 | L23: 5.33 | M23: 5.33 | N23: 5.51 | O23: 5.51 | P23: 5.52 | Q23: daudz
C24: 275 | D24: 4.92 | E24: 5.09 | F24: 5.08 | G24: 5.11 | H24: 5.11 | I24: 5.17 | J24: 5.17 | K24: 5.27 | L24: 5.27 | M24: 5.27 | N24: 5.45 | O24: 5.46 | P24: 5.46 | Q24: daudz
C25: 266 | D25: 5.01 | E25: 5.17 | F25: 5.17 | G25: 5.2 | H25: 5.2 | I25: 5.25 | J25: 5.26 | K25: 5.35 | L25: 5.36 | M25: 5.36 | N25: 5.54 | O25: 5.54 | P25: 5.54 | Q25: daudz
B26: Sa3 | C26: 344 | D26: 5.79 | E26: 6 | F26: 6 | G26: 6.04 | H26: 6.04 | I26: 6.1 | J26: 6.11 | K26: 6.23 | L26: 6.24 | M26: 6.24 | N26: 6.47 | O26: 6.47 | P26: 6.47 | Q26: daudz
C27: 60 | D27: 6.04 | E27: 6.26 | F27: 6.26 | G27: 6.3 | H27: 6.3 | I27: 6.38 | J27: 6.39 | K27: 6.52 | L27: 6.53 | M27: 6.53 | N27: 6.79 | O27: 6.79 | P27: 6.79 | Q27: daudz
C28: 58 | D28: 5.99 | E28: 6.2 | F28: 6.2 | G28: 6.24 | H28: 6.24 | I28: 6.32 | J28: 6.33 | K28: 6.46 | L28: 6.47 | M28: 6.47 | N28: 6.73 | O28: 6.73 | P28: 6.74 | Q28: daudz
B29: Sa4 | C29: 211 | D29: 3.86 | E29: 3.97 | F29: 3.97 | G29: 3.99 | H29: 3.99 | I29: 4.03 | J29: 4.04 | K29: 4.11 | L29: 4.11 | M29: 4.11 | N29: 4.25 | O29: 4.24 | P29: 4.25 | Q29: daudz
C30: 250 | D30: 4.17 | E30: 4.29 | F30: 4.29 | G30: 4.32 | H30: 4.32 | I30: 4.36 | J30: 4.37 | K30: 4.45 | L30: 4.45 | M30: 4.45 | N30: 4.59 | O30: 4.59 | P30: 4.6 | Q30: daudz
C31: 212 | D31: 3.95 | E31: 4.06 | F31: 4.05 | G31: 4.08 | H31: 4.08 | I31: 4.12 | J31: 4.12 | K31: 4.2 | L31: 4.2 | M31: 4.2 | N31: 4.34 | O31: 4.34 | P31: 4.34 | Q31: daudz
A32: hito/sub | B32: Sl1 | C32: 5 | D32: 7.28 | E32: 7.53 | F32: 7.52 | G32: 7.57 | H32: 7.57 | I32: 7.67 | J32: 7.67 | K32: 7.82 | L32: 7.84 | M32: 7.84 | N32: 8.1 | O32: 8.14 | P32: 8.14 | Q32: nav
C33: 17 | D33: 7.26 | E33: 7.49 | F33: 7.49 | G33: 7.54 | H33: 7.54 | I33: 7.63 | J33: 7.63 | K33: 7.78 | L33: 7.8 | M33: 7.81 | N33: 8.06 | O33: 8.09 | P33: 8.09 | Q33: nav
C34: 99 | D34: 7.36 | E34: 7.6 | F34: 7.59 | G34: 7.65 | H34: 7.65 | I34: 7.74 | J34: 7.74 | K34: 7.9 | L34: 7.93 | M34: 7.93 | N34: 8.19 | O34: 8.23 | P34: 8.23 | Q34: nav
B35: Sl2 | C35: 37 | D35: 5.74 | E35: 5.93 | F35: 5.93 | G35: 5.97 | H35: 5.97 | I35: 6.04 | J35: 6.04 | K35: 6.16 | L35: 6.17 | M35: 6.17 | N35: 6.37 | O35: 6.4 | P35: 6.4 | Q35: nav
C36: 53 | D36: 6.24 | E36: 6.44 | F36: 6.44 | G36: 6.48 | H36: 6.48 | I36: 6.56 | J36: 6.56 | K36: 6.69 | L36: 6.71 | M36: 6.71 | N36: 6.93 | O36: 6.96 | P36: 6.96 | Q36: nav
C37: 134 | D37: 5.96 | E37: 6.15 | F37: 6.14 | G37: 6.18 | H37: 6.18 | I37: 6.26 | J37: 6.26 | K37: 6.38 | L37: 6.4 | M37: 6.4 | N37: 6.61 | O37: 6.65 | P37: 6.64 | Q37: nav
B38: Sl3 | C38: 192 | D38: 7.26 | E38: 7.51 | F38: 7.51 | G38: 7.56 | H38: 7.56 | I38: 7.65 | J38: 7.65 | K38: 7.8 | L38: 7.82 | M38: 7.82 | N38: 8.07 | O38: 8.11 | P38: 8.1 | Q38: nav
C39: 143 | D39: 7.39 | E39: 7.65 | F39: 7.65 | G39: 7.71 | H39: 7.71 | I39: 7.81 | J39: 7.81 | K39: 7.97 | L39: 7.99 | M39: 7.99 | N39: 8.26 | O39: 8.3 | P39: 8.3 | Q39: nav
C40: 190 | D40: 7.11 | E40: 7.34 | F40: 7.34 | G40: 7.39 | H40: 7.39 | I40: 7.47 | J40: 7.47 | K40: 7.61 | L40: 7.63 | M40: 7.63 | N40: 7.86 | O40: 7.9 | P40: 7.9 | Q40: nav
B41: Sl4 | C41: 88 | D41: 8.23 | E41: 8.5 | F41: 8.5 | G41: 8.56 | H41: 8.56 | I41: 8.65 | J41: 8.65 | K41: 8.81 | L41: 8.83 | M41: 8.83 | N41: 9.07 | O41: 9.12 | P41: 9.11 | Q41: nav
...

Sheet Masas izmaiņa %
B1: Gaisa mitrums: | D1: 0 | E1: 0.5 | G1: 0.6 | I1: 0.7 | K1: 0.8 | N1: 0.9 | Q1: pelējuma augšana 95% rh
B2: Temperatūra: | D2: 23oC | E2: 23oC | F2: 23oC | G2: 23oC | H2: 23oC | I2: 23oC | J2: 23oC | K2: 23oC | L2: 23oC | M2: 23oC | N2: 23oC | O2: 23oC | P2: 23oC
B3: Paraugi | D3: 24.11.25 | E3: 45987 | F3: 45989 | G3: 45992 | H3: 45994 | I3: 45999 | J3: 46000 | K3: 46001 | L3: 46006 | M3: 46007 | N3: 46010 | O3: 46013 | P3: 23.20.2025
A4: apstrāde | D4: mo*
A5: sub | B5: Sl1 | C5: 9 | D5: =('Kubiņu masa'!D8-'Kubiņu masa'!$D8)/'Kubiņu masa'!$D8*100 -> 0 | E5: =('Kubiņu masa'!E8-'Kubiņu masa'!$D8)/'Kubiņu masa'!$D8*100 -> 3.9187228 | F5: =('Kubiņu masa'!F8-'Kubiņu masa'!$D8)/'Kubiņu masa'!$D8*100 -> 3.9187228 | G5: =('Kubiņu masa'!G8-'Kubiņu masa'!$D8)/'Kubiņu masa'!$D8*100 -> 4.6444122 | H5: =('Kubiņu masa'!H8-'Kubiņu masa'!$D8)/'Kubiņu masa'!$D8*100 -> 4.4992743 | I5: =('Kubiņu masa'!I8-'Kubiņu masa'!$D8)/'Kubiņu masa'!$D8*100 -> 5.9506531 | J5: =('Kubiņu masa'!J8-'Kubiņu masa'!$D8)/'Kubiņu masa'!$D8*100 -> 5.9506531 | K5: =('Kubiņu masa'!K8-'Kubiņu masa'!$D8)/'Kubiņu masa'!$D8*100 -> 8.1277213 | ... P5: =('Kubiņu masa'!P8-'Kubiņu masa'!$D8)/'Kubiņu masa'!$D8*100 -> 12.481858 | Q5: daudz
C6: 27 | D6: =('Kubiņu masa'!D9-'Kubiņu masa'!$D9)/'Kubiņu masa'!$D9*100 -> 0 | E6: =('Kubiņu masa'!E9-'Kubiņu masa'!$D9)/'Kubiņu masa'!$D9*100 -> 3.4674064 | F6: =('Kubiņu masa'!F9-'Kubiņu masa'!$D9)/'Kubiņu masa'!$D9*100 -> 3.4674064 | G6: =('Kubiņu masa'!G9-'Kubiņu masa'!$D9)/'Kubiņu masa'!$D9*100 -> 4.1608877 | H6: =('Kubiņu masa'!H9-'Kubiņu masa'!$D9)/'Kubiņu masa'!$D9*100 -> 4.1608877 | I6: =('Kubiņu masa'!I9-'Kubiņu masa'!$D9)/'Kubiņu masa'!$D9*100 -> 5.5478502 | J6: =('Kubiņu masa'!J9-'Kubiņu masa'!$D9)/'Kubiņu masa'!$D9*100 -> 5.5478502 | K6: =('Kubiņu masa'!K9-'Kubiņu masa'!$D9)/'Kubiņu masa'!$D9*100 -> 7.4895978 | ... P6: =('Kubiņu masa'!P9-'Kubiņu masa'!$D9)/'Kubiņu masa'!$D9*100 -> 11.650485 | Q6: daudz
C7: 106 | D7: =('Kubiņu masa'!D10-'Kubiņu masa'!$D10)/'Kubiņu masa'!$D10*100 -> 0 | E7: =('Kubiņu masa'!E10-'Kubiņu masa'!$D10)/'Kubiņu masa'!$D10*100 -> 3.4965035 | F7: =('Kubiņu masa'!F10-'Kubiņu masa'!$D10)/'Kubiņu masa'!$D10*100 -> 3.4965035 | G7: =('Kubiņu masa'!G10-'Kubiņu masa'!$D10)/'Kubiņu masa'!$D10*100 -> 4.0559441 | H7: =('Kubiņu masa'!H10-'Kubiņu masa'!$D10)/'Kubiņu masa'!$D10*100 -> 4.0559441 | I7: =('Kubiņu masa'!I10-'Kubiņu masa'!$D10)/'Kubiņu masa'!$D10*100 -> 5.4545455 | J7: =('Kubiņu masa'!J10-'Kubiņu masa'!$D10)/'Kubiņu masa'!$D10*100 -> 5.4545455 | K7: =('Kubiņu masa'!K10-'Kubiņu masa'!$D10)/'Kubiņu masa'!$D10*100 -> 7.4125874 | ... P7: =('Kubiņu masa'!P10-'Kubiņu masa'!$D10)/'Kubiņu masa'!$D10*100 -> 11.468531 | Q7: daudz
B8: Sl2 | C8: 39 | D8: =('Kubiņu masa'!D11-'Kubiņu masa'!$D11)/'Kubiņu masa'!$D11*100 -> 0 | E8: =('Kubiņu masa'!E11-'Kubiņu masa'!$D11)/'Kubiņu masa'!$D11*100 -> 3.220339 | F8: =('Kubiņu masa'!F11-'Kubiņu masa'!$D11)/'Kubiņu masa'!$D11*100 -> 3.220339 | G8: =('Kubiņu masa'!G11-'Kubiņu masa'!$D11)/'Kubiņu masa'!$D11*100 -> 3.8983051 | H8: =('Kubiņu masa'!H11-'Kubiņu masa'!$D11)/'Kubiņu masa'!$D11*100 -> 3.7288136 | I8: =('Kubiņu masa'!I11-'Kubiņu masa'!$D11)/'Kubiņu masa'!$D11*100 -> 5.0847458 | J8: =('Kubiņu masa'!J11-'Kubiņu masa'!$D11)/'Kubiņu masa'!$D11*100 -> 5.0847458 | K8: =('Kubiņu masa'!K11-'Kubiņu masa'!$D11)/'Kubiņu masa'!$D11*100 -> 6.9491525 | ... P8: =('Kubiņu masa'!P11-'Kubiņu masa'!$D11)/'Kubiņu masa'!$D11*100 -> 10.847458 | Q8: daudz
C9: 55 | D9: =('Kubiņu masa'!D12-'Kubiņu masa'!$D12)/'Kubiņu masa'!$D12*100 -> 0 | E9: =('Kubiņu masa'!E12-'Kubiņu masa'!$D12)/'Kubiņu masa'!$D12*100 -> 3.2679739 | F9: =('Kubiņu masa'!F12-'Kubiņu masa'!$D12)/'Kubiņu masa'!$D12*100 -> 3.2679739 | G9: =('Kubiņu masa'!G12-'Kubiņu masa'!$D12)/'Kubiņu masa'!$D12*100 -> 3.9215686 | H9: =('Kubiņu masa'!H12-'Kubiņu masa'!$D12)/'Kubiņu masa'!$D12*100 -> 3.9215686 | I9: =('Kubiņu masa'!I12-'Kubiņu masa'!$D12)/'Kubiņu masa'!$D12*100 -> 5.2287582 | J9: =('Kubiņu masa'!J12-'Kubiņu masa'!$D12)/'Kubiņu masa'!$D12*100 -> 5.2287582 | K9: =('Kubiņu masa'!K12-'Kubiņu masa'!$D12)/'Kubiņu masa'!$D12*100 -> 7.1895425 | ... P9: =('Kubiņu masa'!P12-'Kubiņu masa'!$D12)/'Kubiņu masa'!$D12*100 -> 11.111111 | Q9: daudz
C10: 122 | D10: =('Kubiņu masa'!D13-'Kubiņu masa'!$D13)/'Kubiņu masa'!$D13*100 -> 0 | E10: =('Kubiņu masa'!E13-'Kubiņu masa'!$D13)/'Kubiņu masa'!$D13*100 -> 3.236246 | F10: =('Kubiņu masa'!F13-'Kubiņu masa'!$D13)/'Kubiņu masa'!$D13*100 -> 3.0744337 | G10: =('Kubiņu masa'!G13-'Kubiņu masa'!$D13)/'Kubiņu masa'!$D13*100 -> 3.7216828 | H10: =('Kubiņu masa'!H13-'Kubiņu masa'!$D13)/'Kubiņu masa'!$D13*100 -> 3.7216828 | I10: =('Kubiņu masa'!I13-'Kubiņu masa'!$D13)/'Kubiņu masa'!$D13*100 -> 4.8543689 | J10: =('Kubiņu masa'!J13-'Kubiņu masa'!$D13)/'Kubiņu masa'!$D13*100 -> 5.0161812 | K10: =('Kubiņu masa'!K13-'Kubiņu masa'!$D13)/'Kubiņu masa'!$D13*100 -> 6.7961165 | ... P10: =('Kubiņu masa'!P13-'Kubiņu masa'!$D13)/'Kubiņu masa'!$D13*100 -> 10.679612 | Q10: daudz
B11: Sl3 | C11: 66 | D11: =('Kubiņu masa'!D14-'Kubiņu masa'!$D14)/'Kubiņu masa'!$D14*100 -> 0 | E11: =('Kubiņu masa'!E14-'Kubiņu masa'!$D14)/'Kubiņu masa'!$D14*100 -> 3.4578147 | F11: =('Kubiņu masa'!F14-'Kubiņu masa'!$D14)/'Kubiņu masa'!$D14*100 -> 3.4578147 | G11: =('Kubiņu masa'!G14-'Kubiņu masa'!$D14)/'Kubiņu masa'!$D14*100 -> 4.1493776 | H11: =('Kubiņu masa'!H14-'Kubiņu masa'!$D14)/'Kubiņu masa'!$D14*100 -> 4.1493776 | I11: =('Kubiņu masa'!I14-'Kubiņu masa'!$D14)/'Kubiņu masa'!$D14*100 -> 5.2558783 | J11: =('Kubiņu masa'!J14-'Kubiņu masa'!$D14)/'Kubiņu masa'!$D14*100 -> 5.3941909 | K11: =('Kubiņu masa'!K14-'Kubiņu masa'!$D14)/'Kubiņu masa'!$D14*100 -> 7.3305671 | ... P11: =('Kubiņu masa'!P14-'Kubiņu masa'!$D14)/'Kubiņu masa'!$D14*100 -> 11.341632 | Q11: daudz
C12: 142 | D12: =('Kubiņu masa'!D15-'Kubiņu masa'!$D15)/'Kubiņu masa'!$D15*100 -> 0 | E12: =('Kubiņu masa'!E15-'Kubiņu masa'!$D15)/'Kubiņu masa'!$D15*100 -> 3.6842105 | F12: =('Kubiņu masa'!F15-'Kubiņu masa'!$D15)/'Kubiņu masa'!$D15*100 -> 3.5526316 | G12: =('Kubiņu masa'!G15-'Kubiņu masa'!$D15)/'Kubiņu masa'!$D15*100 -> 4.3421053 | H12: =('Kubiņu masa'!H15-'Kubiņu masa'!$D15)/'Kubiņu masa'!$D15*100 -> 4.3421053 | I12: =('Kubiņu masa'!I15-'Kubiņu masa'!$D15)/'Kubiņu masa'!$D15*100 -> 5.5263158 | J12: =('Kubiņu masa'!J15-'Kubiņu masa'!$D15)/'Kubiņu masa'!$D15*100 -> 5.5263158 | K12: =('Kubiņu masa'!K15-'Kubiņu masa'!$D15)/'Kubiņu masa'!$D15*100 -> 7.5 | ... P12: =('Kubiņu masa'!P15-'Kubiņu masa'!$D15)/'Kubiņu masa'!$D15*100 -> 11.710526 | Q12: daudz
C13: 147 | D13: =('Kubiņu masa'!D16-'Kubiņu masa'!$D16)/'Kubiņu masa'!$D16*100 -> 0 | E13: =('Kubiņu masa'!E16-'Kubiņu masa'!$D16)/'Kubiņu masa'!$D16*100 -> 3.638814 | F13: =('Kubiņu masa'!F16-'Kubiņu masa'!$D16)/'Kubiņu masa'!$D16*100 -> 3.638814 | G13: =('Kubiņu masa'!G16-'Kubiņu masa'!$D16)/'Kubiņu masa'!$D16*100 -> 4.3126685 | H13: =('Kubiņu masa'!H16-'Kubiņu masa'!$D16)/'Kubiņu masa'!$D16*100 -> 4.3126685 | I13: =('Kubiņu masa'!I16-'Kubiņu masa'!$D16)/'Kubiņu masa'!$D16*100 -> 5.5256065 | J13: =('Kubiņu masa'!J16-'Kubiņu masa'!$D16)/'Kubiņu masa'!$D16*100 -> 5.6603774 | K13: =('Kubiņu masa'!K16-'Kubiņu masa'!$D16)/'Kubiņu masa'!$D16*100 -> 7.6819407 | ... P13: =('Kubiņu masa'!P16-'Kubiņu masa'!$D16)/'Kubiņu masa'!$D16*100 -> 11.725067 | Q13: daudz
B14: Sl4 | C14: 75 | D14: =('Kubiņu masa'!D17-'Kubiņu masa'!$D17)/'Kubiņu masa'!$D17*100 -> 0 | E14: =('Kubiņu masa'!E17-'Kubiņu masa'!$D17)/'Kubiņu masa'!$D17*100 -> 3.298153 | F14: =('Kubiņu masa'!F17-'Kubiņu masa'!$D17)/'Kubiņu masa'!$D17*100 -> 3.298153 | G14: =('Kubiņu masa'!G17-'Kubiņu masa'!$D17)/'Kubiņu masa'!$D17*100 -> 3.9577836 | H14: =('Kubiņu masa'!H17-'Kubiņu masa'!$D17)/'Kubiņu masa'!$D17*100 -> 3.9577836 | I14: =('Kubiņu masa'!I17-'Kubiņu masa'!$D17)/'Kubiņu masa'!$D17*100 -> 5.1451187 | J14: =('Kubiņu masa'!J17-'Kubiņu masa'!$D17)/'Kubiņu masa'!$D17*100 -> 5.1451187 | K14: =('Kubiņu masa'!K17-'Kubiņu masa'!$D17)/'Kubiņu masa'!$D17*100 -> 6.8601583 | ... P14: =('Kubiņu masa'!P17-'Kubiņu masa'!$D17)/'Kubiņu masa'!$D17*100 -> 10.422164 | Q14: maz
C15: 81 | D15: =('Kubiņu masa'!D18-'Kubiņu masa'!$D18)/'Kubiņu masa'!$D18*100 -> 0 | E15: =('Kubiņu masa'!E18-'Kubiņu masa'!$D18)/'Kubiņu masa'!$D18*100 -> 3.2808399 | F15: =('Kubiņu masa'!F18-'Kubiņu masa'!$D18)/'Kubiņu masa'!$D18*100 -> 3.4120735 | G15: =('Kubiņu masa'!G18-'Kubiņu masa'!$D18)/'Kubiņu masa'!$D18*100 -> 3.9370079 | H15: =('Kubiņu masa'!H18-'Kubiņu masa'!$D18)/'Kubiņu masa'!$D18*100 -> 3.9370079 | I15: =('Kubiņu masa'!I18-'Kubiņu masa'!$D18)/'Kubiņu masa'!$D18*100 -> 5.1181102 | J15: =('Kubiņu masa'!J18-'Kubiņu masa'!$D18)/'Kubiņu masa'!$D18*100 -> 5.1181102 | K15: =('Kubiņu masa'!K18-'Kubiņu masa'!$D18)/'Kubiņu masa'!$D18*100 -> 6.824147 | ... P15: =('Kubiņu masa'!P18-'Kubiņu masa'!$D18)/'Kubiņu masa'!$D18*100 -> 10.367454 | Q15: nav
C16: 91 | D16: =('Kubiņu masa'!D19-'Kubiņu masa'!$D19)/'Kubiņu masa'!$D19*100 -> 0 | E16: =('Kubiņu masa'!E19-'Kubiņu masa'!$D19)/'Kubiņu masa'!$D19*100 -> 3.1969309 | F16: =('Kubiņu masa'!F19-'Kubiņu masa'!$D19)/'Kubiņu masa'!$D19*100 -> 3.1969309 | G16: =('Kubiņu masa'!G19-'Kubiņu masa'!$D19)/'Kubiņu masa'!$D19*100 -> 3.8363171 | H16: =('Kubiņu masa'!H19-'Kubiņu masa'!$D19)/'Kubiņu masa'!$D19*100 -> 3.8363171 | I16: =('Kubiņu masa'!I19-'Kubiņu masa'!$D19)/'Kubiņu masa'!$D19*100 -> 4.9872123 | J16: =('Kubiņu masa'!J19-'Kubiņu masa'!$D19)/'Kubiņu masa'!$D19*100 -> 4.9872123 | K16: =('Kubiņu masa'!K19-'Kubiņu masa'!$D19)/'Kubiņu masa'!$D19*100 -> 6.6496164 | ... P16: =('Kubiņu masa'!P19-'Kubiņu masa'!$D19)/'Kubiņu masa'!$D19*100 -> 10.102302 | Q16: nav
B17: Sa1 | C17: 103 | D17: =('Kubiņu masa'!D20-'Kubiņu masa'!$D20)/'Kubiņu masa'!$D20*100 -> 0 | E17: =('Kubiņu masa'!E20-'Kubiņu masa'!$D20)/'Kubiņu masa'!$D20*100 -> 2.8571429 | F17: =('Kubiņu masa'!F20-'Kubiņu masa'!$D20)/'Kubiņu masa'!$D20*100 -> 2.8571429 | G17: =('Kubiņu masa'!G20-'Kubiņu masa'!$D20)/'Kubiņu masa'!$D20*100 -> 3.6363636 | H17: =('Kubiņu masa'!H20-'Kubiņu masa'!$D20)/'Kubiņu masa'!$D20*100 -> 3.6363636 | I17: =('Kubiņu masa'!I20-'Kubiņu masa'!$D20)/'Kubiņu masa'!$D20*100 -> 4.9350649 | J17: =('Kubiņu masa'!J20-'Kubiņu masa'!$D20)/'Kubiņu masa'!$D20*100 -> 4.9350649 | K17: =('Kubiņu masa'!K20-'Kubiņu masa'!$D20)/'Kubiņu masa'!$D20*100 -> 7.2727273 | ... P17: =('Kubiņu masa'!P20-'Kubiņu masa'!$D20)/'Kubiņu masa'!$D20*100 -> 11.948052 | Q17: daudz
C18: 283 | D18: =('Kubiņu masa'!D21-'Kubiņu masa'!$D21)/'Kubiņu masa'!$D21*100 -> 0 | E18: =('Kubiņu masa'!E21-'Kubiņu masa'!$D21)/'Kubiņu masa'!$D21*100 -> 3.2581454 | F18: =('Kubiņu masa'!F21-'Kubiņu masa'!$D21)/'Kubiņu masa'!$D21*100 -> 3.0075188 | G18: =('Kubiņu masa'!G21-'Kubiņu masa'!$D21)/'Kubiņu masa'!$D21*100 -> 3.7593985 | H18: =('Kubiņu masa'!H21-'Kubiņu masa'!$D21)/'Kubiņu masa'!$D21*100 -> 3.7593985 | I18: =('Kubiņu masa'!I21-'Kubiņu masa'!$D21)/'Kubiņu masa'!$D21*100 -> 5.0125313 | J18: =('Kubiņu masa'!J21-'Kubiņu masa'!$D21)/'Kubiņu masa'!$D21*100 -> 5.2631579 | K18: =('Kubiņu masa'!K21-'Kubiņu masa'!$D21)/'Kubiņu masa'!$D21*100 -> 7.518797 | ... P18: =('Kubiņu masa'!P21-'Kubiņu masa'!$D21)/'Kubiņu masa'!$D21*100 -> 12.531328 | Q18: daudz
C19: 323 | D19: =('Kubiņu masa'!D22-'Kubiņu masa'!$D22)/'Kubiņu masa'!$D22*100 -> 0 | E19: =('Kubiņu masa'!E22-'Kubiņu masa'!$D22)/'Kubiņu masa'!$D22*100 -> 3.087886 | F19: =('Kubiņu masa'!F22-'Kubiņu masa'!$D22)/'Kubiņu masa'!$D22*100 -> 3.087886 | G19: =('Kubiņu masa'!G22-'Kubiņu masa'!$D22)/'Kubiņu masa'!$D22*100 -> 3.3254157 | H19: =('Kubiņu masa'!H22-'Kubiņu masa'!$D22)/'Kubiņu masa'!$D22*100 -> 3.3254157 | I19: =('Kubiņu masa'!I22-'Kubiņu masa'!$D22)/'Kubiņu masa'!$D22*100 -> 4.5130641 | J19: =('Kubiņu masa'!J22-'Kubiņu masa'!$D22)/'Kubiņu masa'!$D22*100 -> 4.7505938 | K19: =('Kubiņu masa'!K22-'Kubiņu masa'!$D22)/'Kubiņu masa'!$D22*100 -> 6.888361 | ... P19: =('Kubiņu masa'!P22-'Kubiņu masa'!$D22)/'Kubiņu masa'!$D22*100 -> 11.638955 | Q19: daudz
B20: Sa2 | C20: 203 | D20: =('Kubiņu masa'!D23-'Kubiņu masa'!$D23)/'Kubiņu masa'!$D23*100 -> 0 | E20: =('Kubiņu masa'!E23-'Kubiņu masa'!$D23)/'Kubiņu masa'!$D23*100 -> 3.2064128 | F20: =('Kubiņu masa'!F23-'Kubiņu masa'!$D23)/'Kubiņu masa'!$D23*100 -> 3.2064128 | G20: =('Kubiņu masa'!G23-'Kubiņu masa'!$D23)/'Kubiņu masa'!$D23*100 -> 3.6072144 | H20: =('Kubiņu masa'!H23-'Kubiņu masa'!$D23)/'Kubiņu masa'!$D23*100 -> 3.6072144 | I20: =('Kubiņu masa'!I23-'Kubiņu masa'!$D23)/'Kubiņu masa'!$D23*100 -> 4.6092184 | J20: =('Kubiņu masa'!J23-'Kubiņu masa'!$D23)/'Kubiņu masa'!$D23*100 -> 4.8096192 | K20: =('Kubiņu masa'!K23-'Kubiņu masa'!$D23)/'Kubiņu masa'!$D23*100 -> 6.8136273 | ... P20: =('Kubiņu masa'!P23-'Kubiņu masa'!$D23)/'Kubiņu masa'!$D23*100 -> 10.621242 | Q20: daudz
C21: 272 | D21: =('Kubiņu masa'!D24-'Kubiņu masa'!$D24)/'Kubiņu masa'!$D24*100 -> 0 | E21: =('Kubiņu masa'!E24-'Kubiņu masa'!$D24)/'Kubiņu masa'!$D24*100 -> 3.4552846 | F21: =('Kubiņu masa'!F24-'Kubiņu masa'!$D24)/'Kubiņu masa'!$D24*100 -> 3.2520325 | G21: =('Kubiņu masa'!G24-'Kubiņu masa'!$D24)/'Kubiņu masa'!$D24*100 -> 3.8617886 | H21: =('Kubiņu masa'!H24-'Kubiņu masa'!$D24)/'Kubiņu masa'!$D24*100 -> 3.8617886 | I21: =('Kubiņu masa'!I24-'Kubiņu masa'!$D24)/'Kubiņu masa'!$D24*100 -> 5.0813008 | J21: =('Kubiņu masa'!J24-'Kubiņu masa'!$D24)/'Kubiņu masa'!$D24*100 -> 5.0813008 | K21: =('Kubiņu masa'!K24-'Kubiņu masa'!$D24)/'Kubiņu masa'!$D24*100 -> 7.1138211 | ... P21: =('Kubiņu masa'!P24-'Kubiņu masa'!$D24)/'Kubiņu masa'!$D24*100 -> 10.97561 | Q21: daudz
C22: 266 | D22: =('Kubiņu masa'!D25-'Kubiņu masa'!$D25)/'Kubiņu masa'!$D25*100 -> 0 | E22: =('Kubiņu masa'!E25-'Kubiņu masa'!$D25)/'Kubiņu masa'!$D25*100 -> 3.1936128 | F22: =('Kubiņu masa'!F25-'Kubiņu masa'!$D25)/'Kubiņu masa'!$D25*100 -> 3.1936128 | G22: =('Kubiņu masa'!G25-'Kubiņu masa'!$D25)/'Kubiņu masa'!$D25*100 -> 3.7924152 | H22: =('Kubiņu masa'!H25-'Kubiņu masa'!$D25)/'Kubiņu masa'!$D25*100 -> 3.7924152 | I22: =('Kubiņu masa'!I25-'Kubiņu masa'!$D25)/'Kubiņu masa'!$D25*100 -> 4.7904192 | J22: =('Kubiņu masa'!J25-'Kubiņu masa'!$D25)/'Kubiņu masa'!$D25*100 -> 4.99002 | K22: =('Kubiņu masa'!K25-'Kubiņu masa'!$D25)/'Kubiņu masa'!$D25*100 -> 6.7864271 | ... P22: =('Kubiņu masa'!P25-'Kubiņu masa'!$D25)/'Kubiņu masa'!$D25*100 -> 10.578842 | Q22: daudz
B23: Sa3 | C23: 168 | D23: =('Kubiņu masa'!D26-'Kubiņu masa'!$D26)/'Kubiņu masa'!$D26*100 -> 0 | E23: =('Kubiņu masa'!E26-'Kubiņu masa'!$D26)/'Kubiņu masa'!$D26*100 -> 3.626943 | F23: =('Kubiņu masa'!F26-'Kubiņu masa'!$D26)/'Kubiņu masa'!$D26*100 -> 3.626943 | G23: =('Kubiņu masa'!G26-'Kubiņu masa'!$D26)/'Kubiņu masa'!$D26*100 -> 4.3177893 | H23: =('Kubiņu masa'!H26-'Kubiņu masa'!$D26)/'Kubiņu masa'!$D26*100 -> 4.3177893 | I23: =('Kubiņu masa'!I26-'Kubiņu masa'!$D26)/'Kubiņu masa'!$D26*100 -> 5.3540587 | J23: =('Kubiņu masa'!J26-'Kubiņu masa'!$D26)/'Kubiņu masa'!$D26*100 -> 5.5267703 | K23: =('Kubiņu masa'!K26-'Kubiņu masa'!$D26)/'Kubiņu masa'!$D26*100 -> 7.5993092 | ... P23: =('Kubiņu masa'!P26-'Kubiņu masa'!$D26)/'Kubiņu masa'!$D26*100 -> 11.744387 | Q23: daudz
C24: 343 | D24: =('Kubiņu masa'!D27-'Kubiņu masa'!$D27)/'Kubiņu masa'!$D27*100 -> 0 | E24: =('Kubiņu masa'!E27-'Kubiņu masa'!$D27)/'Kubiņu masa'!$D27*100 -> 3.6423841 | F24: =('Kubiņu masa'!F27-'Kubiņu masa'!$D27)/'Kubiņu masa'!$D27*100 -> 3.6423841 | G24: =('Kubiņu masa'!G27-'Kubiņu masa'!$D27)/'Kubiņu masa'!$D27*100 -> 4.3046358 | H24: =('Kubiņu masa'!H27-'Kubiņu masa'!$D27)/'Kubiņu masa'!$D27*100 -> 4.3046358 | I24: =('Kubiņu masa'!I27-'Kubiņu masa'!$D27)/'Kubiņu masa'!$D27*100 -> 5.6291391 | J24: =('Kubiņu masa'!J27-'Kubiņu masa'!$D27)/'Kubiņu masa'!$D27*100 -> 5.794702 | K24: =('Kubiņu masa'!K27-'Kubiņu masa'!$D27)/'Kubiņu masa'!$D27*100 -> 7.9470199 | ... P24: =('Kubiņu masa'!P27-'Kubiņu masa'!$D27)/'Kubiņu masa'!$D27*100 -> 12.417219 | Q24: daudz
C25: 58 | D25: =('Kubiņu masa'!D28-'Kubiņu masa'!$D28)/'Kubiņu masa'!$D28*100 -> 0 | E25: =('Kubiņu masa'!E28-'Kubiņu masa'!$D28)/'Kubiņu masa'!$D28*100 -> 3.5058431 | F25: =('Kubiņu masa'!F28-'Kubiņu masa'!$D28)/'Kubiņu masa'!$D28*100 -> 3.5058431 | G25: =('Kubiņu masa'!G28-'Kubiņu masa'!$D28)/'Kubiņu masa'!$D28*100 -> 4.1736227 | H25: =('Kubiņu masa'!H28-'Kubiņu masa'!$D28)/'Kubiņu masa'!$D28*100 -> 4.1736227 | I25: =('Kubiņu masa'!I28-'Kubiņu masa'!$D28)/'Kubiņu masa'!$D28*100 -> 5.509182 | J25: =('Kubiņu masa'!J28-'Kubiņu masa'!$D28)/'Kubiņu masa'!$D28*100 -> 5.6761269 | K25: =('Kubiņu masa'!K28-'Kubiņu masa'!$D28)/'Kubiņu masa'!$D28*100 -> 7.8464107 | ... P25: =('Kubiņu masa'!P28-'Kubiņu masa'!$D28)/'Kubiņu masa'!$D28*100 -> 12.520868 | Q25: daudz
B26: Sa4 | C26: 187 | D26: =('Kubiņu masa'!D29-'Kubiņu masa'!$D29)/'Kubiņu masa'!$D29*100 -> 0 | E26: =('Kubiņu masa'!E29-'Kubiņu masa'!$D29)/'Kubiņu masa'!$D29*100 -> 2.8497409 | F26: =('Kubiņu masa'!F29-'Kubiņu masa'!$D29)/'Kubiņu masa'!$D29*100 -> 2.8497409 | G26: =('Kubiņu masa'!G29-'Kubiņu masa'!$D29)/'Kubiņu masa'!$D29*100 -> 3.3678756 | H26: =('Kubiņu masa'!H29-'Kubiņu masa'!$D29)/'Kubiņu masa'!$D29*100 -> 3.3678756 | I26: =('Kubiņu masa'!I29-'Kubiņu masa'!$D29)/'Kubiņu masa'!$D29*100 -> 4.4041451 | J26: =('Kubiņu masa'!J29-'Kubiņu masa'!$D29)/'Kubiņu masa'!$D29*100 -> 4.6632124 | K26: =('Kubiņu masa'!K29-'Kubiņu masa'!$D29)/'Kubiņu masa'!$D29*100 -> 6.4766839 | ... P26: =('Kubiņu masa'!P29-'Kubiņu masa'!$D29)/'Kubiņu masa'!$D29*100 -> 10.103627 | Q26: daudz
C27: 248 | D27: =('Kubiņu masa'!D30-'Kubiņu masa'!$D30)/'Kubiņu masa'!$D30*100 -> 0 | E27: =('Kubiņu masa'!E30-'Kubiņu masa'!$D30)/'Kubiņu masa'!$D30*100 -> 2.8776978 | F27: =('Kubiņu masa'!F30-'Kubiņu masa'!$D30)/'Kubiņu masa'!$D30*100 -> 2.8776978 | G27: =('Kubiņu masa'!G30-'Kubiņu masa'!$D30)/'Kubiņu masa'!$D30*100 -> 3.5971223 | H27: =('Kubiņu masa'!H30-'Kubiņu masa'!$D30)/'Kubiņu masa'!$D30*100 -> 3.5971223 | I27: =('Kubiņu masa'!I30-'Kubiņu masa'!$D30)/'Kubiņu masa'!$D30*100 -> 4.5563549 | J27: =('Kubiņu masa'!J30-'Kubiņu masa'!$D30)/'Kubiņu masa'!$D30*100 -> 4.7961631 | K27: =('Kubiņu masa'!K30-'Kubiņu masa'!$D30)/'Kubiņu masa'!$D30*100 -> 6.7146283 | ... P27: =('Kubiņu masa'!P30-'Kubiņu masa'!$D30)/'Kubiņu masa'!$D30*100 -> 10.311751 | Q27: daudz
C28: 212 | D28: =('Kubiņu masa'!D31-'Kubiņu masa'!$D31)/'Kubiņu masa'!$D31*100 -> 0 | E28: =('Kubiņu masa'!E31-'Kubiņu masa'!$D31)/'Kubiņu masa'!$D31*100 -> 2.7848101 | F28: =('Kubiņu masa'!F31-'Kubiņu masa'!$D31)/'Kubiņu masa'!$D31*100 -> 2.5316456 | G28: =('Kubiņu masa'!G31-'Kubiņu masa'!$D31)/'Kubiņu masa'!$D31*100 -> 3.2911392 | H28: =('Kubiņu masa'!H31-'Kubiņu masa'!$D31)/'Kubiņu masa'!$D31*100 -> 3.2911392 | I28: =('Kubiņu masa'!I31-'Kubiņu masa'!$D31)/'Kubiņu masa'!$D31*100 -> 4.3037975 | J28: =('Kubiņu masa'!J31-'Kubiņu masa'!$D31)/'Kubiņu masa'!$D31*100 -> 4.3037975 | K28: =('Kubiņu masa'!K31-'Kubiņu masa'!$D31)/'Kubiņu masa'!$D31*100 -> 6.3291139 | ... P28: =('Kubiņu masa'!P31-'Kubiņu masa'!$D31)/'Kubiņu masa'!$D31*100 -> 9.8734177 | Q28: daudz
A29: hito/sub | B29: Sl1 | C29: 5 | D29: =('Kubiņu masa'!D32-'Kubiņu masa'!$D32)/'Kubiņu masa'!$D32*100 -> 0 | E29: =('Kubiņu masa'!E32-'Kubiņu masa'!$D32)/'Kubiņu masa'!$D32*100 -> 3.4340659 | F29: =('Kubiņu masa'!F32-'Kubiņu masa'!$D32)/'Kubiņu masa'!$D32*100 -> 3.2967033 | G29: =('Kubiņu masa'!G32-'Kubiņu masa'!$D32)/'Kubiņu masa'!$D32*100 -> 3.9835165 | H29: =('Kubiņu masa'!H32-'Kubiņu masa'!$D32)/'Kubiņu masa'!$D32*100 -> 3.9835165 | I29: =('Kubiņu masa'!I32-'Kubiņu masa'!$D32)/'Kubiņu masa'!$D32*100 -> 5.3571429 | J29: =('Kubiņu masa'!J32-'Kubiņu masa'!$D32)/'Kubiņu masa'!$D32*100 -> 5.3571429 | K29: =('Kubiņu masa'!K32-'Kubiņu masa'!$D32)/'Kubiņu masa'!$D32*100 -> 7.4175824 | ... P29: =('Kubiņu masa'!P32-'Kubiņu masa'!$D32)/'Kubiņu masa'!$D32*100 -> 11.813187 | Q29: nav
C30: 17 | D30: =('Kubiņu masa'!D33-'Kubiņu masa'!$D33)/'Kubiņu masa'!$D33*100 -> 0 | E30: =('Kubiņu masa'!E33-'Kubiņu masa'!$D33)/'Kubiņu masa'!$D33*100 -> 3.1680441 | F30: =('Kubiņu masa'!F33-'Kubiņu masa'!$D33)/'Kubiņu masa'!$D33*100 -> 3.1680441 | G30: =('Kubiņu masa'!G33-'Kubiņu masa'!$D33)/'Kubiņu masa'!$D33*100 -> 3.8567493 | H30: =('Kubiņu masa'!H33-'Kubiņu masa'!$D33)/'Kubiņu masa'!$D33*100 -> 3.8567493 | I30: =('Kubiņu masa'!I33-'Kubiņu masa'!$D33)/'Kubiņu masa'!$D33*100 -> 5.0964187 | J30: =('Kubiņu masa'!J33-'Kubiņu masa'!$D33)/'Kubiņu masa'!$D33*100 -> 5.0964187 | K30: =('Kubiņu masa'!K33-'Kubiņu masa'!$D33)/'Kubiņu masa'!$D33*100 -> 7.1625344 | ... P30: =('Kubiņu masa'!P33-'Kubiņu masa'!$D33)/'Kubiņu masa'!$D33*100 -> 11.432507 | Q30: nav
C31: 99 | D31: =('Kubiņu masa'!D34-'Kubiņu masa'!$D34)/'Kubiņu masa'!$D34*100 -> 0 | E31: =('Kubiņu masa'!E34-'Kubiņu masa'!$D34)/'Kubiņu masa'!$D34*100 -> 3.2608696 | F31: =('Kubiņu masa'!F34-'Kubiņu masa'!$D34)/'Kubiņu masa'!$D34*100 -> 3.125 | G31: =('Kubiņu masa'!G34-'Kubiņu masa'!$D34)/'Kubiņu masa'!$D34*100 -> 3.9402174 | H31: =('Kubiņu masa'!H34-'Kubiņu masa'!$D34)/'Kubiņu masa'!$D34*100 -> 3.9402174 | I31: =('Kubiņu masa'!I34-'Kubiņu masa'!$D34)/'Kubiņu masa'!$D34*100 -> 5.1630435 | J31: =('Kubiņu masa'!J34-'Kubiņu masa'!$D34)/'Kubiņu masa'!$D34*100 -> 5.1630435 | K31: =('Kubiņu masa'!K34-'Kubiņu masa'!$D34)/'Kubiņu masa'!$D34*100 -> 7.3369565 | ... P31: =('Kubiņu masa'!P34-'Kubiņu masa'!$D34)/'Kubiņu masa'!$D34*100 -> 11.820652 | Q31: nav
B32: Sl2 | C32: 37 | D32: =('Kubiņu masa'!D35-'Kubiņu masa'!$D35)/'Kubiņu masa'!$D35*100 -> 0 | E32: =('Kubiņu masa'!E35-'Kubiņu masa'!$D35)/'Kubiņu masa'!$D35*100 -> 3.3101045 | F32: =('Kubiņu masa'!F35-'Kubiņu masa'!$D35)/'Kubiņu masa'!$D35*100 -> 3.3101045 | G32: =('Kubiņu masa'!G35-'Kubiņu masa'!$D35)/'Kubiņu masa'!$D35*100 -> 4.0069686 | H32: =('Kubiņu masa'!H35-'Kubiņu masa'!$D35)/'Kubiņu masa'!$D35*100 -> 4.0069686 | I32: =('Kubiņu masa'!I35-'Kubiņu masa'!$D35)/'Kubiņu masa'!$D35*100 -> 5.2264808 | J32: =('Kubiņu masa'!J35-'Kubiņu masa'!$D35)/'Kubiņu masa'!$D35*100 -> 5.2264808 | K32: =('Kubiņu masa'!K35-'Kubiņu masa'!$D35)/'Kubiņu masa'!$D35*100 -> 7.3170732 | ... P32: =('Kubiņu masa'!P35-'Kubiņu masa'!$D35)/'Kubiņu masa'!$D35*100 -> 11.498258 | Q32: nav
C33: 53 | D33: =('Kubiņu masa'!D36-'Kubiņu masa'!$D36)/'Kubiņu masa'!$D36*100 -> 0 | E33: =('Kubiņu masa'!E36-'Kubiņu masa'!$D36)/'Kubiņu masa'!$D36*100 -> 3.2051282 | F33: =('Kubiņu masa'!F36-'Kubiņu masa'!$D36)/'Kubiņu masa'!$D36*100 -> 3.2051282 | G33: =('Kubiņu masa'!G36-'Kubiņu masa'!$D36)/'Kubiņu masa'!$D36*100 -> 3.8461538 | H33: =('Kubiņu masa'!H36-'Kubiņu masa'!$D36)/'Kubiņu masa'!$D36*100 -> 3.8461538 | I33: =('Kubiņu masa'!I36-'Kubiņu masa'!$D36)/'Kubiņu masa'!$D36*100 -> 5.1282051 | J33: =('Kubiņu masa'!J36-'Kubiņu masa'!$D36)/'Kubiņu masa'!$D36*100 -> 5.1282051 | K33: =('Kubiņu masa'!K36-'Kubiņu masa'!$D36)/'Kubiņu masa'!$D36*100 -> 7.2115385 | ... P33: =('Kubiņu masa'!P36-'Kubiņu masa'!$D36)/'Kubiņu masa'!$D36*100 -> 11.538462 | Q33: nav
C34: 134 | D34: =('Kubiņu masa'!D37-'Kubiņu masa'!$D37)/'Kubiņu masa'!$D37*100 -> 0 | E34: =('Kubiņu masa'!E37-'Kubiņu masa'!$D37)/'Kubiņu masa'!$D37*100 -> 3.1879195 | F34: =('Kubiņu masa'!F37-'Kubiņu masa'!$D37)/'Kubiņu masa'!$D37*100 -> 3.0201342 | G34: =('Kubiņu masa'!G37-'Kubiņu masa'!$D37)/'Kubiņu masa'!$D37*100 -> 3.6912752 | H34: =('Kubiņu masa'!H37-'Kubiņu masa'!$D37)/'Kubiņu masa'!$D37*100 -> 3.6912752 | I34: =('Kubiņu masa'!I37-'Kubiņu masa'!$D37)/'Kubiņu masa'!$D37*100 -> 5.033557 | J34: =('Kubiņu masa'!J37-'Kubiņu masa'!$D37)/'Kubiņu masa'!$D37*100 -> 5.033557 | K34: =('Kubiņu masa'!K37-'Kubiņu masa'!$D37)/'Kubiņu masa'!$D37*100 -> 7.0469799 | ... P34: =('Kubiņu masa'!P37-'Kubiņu masa'!$D37)/'Kubiņu masa'!$D37*100 -> 11.409396 | Q34: nav
B35: Sl3 | C35: 68 | D35: =('Kubiņu masa'!D38-'Kubiņu masa'!$D38)/'Kubiņu masa'!$D38*100 -> 0 | E35: =('Kubiņu masa'!E38-'Kubiņu masa'!$D38)/'Kubiņu masa'!$D38*100 -> 3.4435262 | F35: =('Kubiņu masa'!F38-'Kubiņu masa'!$D38)/'Kubiņu masa'!$D38*100 -> 3.4435262 | G35: =('Kubiņu masa'!G38-'Kubiņu masa'!$D38)/'Kubiņu masa'!$D38*100 -> 4.1322314 | H35: =('Kubiņu masa'!H38-'Kubiņu masa'!$D38)/'Kubiņu masa'!$D38*100 -> 4.1322314 | I35: =('Kubiņu masa'!I38-'Kubiņu masa'!$D38)/'Kubiņu masa'!$D38*100 -> 5.3719008 | J35: =('Kubiņu masa'!J38-'Kubiņu masa'!$D38)/'Kubiņu masa'!$D38*100 -> 5.3719008 | K35: =('Kubiņu masa'!K38-'Kubiņu masa'!$D38)/'Kubiņu masa'!$D38*100 -> 7.4380165 | ... P35: =('Kubiņu masa'!P38-'Kubiņu masa'!$D38)/'Kubiņu masa'!$D38*100 -> 11.570248 | Q35: nav
C36: 143 | D36: =('Kubiņu masa'!D39-'Kubiņu masa'!$D39)/'Kubiņu masa'!$D39*100 -> 0 | E36: =('Kubiņu masa'!E39-'Kubiņu masa'!$D39)/'Kubiņu masa'!$D39*100 -> 3.5182679 | F36: =('Kubiņu masa'!F39-'Kubiņu masa'!$D39)/'Kubiņu masa'!$D39*100 -> 3.5182679 | G36: =('Kubiņu masa'!G39-'Kubiņu masa'!$D39)/'Kubiņu masa'!$D39*100 -> 4.3301759 | H36: =('Kubiņu masa'!H39-'Kubiņu masa'!$D39)/'Kubiņu masa'!$D39*100 -> 4.3301759 | I36: =('Kubiņu masa'!I39-'Kubiņu masa'!$D39)/'Kubiņu masa'!$D39*100 -> 5.6833559 | J36: =('Kubiņu masa'!J39-'Kubiņu masa'!$D39)/'Kubiņu masa'!$D39*100 -> 5.6833559 | K36: =('Kubiņu masa'!K39-'Kubiņu masa'!$D39)/'Kubiņu masa'!$D39*100 -> 7.8484438 | ... P36: =('Kubiņu masa'!P39-'Kubiņu masa'!$D39)/'Kubiņu masa'!$D39*100 -> 12.313938 | Q36: nav
C37: 190 | D37: =('Kubiņu masa'!D40-'Kubiņu masa'!$D40)/'Kubiņu masa'!$D40*100 -> 0 | E37: =('Kubiņu masa'!E40-'Kubiņu masa'!$D40)/'Kubiņu masa'!$D40*100 -> 3.2348805 | F37: =('Kubiņu masa'!F40-'Kubiņu masa'!$D40)/'Kubiņu masa'!$D40*100 -> 3.2348805 | G37: =('Kubiņu masa'!G40-'Kubiņu masa'!$D40)/'Kubiņu masa'!$D40*100 -> 3.9381153 | H37: =('Kubiņu masa'!H40-'Kubiņu masa'!$D40)/'Kubiņu masa'!$D40*100 -> 3.9381153 | I37: =('Kubiņu masa'!I40-'Kubiņu masa'!$D40)/'Kubiņu masa'!$D40*100 -> 5.0632911 | J37: =('Kubiņu masa'!J40-'Kubiņu masa'!$D40)/'Kubiņu masa'!$D40*100 -> 5.0632911 | K37: =('Kubiņu masa'!K40-'Kubiņu masa'!$D40)/'Kubiņu masa'!$D40*100 -> 7.0323488 | ... P37: =('Kubiņu masa'!P40-'Kubiņu masa'!$D40)/'Kubiņu masa'!$D40*100 -> 11.111111 | Q37: nav
B38: Sl4 | C38: 158 | D38: =('Kubiņu masa'!D41-'Kubiņu masa'!$D41)/'Kubiņu masa'!$D41*100 -> 0 | E38: =('Kubiņu masa'!E41-'Kubiņu masa'!$D41)/'Kubiņu masa'!$D41*100 -> 3.2806804 | F38: =('Kubiņu masa'!F41-'Kubiņu masa'!$D41)/'Kubiņu masa'!$D41*100 -> 3.2806804 | G38: =('Kubiņu masa'!G41-'Kubiņu masa'!$D41)/'Kubiņu masa'!$D41*100 -> 4.0097205 | H38: =('Kubiņu masa'!H41-'Kubiņu masa'!$D41)/'Kubiņu masa'!$D41*100 -> 4.0097205 | I38: =('Kubiņu masa'!I41-'Kubiņu masa'!$D41)/'Kubiņu masa'!$D41*100 -> 5.1032807 | J38: =('Kubiņu masa'!J41-'Kubiņu masa'!$D41)/'Kubiņu masa'!$D41*100 -> 5.1032807 | K38: =('Kubiņu masa'!K41-'Kubiņu masa'!$D41)/'Kubiņu masa'!$D41*100 -> 7.0473876 | ... P38: =('Kubiņu masa'!P41-'Kubiņu masa'!$D41)/'Kubiņu masa'!$D41*100 -> 10.692588 | Q38: nav
C39: 169 | D39: =('Kubiņu masa'!D42-'Kubiņu masa'!$D42)/'Kubiņu masa'!$D42*100 -> 0 | E39: =('Kubiņu masa'!E42-'Kubiņu masa'!$D42)/'Kubiņu masa'!$D42*100 -> 3.2911392 | F39: =('Kubiņu masa'!F42-'Kubiņu masa'!$D42)/'Kubiņu masa'!$D42*100 -> 3.164557 | G39: =('Kubiņu masa'!G42-'Kubiņu masa'!$D42)/'Kubiņu masa'!$D42*100 -> 3.7974684 | H39: =('Kubiņu masa'!H42-'Kubiņu masa'!$D42)/'Kubiņu masa'!$D42*100 -> 3.7974684 | I39: =('Kubiņu masa'!I42-'Kubiņu masa'!$D42)/'Kubiņu masa'!$D42*100 -> 4.9367089 | J39: =('Kubiņu masa'!J42-'Kubiņu masa'!$D42)/'Kubiņu masa'!$D42*100 -> 4.9367089 | K39: =('Kubiņu masa'!K42-'Kubiņu masa'!$D42)/'Kubiņu masa'!$D42*100 -> 6.9620253 | ... P39: =('Kubiņu masa'!P42-'Kubiņu masa'!$D42)/'Kubiņu masa'!$D42*100 -> 10.632911 | Q39: nav
C40: 174 | D40: =('Kubiņu masa'!D43-'Kubiņu masa'!$D43)/'Kubiņu masa'!$D43*100 -> 0 | E40: =('Kubiņu masa'!E43-'Kubiņu masa'!$D43)/'Kubiņu masa'!$D43*100 -> 3.1537451 | F40: =('Kubiņu masa'!F43-'Kubiņu masa'!$D43)/'Kubiņu masa'!$D43*100 -> 3.1537451 | G40: =('Kubiņu masa'!G43-'Kubiņu masa'!$D43)/'Kubiņu masa'!$D43*100 -> 3.8107753 | H40: =('Kubiņu masa'!H43-'Kubiņu masa'!$D43)/'Kubiņu masa'!$D43*100 -> 3.8107753 | I40: =('Kubiņu masa'!I43-'Kubiņu masa'!$D43)/'Kubiņu masa'!$D43*100 -> 4.9934297 | J40: =('Kubiņu masa'!J43-'Kubiņu masa'!$D43)/'Kubiņu masa'!$D43*100 -> 4.9934297 | K40: =('Kubiņu masa'!K43-'Kubiņu masa'!$D43)/'Kubiņu masa'!$D43*100 -> 6.9645204 | ... P40: =('Kubiņu masa'!P43-'Kubiņu masa'!$D43)/'Kubiņu masa'!$D43*100 -> 10.775296 | Q40: maz
...

Sheet Statistikai
A1: apstrade | B1: substrate | C1: id | D1: rh | E1: date | F1: humidity% | G1: masa | H1: udens | I1: tilpumprocenti
A2: sub | B2: BSD1 | C2: 9 | D2: 50 | E2: 2025-11-26 | F2: 3.9187228 | G2: 7.16 | H2: =G2-'Kubiņu masa'!D8 -> 0.27 | I2: =H2/27*100 -> 1
A3: sub | B3: BSD1 | C3: 27 | D3: 50 | E3: 2025-11-26 | F3: 3.4674064 | G3: 7.46 | H3: =G3-'Kubiņu masa'!D9 -> 0.25 | I3: =H3/27*100 -> 0.92592593
A4: sub | B4: BSD1 | C4: 106 | D4: 50 | E4: 2025-11-26 | F4: 3.4965035 | G4: 7.4 | H4: =G4-'Kubiņu masa'!D10 -> 0.25 | I4: =H4/27*100 -> 0.92592593
A5: sub | B5: BSD2 | C5: 39 | D5: 50 | E5: 2025-11-26 | F5: 3.220339 | G5: 6.09 | H5: =G5-'Kubiņu masa'!D11 -> 0.19 | I5: =H5/27*100 -> 0.7037037
A6: sub | B6: BSD2 | C6: 55 | D6: 50 | E6: 2025-11-26 | F6: 3.2679739 | G6: 6.32 | H6: =G6-'Kubiņu masa'!D12 -> 0.2 | I6: =H6/27*100 -> 0.74074074
A7: sub | B7: BSD2 | C7: 122 | D7: 50 | E7: 2025-11-26 | F7: 3.236246 | G7: 6.38 | H7: =G7-'Kubiņu masa'!D13 -> 0.2 | I7: =H7/27*100 -> 0.74074074
A8: sub | B8: BSD3 | C8: 66 | D8: 50 | E8: 2025-11-26 | F8: 3.4578147 | G8: 7.48 | H8: =G8-'Kubiņu masa'!D14 -> 0.25 | I8: =H8/27*100 -> 0.92592593
A9: sub | B9: BSD3 | C9: 142 | D9: 50 | E9: 2025-11-26 | F9: 3.6842105 | G9: 7.88 | H9: =G9-'Kubiņu masa'!D15 -> 0.28 | I9: =H9/27*100 -> 1.037037
A10: sub | B10: BSD3 | C10: 147 | D10: 50 | E10: 2025-11-26 | F10: 3.638814 | G10: 7.69 | H10: =G10-'Kubiņu masa'!D16 -> 0.27 | I10: =H10/27*100 -> 1
A11: sub | B11: BSD4 | C11: 75 | D11: 50 | E11: 2025-11-26 | F11: 3.298153 | G11: 7.83 | H11: =G11-'Kubiņu masa'!D17 -> 0.25 | I11: =H11/27*100 -> 0.92592593
A12: sub | B12: BSD4 | C12: 81 | D12: 50 | E12: 2025-11-26 | F12: 3.2808399 | G12: 7.87 | H12: =G12-'Kubiņu masa'!D18 -> 0.25 | I12: =H12/27*100 -> 0.92592593
A13: sub | B13: BSD4 | C13: 91 | D13: 50 | E13: 2025-11-26 | F13: 3.1969309 | G13: 8.07 | H13: =G13-'Kubiņu masa'!D19 -> 0.25 | I13: =H13/27*100 -> 0.92592593
... A49: hito_sub | B49: WS4 | C49: 218 | D49: 50 | E49: 2025-11-26 | F49: 2.3866348 | G49: 4.29 | H49: =G49-'Kubiņu masa'!D55 -> 0.1 | I49: =H49/27*100 -> 0.37037037
A50: ref | B50: BP | C50: 32 | D50: 50 | E50: 2025-11-26 | F50: 3.9973788 | G50: 15.87 | H50: =G50-'Kubiņu masa'!D56 -> 0.61 | I50: =H50/15*100 -> 4.0666667
A51: ref | B51: BP | C51: 33 | D51: 50 | E51: 2025-11-26 | F51: 3.7275064 | G51: 16.14 | H51: =G51-'Kubiņu masa'!D57 -> 0.58 | I51: =H51/15*100 -> 3.8666667
A52: ref | B52: BP | C52: 34 | D52: 50 | E52: 2025-11-26 | F52: 3.5580524 | G52: 16.59 | H52: =G52-'Kubiņu masa'!D58 -> 0.57 | I52: =H52/15*100 -> 3.8
A53: ref | B53: mMDF | C53: 50 | D53: 50 | E53: 2025-11-26 | F53: 2.82523 | G53: 15.65 | H53: =G53-'Kubiņu masa'!D59 -> 0.43 | I53: =H53/15*100 -> 2.8666667
A54: ref | B54: mMDF | C54: 51 | D54: 50 | E54: 2025-11-26 | F54: 2.870494 | G54: 15.41 | H54: =G54-'Kubiņu masa'!D60 -> 0.43 | I54: =H54/15*100 -> 2.8666667
A55: ref | B55: mMDF | C55: 52 | D55: 50 | E55: 2025-11-26 | F55: 2.919708 | G55: 15.51 | H55: =G55-'Kubiņu masa'!D61 -> 0.44 | I55: =H55/15*100 -> 2.9333333
A56: ref | B56: LPB | C56: 8r | D56: 50 | E56: 2025-11-26 | F56: 3.2379518 | G56: 13.71 | H56: =G56-'Kubiņu masa'!D62 -> 0.43 | I56: =H56/15*100 -> 2.8666667
A57: ref | B57: LPB | C57: 9r | D57: 50 | E57: 2025-11-26 | F57: 3.3460076 | G57: 13.59 | H57: =G57-'Kubiņu masa'!D63 -> 0.44 | I57: =H57/15*100 -> 2.9333333
A58: ref | B58: LPB | C58: 10r | D58: 50 | E58: 2025-11-26 | F58: 3.4429992 | G58: 13.52 | H58: =G58-'Kubiņu masa'!D64 -> 0.45 | I58: =H58/15*100 -> 3
A59: ref | B59: MRPB | C59: 38r | D59: 50 | E59: 2025-11-26 | F59: 3.8202247 | G59: 13.86 | H59: =G59-'Kubiņu masa'!D65 -> 0.51 | I59: =H59/15*100 -> 3.4
A60: ref | B60: MRPB | C60: 39r | D60: 50 | E60: 2025-11-26 | F60: 3.6814425 | G60: 13.8 | H60: =G60-'Kubiņu masa'!D66 -> 0.49 | I60: =H60/15*100 -> 3.2666667
A61: ref | B61: MRPB | C61: 40r | D61: 50 | E61: 2025-11-26 | F61: 3.7091988 | G61: 13.98 | H61: =G61-'Kubiņu masa'!D67 -> 0.5 | I61: =H61/15*100 -> 3.3333333
A62: ref | B62: LMDF | C62: 45r | D62: 50 | E62: 2025-11-26 | F62: 2.6878436 | G62: 16.81 | H62: =G62-'Kubiņu masa'!D68 -> 0.44 | I62: =H62/15*100 -> 2.9333333
A63: ref | B63: LMDF | C63: 46r | D63: 50 | E63: 2025-11-26 | F63: 2.6944274 | G63: 16.77 | H63: =G63-'Kubiņu masa'!D69 -> 0.44 | I63: =H63/15*100 -> 2.9333333
A64: ref | B64: MDF | C64: 26r | D64: 50 | E64: 2025-11-26 | F64: 3.5016835 | G64: 15.37 | H64: =G64-'Kubiņu masa'!D70 -> 0.52 | I64: =H64/15*100 -> 3.4666667
A65: ref | B65: MDF | C65: 27r | D65: 50 | E65: 2025-11-26 | F65: 3.5254237 | G65: 15.27 | H65: =G65-'Kubiņu masa'!D71 -> 0.52 | I65: =H65/15*100 -> 3.4666667
A66: ref | B66: MDF | C66: 28r | D66: 50 | E66: 2025-11-26 | F66: 3.4993271 | G66: 15.38 | H66: =G66-'Kubiņu masa'!D72 -> 0.52 | I66: =H66/15*100 -> 3.4666667
A67: sub | B67: BSD1 | C67: 9 | D67: 50 | E67: 2025-11-28 | F67: 3.9187228 | G67: 7.16 | H67: =G67-'Kubiņu masa'!D8 -> 0.27 | I67: =H67/27*100 -> 1
A68: sub | B68: BSD1 | C68: 27 | D68: 50 | E68: 2025-11-28 | F68: 3.4674064 | G68: 7.46 | H68: =G68-'Kubiņu masa'!D9 -> 0.25 | I68: =H68/27*100 -> 0.92592593
A69: sub | B69: BSD1 | C69: 106 | D69: 50 | E69: 2025-11-28 | F69: 3.4965035 | G69: 7.4 | H69: =G69-'Kubiņu masa'!D10 -> 0.25 | I69: =H69/27*100 -> 0.92592593
A70: sub | B70: BSD2 | C70: 39 | D70: 50 | E70: 2025-11-28 | F70: 3.220339 | G70: 6.09 | H70: =G70-'Kubiņu masa'!D11 -> 0.19 | I70: =H70/27*100 -> 0.7037037
A71: sub | B71: BSD2 | C71: 55 | D71: 50 | E71: 2025-11-28 | F71: 3.2679739 | G71: 6.32 | H71: =G71-'Kubiņu masa'!D12 -> 0.2 | I71: =H71/27*100 -> 0.74074074
A72: sub | B72: BSD2 | C72: 122 | D72: 50 | E72: 2025-11-28 | F72: 3.0744337 | G72: 6.37 | H72: =G72-'Kubiņu masa'!D13 -> 0.19 | I72: =H72/27*100 -> 0.7037037
A73: sub | B73: BSD3 | C73: 66 | D73: 50 | E73: 2025-11-28 | F73: 3.4578147 | G73: 7.48 | H73: =G73-'Kubiņu masa'!D14 -> 0.25 | I73: =H73/27*100 -> 0.92592593
A74: sub | B74: BSD3 | C74: 142 | D74: 50 | E74: 2025-11-28 | F74: 3.5526316 | G74: 7.87 | H74: =G74-'Kubiņu masa'!D15 -> 0.27 | I74: =H74/27*100 -> 1
A75: sub | B75: BSD3 | C75: 147 | D75: 50 | E75: 2025-11-28 | F75: 3.638814 | G75: 7.69 | H75: =G75-'Kubiņu masa'!D16 -> 0.27 | I75: =H75/27*100 -> 1
...

Sheet Mean_SD
A1: apstrade | B1: substrate | C1: rh | D1: mean_udens_sat | E1: sd_udens_sat
A2: control | B2: BSD1 | C2: 50 | D2: 5.5788382 | E2: 0.091935619
A3: control | B3: BSD1 | C3: 60 | D3: 6.7241988 | E3: 0.1809304
A4: control | B4: BSD1 | C4: 70 | D4: 7.9691894 | E4: 0.095987932
A5: control | B5: BSD1 | C5: 80 | D5: 11.146013 | E5: 0.078230319
A6: control | B6: BSD1 | C6: 90 | D6: 16.45907 | E6: 0.23186471
A7: control | B7: BSD1 | C7: 95 | D7: 20.092633 | E7: 0.13314303
A8: control | B8: BSD2 | C8: 50 | D8: 5.5273318 | E8: 0.16395106
A9: control | B9: BSD2 | C9: 60 | D9: 6.6810459 | E9: 0.40208381
A10: control | B10: BSD2 | C10: 70 | D10: 7.8451589 | E10: 0.34672382
A11: control | B11: BSD2 | C11: 80 | D11: 11.062624 | E11: 0.10517531
A12: control | B12: BSD2 | C12: 90 | D12: 16.86847 | E12: 0.32944708
A13: control | B13: BSD2 | C13: 95 | D13: 20.798069 | E13: 0.31339337
... A201: sub | B201: WS4 | C201: 90 | D201: 10.096265 | E201: 0.21925915
