Workbook

Sheet stienīši
A1: substrate | B1: plate/rod | C1: pate number | D1: id | E1: mass | F1: length | G1: width | H1: height | J1: *Nepietiekams garums
A2: Sl1 | B2: plate | C2: 1 | D2: 1
D3: 2
D4: 3
D5: 4 | I5: stieni | J5: sub 20%
D6: 5 | I6: stieni | J6: hito2% sub 20%
C7: 3 | D7: 6 | I7: stieni | J7: org
D8: 7
D9: 8
D10: 9 | I10: kubiņi | J10: visi pārējie
D11: 10
A12: Sl1 | B12: plate | C12: 1 | D12: 58
D13: 59
D14: 60
D15: 61
D16: 62
C17: 3 | D17: 63
D18: 64
D19: 65
D20: 66
D21: 67
A22: Sl2 | B22: plate | C22: 2 | D22: 11
D23: 13
D24: 14
D25: 15
D26: 16
C27: 3 | D27: 17
D28: 18
D29: 19
D30: 30
D31: 31
B32: rod | C32: a | D32: 66*
C33: b | D33: 67*
A34: Sl2 | B34: plate | C34: 1 | D34: 68
D35: 69
D36: 70
D37: 71
D38: 72
C39: 2 | D39: 73
D40: 74
...

Sheet kubiņi
A1: 7.05.2025
A2: Substrats | B2: plāksne | C2: stienīša nr | D2: id | E2: apstrāde | F2: izmantošana | O2: sub | P2: hito/sub
A3: Sl1 | B3: 1 | C3: 3 | D3: 1 | E3: =IF(COUNTIF('Sl suberinskabe'!$A$5:$A$84, $D3) > 0,"sub",IF(COUNTIF('Sl hito+suberinskabe'!$A$5:$A$78, $D3) > 0,"hito_sub","")) -> hito_sub | F3: =IF(COUNTIF('ūd. sorbcija Sl'!$C$3:$C$43, $D3) > 0, "ūdens sorbc",IF(COUNTIF(spiedei!$C$2:$C$41, $D3) > 0, "spiede", IF(COUNTIF(higro!$C$5:$C$18, $D3) > 0, "higroskopija",IF(COUNTIF(higro!$C$31:$C$45, $D3) > 0, "higroskopija",IF(COUNTIF(Komp!$A$2:$A$13, $D3) > 0, "komposts",""))))) -> spiede | N3: spiede | O3: 5 | P3: 5
D4: 2 | E4: =IF(COUNTIF('Sl suberinskabe'!$A$5:$A$84, $D4) > 0,"sub",IF(COUNTIF('Sl hito+suberinskabe'!$A$5:$A$78, $D4) > 0,"hito_sub","")) -> hito_sub | F4: =IF(COUNTIF('ūd. sorbcija Sl'!$C$3:$C$43, $D4) > 0, "ūdens sorbc",IF(COUNTIF(spiedei!$C$2:$C$41, $D4) > 0, "spiede", IF(COUNTIF(higro!$C$5:$C$18, $D4) > 0, "higroskopija",IF(COUNTIF(higro!$C$31:$C$45, $D4) > 0, "higroskopija",IF(COUNTIF(Komp!$A$2:$A$13, $D4) > 0, "komposts",""))))) -> ūdens sorbc | N4: udens | O4: 5 | P4: 5
D5: 3 | E5: =IF(COUNTIF('Sl suberinskabe'!$A$5:$A$84, $D5) > 0,"sub",IF(COUNTIF('Sl hito+suberinskabe'!$A$5:$A$78, $D5) > 0,"hito_sub","")) -> sub | F5: =IF(COUNTIF('ūd. sorbcija Sl'!$C$3:$C$43, $D5) > 0, "ūdens sorbc",IF(COUNTIF(spiedei!$C$2:$C$41, $D5) > 0, "spiede", IF(COUNTIF(higro!$C$5:$C$18, $D5) > 0, "higroskopija",IF(COUNTIF(higro!$C$31:$C$45, $D5) > 0, "higroskopija",IF(COUNTIF(Komp!$A$2:$A$13, $D5) > 0, "komposts",""))))) -> spiede | N5: higro | O5: 3 | P5: 3
D6: 4 | E6: =IF(COUNTIF('Sl suberinskabe'!$A$5:$A$84, $D6) > 0,"sub",IF(COUNTIF('Sl hito+suberinskabe'!$A$5:$A$78, $D6) > 0,"hito_sub","")) -> sub | F6: =IF(COUNTIF('ūd. sorbcija Sl'!$C$3:$C$43, $D6) > 0, "ūdens sorbc",IF(COUNTIF(spiedei!$C$2:$C$41, $D6) > 0, "spiede", IF(COUNTIF(higro!$C$5:$C$18, $D6) > 0, "higroskopija",IF(COUNTIF(higro!$C$31:$C$45, $D6) > 0, "higroskopija",IF(COUNTIF(Komp!$A$2:$A$13, $D6) > 0, "komposts",""))))) -> komposts | N6: kont lenkis | O6: 3 | P6: 3 | Q6: trukst
D7: 5 | E7: =IF(COUNTIF('Sl suberinskabe'!$A$5:$A$84, $D7) > 0,"sub",IF(COUNTIF('Sl hito+suberinskabe'!$A$5:$A$78, $D7) > 0,"hito_sub","")) -> hito_sub | F7: =IF(COUNTIF('ūd. sorbcija Sl'!$C$3:$C$43, $D7) > 0, "ūdens sorbc",IF(COUNTIF(spiedei!$C$2:$C$41, $D7) > 0, "spiede", IF(COUNTIF(higro!$C$5:$C$18, $D7) > 0, "higroskopija",IF(COUNTIF(higro!$C$31:$C$45, $D7) > 0, "higroskopija",IF(COUNTIF(Komp!$A$2:$A$13, $D7) > 0, "komposts",""))))) -> higroskopija | N7: poroz | O7: 2 | P7: 2 | Q7: trukst
C8: 4 | D8: 6 | E8: =IF(COUNTIF('Sl suberinskabe'!$A$5:$A$84, $D8) > 0,"sub",IF(COUNTIF('Sl hito+suberinskabe'!$A$5:$A$78, $D8) > 0,"hito_sub","")) -> hito_sub | F8: =IF(COUNTIF('ūd. sorbcija Sl'!$C$3:$C$43, $D8) > 0, "ūdens sorbc",IF(COUNTIF(spiedei!$C$2:$C$41, $D8) > 0, "spiede", IF(COUNTIF(higro!$C$5:$C$18, $D8) > 0, "higroskopija",IF(COUNTIF(higro!$C$31:$C$45, $D8) > 0, "higroskopija",IF(COUNTIF(Komp!$A$2:$A$13, $D8) > 0, "komposts",""))))) -> ūdens sorbc | N8: titresana | O8: 2 | P8: 2 | Q8: trukst
D9: 7 | E9: =IF(COUNTIF('Sl suberinskabe'!$A$5:$A$84, $D9) > 0,"sub",IF(COUNTIF('Sl hito+suberinskabe'!$A$5:$A$78, $D9) > 0,"hito_sub","")) -> sub | F9: =IF(COUNTIF('ūd. sorbcija Sl'!$C$3:$C$43, $D9) > 0, "ūdens sorbc",IF(COUNTIF(spiedei!$C$2:$C$41, $D9) > 0, "spiede", IF(COUNTIF(higro!$C$5:$C$18, $D9) > 0, "higroskopija",IF(COUNTIF(higro!$C$31:$C$45, $D9) > 0, "higroskopija",IF(COUNTIF(Komp!$A$2:$A$13, $D9) > 0, "komposts",""))))) -> ūdens sorbc | O9: 20 | P9: 20
D10: 8 | E10: =IF(COUNTIF('Sl suberinskabe'!$A$5:$A$84, $D10) > 0,"sub",IF(COUNTIF('Sl hito+suberinskabe'!$A$5:$A$78, $D10) > 0,"hito_sub","")) -> sub | F10: =IF(COUNTIF('ūd. sorbcija Sl'!$C$3:$C$43, $D10) > 0, "ūdens sorbc",IF(COUNTIF(spiedei!$C$2:$C$41, $D10) > 0, "spiede", IF(COUNTIF(higro!$C$5:$C$18, $D10) > 0, "higroskopija",IF(COUNTIF(higro!$C$31:$C$45, $D10) > 0, "higroskopija",IF(COUNTIF(Komp!$A$2:$A$13, $D10) > 0, "komposts",""))))) -> komposts
D11: 9 | E11: =IF(COUNTIF('Sl suberinskabe'!$A$5:$A$84, $D11) > 0,"sub",IF(COUNTIF('Sl hito+suberinskabe'!$A$5:$A$78, $D11) > 0,"hito_sub","")) -> sub | F11: =IF(COUNTIF('ūd. sorbcija Sl'!$C$3:$C$43, $D11) > 0, "ūdens sorbc",IF(COUNTIF(spiedei!$C$2:$C$41, $D11) > 0, "spiede", IF(COUNTIF(higro!$C$5:$C$18, $D11) > 0, "higroskopija",IF(COUNTIF(higro!$C$31:$C$45, $D11) > 0, "higroskopija",IF(COUNTIF(Komp!$A$2:$A$13, $D11) > 0, "komposts",""))))) -> higroskopija | N11: komposts | O11: pietrukst, paņemt no kont l,poroz un titrēšanas
D12: 10 | E12: =IF(COUNTIF('Sl suberinskabe'!$A$5:$A$84, $D12) > 0,"sub",IF(COUNTIF('Sl hito+suberinskabe'!$A$5:$A$78, $D12) > 0,"hito_sub","")) -> hito_sub | F12: =IF(COUNTIF('ūd. sorbcija Sl'!$C$3:$C$43, $D12) > 0, "ūdens sorbc",IF(COUNTIF(spiedei!$C$2:$C$41, $D12) > 0, "spiede", IF(COUNTIF(higro!$C$5:$C$18, $D12) > 0, "higroskopija",IF(COUNTIF(higro!$C$31:$C$45, $D12) > 0, "higroskopija",IF(COUNTIF(Komp!$A$2:$A$13, $D12) > 0, "komposts","")))))
C13: 5 | D13: 11 | E13: =IF(COUNTIF('Sl suberinskabe'!$A$5:$A$84, $D13) > 0,"sub",IF(COUNTIF('Sl hito+suberinskabe'!$A$5:$A$78, $D13) > 0,"hito_sub","")) -> hito_sub | F13: =IF(COUNTIF('ūd. sorbcija Sl'!$C$3:$C$43, $D13) > 0, "ūdens sorbc",IF(COUNTIF(spiedei!$C$2:$C$41, $D13) > 0, "spiede", IF(COUNTIF(higro!$C$5:$C$18, $D13) > 0, "higroskopija",IF(COUNTIF(higro!$C$31:$C$45, $D13) > 0, "higroskopija",IF(COUNTIF(Komp!$A$2:$A$13, $D13) > 0, "komposts","")))))
D14: 12 | E14: =IF(COUNTIF('Sl suberinskabe'!$A$5:$A$84, $D14) > 0,"sub",IF(COUNTIF('Sl hito+suberinskabe'!$A$5:$A$78, $D14) > 0,"hito_sub","")) -> sub | F14: =IF(COUNTIF('ūd. sorbcija Sl'!$C$3:$C$43, $D14) > 0, "ūdens sorbc",IF(COUNTIF(spiedei!$C$2:$C$41, $D14) > 0, "spiede", IF(COUNTIF(higro!$C$5:$C$18, $D14) > 0, "higroskopija",IF(COUNTIF(higro!$C$31:$C$45, $D14) > 0, "higroskopija",IF(COUNTIF(Komp!$A$2:$A$13, $D14) > 0, "komposts",""))))) -> komposts
D15: 13 | E15: =IF(COUNTIF('Sl suberinskabe'!$A$5:$A$84, $D15) > 0,"sub",IF(COUNTIF('Sl hito+suberinskabe'!$A$5:$A$78, $D15) > 0,"hito_sub","")) -> sub | F15: =IF(COUNTIF('ūd. sorbcija Sl'!$C$3:$C$43, $D15) > 0, "ūdens sorbc",IF(COUNTIF(spiedei!$C$2:$C$41, $D15) > 0, "spiede", IF(COUNTIF(higro!$C$5:$C$18, $D15) > 0, "higroskopija",IF(COUNTIF(higro!$C$31:$C$45, $D15) > 0, "higroskopija",IF(COUNTIF(Komp!$A$2:$A$13, $D15) > 0, "komposts",""))))) -> ūdens sorbc
D16: 14 | E16: =IF(COUNTIF('Sl suberinskabe'!$A$5:$A$84, $D16) > 0,"sub",IF(COUNTIF('Sl hito+suberinskabe'!$A$5:$A$78, $D16) > 0,"hito_sub","")) -> hito_sub | F16: =IF(COUNTIF('ūd. sorbcija Sl'!$C$3:$C$43, $D16) > 0, "ūdens sorbc",IF(COUNTIF(spiedei!$C$2:$C$41, $D16) > 0, "spiede", IF(COUNTIF(higro!$C$5:$C$18, $D16) > 0, "higroskopija",IF(COUNTIF(higro!$C$31:$C$45, $D16) > 0, "higroskopija",IF(COUNTIF(Komp!$A$2:$A$13, $D16) > 0, "komposts",""))))) -> spiede
D17: 15 | E17: =IF(COUNTIF('Sl suberinskabe'!$A$5:$A$84, $D17) > 0,"sub",IF(COUNTIF('Sl hito+suberinskabe'!$A$5:$A$78, $D17) > 0,"hito_sub","")) | F17: =IF(COUNTIF('ūd. sorbcija Sl'!$C$3:$C$43, $D17) > 0, "ūdens sorbc",IF(COUNTIF(spiedei!$C$2:$C$41, $D17) > 0, "spiede", IF(COUNTIF(higro!$C$5:$C$18, $D17) > 0, "higroskopija",IF(COUNTIF(higro!$C$31:$C$45, $D17) > 0, "higroskopija",IF(COUNTIF(Komp!$A$2:$A$13, $D17) > 0, "komposts","")))))
B18: 3 | C18: 7 | D18: 16 | E18: =IF(COUNTIF('Sl suberinskabe'!$A$5:$A$84, $D18) > 0,"sub",IF(COUNTIF('Sl hito+suberinskabe'!$A$5:$A$78, $D18) > 0,"hito_sub","")) -> hito_sub | F18: =IF(COUNTIF('ūd. sorbcija Sl'!$C$3:$C$43, $D18) > 0, "ūdens sorbc",IF(COUNTIF(spiedei!$C$2:$C$41, $D18) > 0, "spiede", IF(COUNTIF(higro!$C$5:$C$18, $D18) > 0, "higroskopija",IF(COUNTIF(higro!$C$31:$C$45, $D18) > 0, "higroskopija",IF(COUNTIF(Komp!$A$2:$A$13, $D18) > 0, "komposts",""))))) -> ūdens sorbc
D19: 17 | E19: =IF(COUNTIF('Sl suberinskabe'!$A$5:$A$84, $D19) > 0,"sub",IF(COUNTIF('Sl hito+suberinskabe'!$A$5:$A$78, $D19) > 0,"hito_sub","")) -> hito_sub | F19: =IF(COUNTIF('ūd. sorbcija Sl'!$C$3:$C$43, $D19) > 0, "ūdens sorbc",IF(COUNTIF(spiedei!$C$2:$C$41, $D19) > 0, "spiede", IF(COUNTIF(higro!$C$5:$C$18, $D19) > 0, "higroskopija",IF(COUNTIF(higro!$C$31:$C$45, $D19) > 0, "higroskopija",IF(COUNTIF(Komp!$A$2:$A$13, $D19) > 0, "komposts",""))))) -> higroskopija
D20: 18 | E20: =IF(COUNTIF('Sl suberinskabe'!$A$5:$A$84, $D20) > 0,"sub",IF(COUNTIF('Sl hito+suberinskabe'!$A$5:$A$78, $D20) > 0,"hito_sub","")) -> sub | F20: =IF(COUNTIF('ūd. sorbcija Sl'!$C$3:$C$43, $D20) > 0, "ūdens sorbc",IF(COUNTIF(spiedei!$C$2:$C$41, $D20) > 0, "spiede", IF(COUNTIF(higro!$C$5:$C$18, $D20) > 0, "higroskopija",IF(COUNTIF(higro!$C$31:$C$45, $D20) > 0, "higroskopija",IF(COUNTIF(Komp!$A$2:$A$13, $D20) > 0, "komposts",""))))) -> ūdens sorbc
D21: 19 | E21: =IF(COUNTIF('Sl suberinskabe'!$A$5:$A$84, $D21) > 0,"sub",IF(COUNTIF('Sl hito+suberinskabe'!$A$5:$A$78, $D21) > 0,"hito_sub","")) -> hito_sub | F21: =IF(COUNTIF('ūd. sorbcija Sl'!$C$3:$C$43, $D21) > 0, "ūdens sorbc",IF(COUNTIF(spiedei!$C$2:$C$41, $D21) > 0, "spiede", IF(COUNTIF(higro!$C$5:$C$18, $D21) > 0, "higroskopija",IF(COUNTIF(higro!$C$31:$C$45, $D21) > 0, "higroskopija",IF(COUNTIF(Komp!$A$2:$A$13, $D21) > 0, "komposts",""))))) -> spiede
D22: 20 | E22: =IF(COUNTIF('Sl suberinskabe'!$A$5:$A$84, $D22) > 0,"sub",IF(COUNTIF('Sl hito+suberinskabe'!$A$5:$A$78, $D22) > 0,"hito_sub","")) -> hito_sub | F22: =IF(COUNTIF('ūd. sorbcija Sl'!$C$3:$C$43, $D22) > 0, "ūdens sorbc",IF(COUNTIF(spiedei!$C$2:$C$41, $D22) > 0, "spiede", IF(COUNTIF(higro!$C$5:$C$18, $D22) > 0, "higroskopija",IF(COUNTIF(higro!$C$31:$C$45, $D22) > 0, "higroskopija",IF(COUNTIF(Komp!$A$2:$A$13, $D22) > 0, "komposts","")))))
C23: 9 | D23: 21 | E23: =IF(COUNTIF('Sl suberinskabe'!$A$5:$A$84, $D23) > 0,"sub",IF(COUNTIF('Sl hito+suberinskabe'!$A$5:$A$78, $D23) > 0,"hito_sub","")) -> sub | F23: =IF(COUNTIF('ūd. sorbcija Sl'!$C$3:$C$43, $D23) > 0, "ūdens sorbc",IF(COUNTIF(spiedei!$C$2:$C$41, $D23) > 0, "spiede", IF(COUNTIF(higro!$C$5:$C$18, $D23) > 0, "higroskopija",IF(COUNTIF(higro!$C$31:$C$45, $D23) > 0, "higroskopija",IF(COUNTIF(Komp!$A$2:$A$13, $D23) > 0, "komposts","")))))
D24: 22 | E24: =IF(COUNTIF('Sl suberinskabe'!$A$5:$A$84, $D24) > 0,"sub",IF(COUNTIF('Sl hito+suberinskabe'!$A$5:$A$78, $D24) > 0,"hito_sub","")) -> sub | F24: =IF(COUNTIF('ūd. sorbcija Sl'!$C$3:$C$43, $D24) > 0, "ūdens sorbc",IF(COUNTIF(spiedei!$C$2:$C$41, $D24) > 0, "spiede", IF(COUNTIF(higro!$C$5:$C$18, $D24) > 0, "higroskopija",IF(COUNTIF(higro!$C$31:$C$45, $D24) > 0, "higroskopija",IF(COUNTIF(Komp!$A$2:$A$13, $D24) > 0, "komposts",""))))) -> spiede
D25: 23 | E25: =IF(COUNTIF('Sl suberinskabe'!$A$5:$A$84, $D25) > 0,"sub",IF(COUNTIF('Sl hito+suberinskabe'!$A$5:$A$78, $D25) > 0,"hito_sub","")) -> sub | F25: =IF(COUNTIF('ūd. sorbcija Sl'!$C$3:$C$43, $D25) > 0, "ūdens sorbc",IF(COUNTIF(spiedei!$C$2:$C$41, $D25) > 0, "spiede", IF(COUNTIF(higro!$C$5:$C$18, $D25) > 0, "higroskopija",IF(COUNTIF(higro!$C$31:$C$45, $D25) > 0, "higroskopija",IF(COUNTIF(Komp!$A$2:$A$13, $D25) > 0, "komposts","")))))
D26: 24 | E26: =IF(COUNTIF('Sl suberinskabe'!$A$5:$A$84, $D26) > 0,"sub",IF(COUNTIF('Sl hito+suberinskabe'!$A$5:$A$78, $D26) > 0,"hito_sub","")) -> hito_sub | F26: =IF(COUNTIF('ūd. sorbcija Sl'!$C$3:$C$43, $D26) > 0, "ūdens sorbc",IF(COUNTIF(spiedei!$C$2:$C$41, $D26) > 0, "spiede", IF(COUNTIF(higro!$C$5:$C$18, $D26) > 0, "higroskopija",IF(COUNTIF(higro!$C$31:$C$45, $D26) > 0, "higroskopija",IF(COUNTIF(Komp!$A$2:$A$13, $D26) > 0, "komposts","")))))
D27: 25 | E27: =IF(COUNTIF('Sl suberinskabe'!$A$5:$A$84, $D27) > 0,"sub",IF(COUNTIF('Sl hito+suberinskabe'!$A$5:$A$78, $D27) > 0,"hito_sub","")) | F27: =IF(COUNTIF('ūd. sorbcija Sl'!$C$3:$C$43, $D27) > 0, "ūdens sorbc",IF(COUNTIF(spiedei!$C$2:$C$41, $D27) > 0, "spiede", IF(COUNTIF(higro!$C$5:$C$18, $D27) > 0, "higroskopija",IF(COUNTIF(higro!$C$31:$C$45, $D27) > 0, "higroskopija",IF(COUNTIF(Komp!$A$2:$A$13, $D27) > 0, "komposts","")))))
C28: 10 | D28: 26 | E28: =IF(COUNTIF('Sl suberinskabe'!$A$5:$A$84, $D28) > 0,"sub",IF(COUNTIF('Sl hito+suberinskabe'!$A$5:$A$78, $D28) > 0,"hito_sub","")) -> hito_sub | F28: =IF(COUNTIF('ūd. sorbcija Sl'!$C$3:$C$43, $D28) > 0, "ūdens sorbc",IF(COUNTIF(spiedei!$C$2:$C$41, $D28) > 0, "spiede", IF(COUNTIF(higro!$C$5:$C$18, $D28) > 0, "higroskopija",IF(COUNTIF(higro!$C$31:$C$45, $D28) > 0, "higroskopija",IF(COUNTIF(Komp!$A$2:$A$13, $D28) > 0, "komposts","")))))
D29: 27 | E29: =IF(COUNTIF('Sl suberinskabe'!$A$5:$A$84, $D29) > 0,"sub",IF(COUNTIF('Sl hito+suberinskabe'!$A$5:$A$78, $D29) > 0,"hito_sub","")) -> sub | F29: =IF(COUNTIF('ūd. sorbcija Sl'!$C$3:$C$43, $D29) > 0, "ūdens sorbc",IF(COUNTIF(spiedei!$C$2:$C$41, $D29) > 0, "spiede", IF(COUNTIF(higro!$C$5:$C$18, $D29) > 0, "higroskopija",IF(COUNTIF(higro!$C$31:$C$45, $D29) > 0, "higroskopija",IF(COUNTIF(Komp!$A$2:$A$13, $D29) > 0, "komposts",""))))) -> higroskopija
D30: 28 | E30: =IF(COUNTIF('Sl suberinskabe'!$A$5:$A$84, $D30) > 0,"sub",IF(COUNTIF('Sl hito+suberinskabe'!$A$5:$A$78, $D30) > 0,"hito_sub","")) -> sub | F30: =IF(COUNTIF('ūd. sorbcija Sl'!$C$3:$C$43, $D30) > 0, "ūdens sorbc",IF(COUNTIF(spiedei!$C$2:$C$41, $D30) > 0, "spiede", IF(COUNTIF(higro!$C$5:$C$18, $D30) > 0, "higroskopija",IF(COUNTIF(higro!$C$31:$C$45, $D30) > 0, "higroskopija",IF(COUNTIF(Komp!$A$2:$A$13, $D30) > 0, "komposts","")))))
D31: 29 | E31: =IF(COUNTIF('Sl suberinskabe'!$A$5:$A$84, $D31) > 0,"sub",IF(COUNTIF('Sl hito+suberinskabe'!$A$5:$A$78, $D31) > 0,"hito_sub","")) -> hito_sub | F31: =IF(COUNTIF('ūd. sorbcija Sl'!$C$3:$C$43, $D31) > 0, "ūdens sorbc",IF(COUNTIF(spiedei!$C$2:$C$41, $D31) > 0, "spiede", IF(COUNTIF(higro!$C$5:$C$18, $D31) > 0, "higroskopija",IF(COUNTIF(higro!$C$31:$C$45, $D31) > 0, "higroskopija",IF(COUNTIF(Komp!$A$2:$A$13, $D31) > 0, "komposts",""))))) -> ūdens sorbc
D32: 30 | E32: =IF(COUNTIF('Sl suberinskabe'!$A$5:$A$84, $D32) > 0,"sub",IF(COUNTIF('Sl hito+suberinskabe'!$A$5:$A$78, $D32) > 0,"hito_sub","")) | F32: =IF(COUNTIF('ūd. sorbcija Sl'!$C$3:$C$43, $D32) > 0, "ūdens sorbc",IF(COUNTIF(spiedei!$C$2:$C$41, $D32) > 0, "spiede", IF(COUNTIF(higro!$C$5:$C$18, $D32) > 0, "higroskopija",IF(COUNTIF(higro!$C$31:$C$45, $D32) > 0, "higroskopija",IF(COUNTIF(Komp!$A$2:$A$13, $D32) > 0, "komposts","")))))
A33: Sl1 | B33: 1 | C33: 60 | D33: 99 | E33: =IF(COUNTIF('Sl suberinskabe'!$A$5:$A$84, $D33) > 0,"sub",IF(COUNTIF('Sl hito+suberinskabe'!$A$5:$A$78, $D33) > 0,"hito_sub","")) -> hito_sub | F33: =IF(COUNTIF('ūd. sorbcija Sl'!$C$3:$C$43, $D33) > 0, "ūdens sorbc",IF(COUNTIF(spiedei!$C$2:$C$41, $D33) > 0, "spiede", IF(COUNTIF(higro!$C$5:$C$18, $D33) > 0, "higroskopija",IF(COUNTIF(higro!$C$31:$C$45, $D33) > 0, "higroskopija",IF(COUNTIF(Komp!$A$2:$A$13, $D33) > 0, "komposts",""))))) -> higroskopija
D34: 100 | E34: =IF(COUNTIF('Sl suberinskabe'!$A$5:$A$84, $D34) > 0,"sub",IF(COUNTIF('Sl hito+suberinskabe'!$A$5:$A$78, $D34) > 0,"hito_sub","")) -> hito_sub | F34: =IF(COUNTIF('ūd. sorbcija Sl'!$C$3:$C$43, $D34) > 0, "ūdens sorbc",IF(COUNTIF(spiedei!$C$2:$C$41, $D34) > 0, "spiede", IF(COUNTIF(higro!$C$5:$C$18, $D34) > 0, "higroskopija",IF(COUNTIF(higro!$C$31:$C$45, $D34) > 0, "higroskopija",IF(COUNTIF(Komp!$A$2:$A$13, $D34) > 0, "komposts",""))))) -> spiede
D35: 101 | E35: =IF(COUNTIF('Sl suberinskabe'!$A$5:$A$84, $D35) > 0,"sub",IF(COUNTIF('Sl hito+suberinskabe'!$A$5:$A$78, $D35) > 0,"hito_sub","")) -> sub | F35: =IF(COUNTIF('ūd. sorbcija Sl'!$C$3:$C$43, $D35) > 0, "ūdens sorbc",IF(COUNTIF(spiedei!$C$2:$C$41, $D35) > 0, "spiede", IF(COUNTIF(higro!$C$5:$C$18, $D35) > 0, "higroskopija",IF(COUNTIF(higro!$C$31:$C$45, $D35) > 0, "higroskopija",IF(COUNTIF(Komp!$A$2:$A$13, $D35) > 0, "komposts",""))))) -> spiede
D36: 102 | E36: =IF(COUNTIF('Sl suberinskabe'!$A$5:$A$84, $D36) > 0,"sub",IF(COUNTIF('Sl hito+suberinskabe'!$A$5:$A$78, $D36) > 0,"hito_sub","")) -> sub | F36: =IF(COUNTIF('ūd. sorbcija Sl'!$C$3:$C$43, $D36) > 0, "ūdens sorbc",IF(COUNTIF(spiedei!$C$2:$C$41, $D36) > 0, "spiede", IF(COUNTIF(higro!$C$5:$C$18, $D36) > 0, "higroskopija",IF(COUNTIF(higro!$C$31:$C$45, $D36) > 0, "higroskopija",IF(COUNTIF(Komp!$A$2:$A$13, $D36) > 0, "komposts","")))))
D37: 103 | E37: =IF(COUNTIF('Sl suberinskabe'!$A$5:$A$84, $D37) > 0,"sub",IF(COUNTIF('Sl hito+suberinskabe'!$A$5:$A$78, $D37) > 0,"hito_sub","")) | F37: =IF(COUNTIF('ūd. sorbcija Sl'!$C$3:$C$43, $D37) > 0, "ūdens sorbc",IF(COUNTIF(spiedei!$C$2:$C$41, $D37) > 0, "spiede", IF(COUNTIF(higro!$C$5:$C$18, $D37) > 0, "higroskopija",IF(COUNTIF(higro!$C$31:$C$45, $D37) > 0, "higroskopija",IF(COUNTIF(Komp!$A$2:$A$13, $D37) > 0, "komposts","")))))
C38: 62 | D38: 104 | E38: =IF(COUNTIF('Sl suberinskabe'!$A$5:$A$84, $D38) > 0,"sub",IF(COUNTIF('Sl hito+suberinskabe'!$A$5:$A$78, $D38) > 0,"hito_sub","")) -> hito_sub | F38: =IF(COUNTIF('ūd. sorbcija Sl'!$C$3:$C$43, $D38) > 0, "ūdens sorbc",IF(COUNTIF(spiedei!$C$2:$C$41, $D38) > 0, "spiede", IF(COUNTIF(higro!$C$5:$C$18, $D38) > 0, "higroskopija",IF(COUNTIF(higro!$C$31:$C$45, $D38) > 0, "higroskopija",IF(COUNTIF(Komp!$A$2:$A$13, $D38) > 0, "komposts","")))))
D39: 105 | E39: =IF(COUNTIF('Sl suberinskabe'!$A$5:$A$84, $D39) > 0,"sub",IF(COUNTIF('Sl hito+suberinskabe'!$A$5:$A$78, $D39) > 0,"hito_sub","")) -> sub | F39: =IF(COUNTIF('ūd. sorbcija Sl'!$C$3:$C$43, $D39) > 0, "ūdens sorbc",IF(COUNTIF(spiedei!$C$2:$C$41, $D39) > 0, "spiede", IF(COUNTIF(higro!$C$5:$C$18, $D39) > 0, "higroskopija",IF(COUNTIF(higro!$C$31:$C$45, $D39) > 0, "higroskopija",IF(COUNTIF(Komp!$A$2:$A$13, $D39) > 0, "komposts",""))))) -> ūdens sorbc
D40: 106 | E40: =IF(COUNTIF('Sl suberinskabe'!$A$5:$A$84, $D40) > 0,"sub",IF(COUNTIF('Sl hito+suberinskabe'!$A$5:$A$78, $D40) > 0,"hito_sub","")) -> sub | F40: =IF(COUNTIF('ūd. sorbcija Sl'!$C$3:$C$43, $D40) > 0, "ūdens sorbc",IF(COUNTIF(spiedei!$C$2:$C$41, $D40) > 0, "spiede", IF(COUNTIF(higro!$C$5:$C$18, $D40) > 0, "higroskopija",IF(COUNTIF(higro!$C$31:$C$45, $D40) > 0, "higroskopija",IF(COUNTIF(Komp!$A$2:$A$13, $D40) > 0, "komposts",""))))) -> higroskopija
...

Sheet Sl suberinskabe
A1: 12.05.2025
A2: suberīnskabe | C2: m1 = 30s dip + 100 oC līdz konst. m. + 150 oC 15 min
A3: 80 gab | G3: 20 gab
A4: kubiņa nr | B4: mo* | C4: m1 | D4: uzņemtā sub. Sk. | E4: sub. sk. g/g MK | F4: sub. sk. g/cm3 | G4: stieņa nr | H4: mo* | I4: m1 | J4: uzņemtā sub. Sk. | K4: sub. sk. g/g MK | L4: sub. sk. g/cm3
A5: 3 | B5: 4.5 | C5: 7.12 | D5: =C5-B5 -> 2.62 | E5: =D5/B5 -> 0.58222222 | F5: =D5/27 -> 0.097037037 | G5: 1 | H5: 25.63 | I5: 39.28 | J5: =I5-H5 -> 13.65 | K5: =J5/H5 -> 0.53257901 | L5: =J5/153 -> 0.089215686
A6: 4 | B6: 4.66 | C6: 7.23 | D6: =C6-B6 -> 2.57 | E6: =D6/B6 -> 0.55150215 | F6: =D6/27 -> 0.095185185 | G6: 8 | H6: 24.96 | I6: 39.61 | J6: =I6-H6 -> 14.65 | K6: =J6/H6 -> 0.5869391 | L6: =J6/153 -> 0.095751634
A7: 7 | B7: 4.44 | C7: 7.12 | D7: =C7-B7 -> 2.68 | E7: =D7/B7 -> 0.6036036 | F7: =D7/27 -> 0.099259259 | G7: 11 | H7: 18.89 | I7: 31.98 | J7: =I7-H7 -> 13.09 | K7: =J7/H7 -> 0.69295924 | L7: =J7/153 -> 0.085555556
A8: 8 | B8: 4.48 | C8: 7.03 | D8: =C8-B8 -> 2.55 | E8: =D8/B8 -> 0.56919643 | F8: =D8/27 -> 0.094444444 | G8: 19 | H8: 19.51 | I8: 33.24 | J8: =I8-H8 -> 13.73 | K8: =J8/H8 -> 0.70374167 | L8: =J8/153 -> 0.089738562
A9: 9 | B9: 4.62 | C9: 6.84 | D9: =C9-B9 -> 2.22 | E9: =D9/B9 -> 0.48051948 | F9: =D9/27 -> 0.082222222 | G9: 32 | H9: 26.1 | I9: 40.55 | J9: =I9-H9 -> 14.45 | K9: =J9/H9 -> 0.55363985 | L9: =J9/153 -> 0.094444444
A10: 12 | B10: 4.54 | C10: 6.93 | D10: =C10-B10 -> 2.39 | E10: =D10/B10 -> 0.52643172 | F10: =D10/27 -> 0.088518519 | G10: 34 | H10: 26.76 | I10: 40.63 | J10: =I10-H10 -> 13.87 | K10: =J10/H10 -> 0.51831091 | L10: =J10/153 -> 0.090653595
A11: 13 | B11: 4.57 | C11: 6.95 | D11: =C11-B11 -> 2.38 | E11: =D11/B11 -> 0.52078775 | F11: =D11/27 -> 0.088148148 | G11: 37 | H11: 27.25 | I11: 42.9 | J11: =I11-H11 -> 15.65 | K11: =J11/H11 -> 0.57431193 | L11: =J11/153 -> 0.10228758
A12: 18 | B12: 6.16 | C12: 8.87 | D12: =C12-B12 -> 2.71 | E12: =D12/B12 -> 0.43993506 | F12: =D12/27 -> 0.10037037 | G12: 43 | H12: 26.67 | I12: 43.13 | J12: =I12-H12 -> 16.46 | K12: =J12/H12 -> 0.61717285 | L12: =J12/153 -> 0.1075817
A13: 21 | B13: 4.24 | C13: 6.85 | D13: =C13-B13 -> 2.61 | E13: =D13/B13 -> 0.61556604 | F13: =D13/27 -> 0.096666667 | G13: 58 | H13: 25.06 | I13: 37.3 | J13: =I13-H13 -> 12.24 | K13: =J13/H13 -> 0.48842777 | L13: =J13/153 -> 0.08
A14: 22 | B14: 4.27 | C14: 6.92 | D14: =C14-B14 -> 2.65 | E14: =D14/B14 -> 0.6206089 | F14: =D14/27 -> 0.098148148 | G14: 63 | H14: 24.74 | I14: 38.2 | J14: =I14-H14 -> 13.46 | K14: =J14/H14 -> 0.54405821 | L14: =J14/153 -> 0.087973856
A15: 23 | B15: 4.38 | C15: 6.85 | D15: =C15-B15 -> 2.47 | E15: =D15/B15 -> 0.56392694 | F15: =D15/27 -> 0.091481481 | G15: 65 | H15: 24.22 | I15: 38.85 | J15: =I15-H15 -> 14.63 | K15: =J15/H15 -> 0.60404624 | L15: =J15/153 -> 0.095620915
A16: 27 | B16: 4.5 | C16: 7.15 | D16: =C16-B16 -> 2.65 | E16: =D16/B16 -> 0.58888889 | F16: =D16/27 -> 0.098148148 | G16: 69 | H16: 19.26 | I16: 33.64 | J16: =I16-H16 -> 14.38 | K16: =J16/H16 -> 0.74662513 | L16: =J16/153 -> 0.093986928
... A24: 45 | B24: 3.32 | C24: 5.93 | D24: =C24-B24 -> 2.61 | E24: =D24/B24 -> 0.78614458 | F24: =D24/27 -> 0.096666667 | G24: 94 | H24: 26.71 | I24: 43 | J24: =I24-H24 -> 16.29 | K24: =J24/H24 -> 0.60988394 | L24: =J24/153 -> 0.10647059
A25: 46 | B25: 3.38 | C25: 6.09 | D25: =C25-B25 -> 2.71 | E25: =D25/B25 -> 0.80177515 | F25: =D25/27 -> 0.10037037
A26: 51 | B26: 3.48 | C26: 6.22 | D26: =C26-B26 -> 2.74 | E26: =D26/B26 -> 0.78735632 | F26: =D26/27 -> 0.10148148
A27: 52 | B27: 3.38 | C27: 6.09 | D27: =C27-B27 -> 2.71 | E27: =D27/B27 -> 0.80177515 | F27: =D27/27 -> 0.10037037
A28: 55 | B28: 3.45 | C28: 6.09 | D28: =C28-B28 -> 2.64 | E28: =D28/B28 -> 0.76521739 | F28: =D28/27 -> 0.097777778
A29: 56 | B29: 3.56 | C29: 6.09 | D29: =C29-B29 -> 2.53 | E29: =D29/B29 -> 0.71067416 | F29: =D29/27 -> 0.093703704
A30: 60 | B30: 3.31 | C30: 5.85 | D30: =C30-B30 -> 2.54 | E30: =D30/B30 -> 0.7673716 | F30: =D30/27 -> 0.094074074
A31: 61 | B31: 3.46 | C31: 6.1 | D31: =C31-B31 -> 2.64 | E31: =D31/B31 -> 0.76300578 | F31: =D31/27 -> 0.097777778
A32: 65 | B32: 4.45 | C32: 7.23 | D32: =C32-B32 -> 2.78 | E32: =D32/B32 -> 0.6247191 | F32: =D32/27 -> 0.10296296
A33: 66 | B33: 4.45 | C33: 7.18 | D33: =C33-B33 -> 2.73 | E33: =D33/B33 -> 0.61348315 | F33: =D33/27 -> 0.10111111
A34: 67 | B34: 4.56 | C34: 7.18 | D34: =C34-B34 -> 2.62 | E34: =D34/B34 -> 0.5745614 | F34: =D34/27 -> 0.097037037
A35: 69 | B35: 4.63 | C35: 7.22 | D35: =C35-B35 -> 2.59 | E35: =D35/B35 -> 0.55939525 | F35: =D35/27 -> 0.095925926
A36: 70 | B36: 4.46 | C36: 7.13 | D36: =C36-B36 -> 2.67 | E36: =D36/B36 -> 0.59865471 | F36: =D36/27 -> 0.098888889
... A38: 72 | B38: 4.76 | C38: 7.46 | D38: =C38-B38 -> 2.7 | E38: =D38/B38 -> 0.56722689 | F38: =D38/27 -> 0.1
A39: 75 | B39: 4.75 | C39: 7.57 | D39: =C39-B39 -> 2.82 | E39: =D39/B39 -> 0.59368421 | F39: =D39/27 -> 0.10444444 | J39: Sl1
A40: 76 | B40: 4.88 | C40: 7.61 | D40: =C40-B40 -> 2.73 | E40: =D40/B40 -> 0.55942623 | F40: =D40/27 -> 0.10111111 | J40: Sl2
A41: 77 | B41: 4.66 | C41: 7.53 | D41: =C41-B41 -> 2.87 | E41: =D41/B41 -> 0.61587983 | F41: =D41/27 -> 0.1062963 | J41: Sl3
A42: 80 | B42: 4.83 | C42: 7.78 | D42: =C42-B42 -> 2.95 | E42: =D42/B42 -> 0.61076605 | F42: =D42/27 -> 0.10925926 | J42: Sl4
A43: 81 | B43: 4.78 | C43: 7.61 | D43: =C43-B43 -> 2.83 | E43: =D43/B43 -> 0.59205021 | F43: =D43/27 -> 0.10481481
A44: 82 | B44: 4.93 | C44: 7.9 | D44: =C44-B44 -> 2.97 | E44: =D44/B44 -> 0.60243408 | F44: =D44/27 -> 0.11
A45: 83 | B45: 4.86 | C45: 7.8 | D45: =C45-B45 -> 2.94 | E45: =D45/B45 -> 0.60493827 | F45: =D45/27 -> 0.10888889
A46: 85 | B46: 4.63 | C46: 7.61 | D46: =C46-B46 -> 2.98 | E46: =D46/B46 -> 0.64362851 | F46: =D46/27 -> 0.11037037
A47: 86 | B47: 4.82 | C47: 7.74 | D47: =C47-B47 -> 2.92 | E47: =D47/B47 -> 0.60580913 | F47: =D47/27 -> 0.10814815
A48: 90 | B48: 5.02 | C48: 8.21 | D48: =C48-B48 -> 3.19 | E48: =D48/B48 -> 0.63545817 | F48: =D48/27 -> 0.11814815
...

Sheet Sl hito+suberinskabe
A1: 13.05.2025
A2: hito +suberīnskabe | D2: m1 = 30s dip. hito + 100 oC 30 min | J2: m2 = 30s dip. suber. + 100 oC līdz konst. m. + 150 oC 15 min
A3: 74 gab | L3: 8 gab
A4: kubiņa nr | B4: mo* | C4: m1 | D4: m2 | E4: Uzņemtais hito. | F4: hito g/g MK | G4: hito g/cm2 | H4: hito g/cm3 | I4: uzņemtā sub. Sk. | J4: sub. sk. g/g MK | K4: sub. sk. g/cm3 | L4: stieņa nr | M4: mo* | N4: m1 | O4: m2 | P4: Uzņemtais hito. | Q4: hito g/g MK | R4: hito g/cm2 | S4: hito h/cm3 | T4: uzņemtā sub. Sk. | U4: sub. sk. g/g MK | V4: sub. sk. g/cm3
A5: 1 | B5: 4.78 | C5: 5.06 | D5: 6.97 | E5: =C5-B5 -> 0.28 | F5: =E5/B5 -> 0.058577406 | G5: =E5/(9*6) -> 0.0051851852 | H5: =E5/27 -> 0.01037037 | I5: =D5-C5 -> 1.91 | J5: =I5/C5 -> 0.37747036 | K5: =I5/27 -> 0.070740741 | L5: 2 | M5: 25.76 | N5: 26.32 | O5: 38.03 | P5: =N5-M5 -> 0.56 | Q5: =P5/M5 -> 0.02173913 | R5: =P5/(9*2+3*17*4) -> 0.0025225225 | S5: =P5/153 -> 0.0036601307 | T5: =O5-N5 -> 11.71 | U5: =T5/N5 -> 0.44490881 | V5: =T5/153 -> 0.076535948
A6: 2 | B6: 4.38 | C6: 4.63 | D6: 6.89 | E6: =C6-B6 -> 0.25 | F6: =E6/B6 -> 0.057077626 | G6: =E6/(9*6) -> 0.0046296296 | H6: =E6/27 -> 0.0092592593 | I6: =D6-C6 -> 2.26 | J6: =I6/C6 -> 0.48812095 | K6: =I6/27 -> 0.083703704 | L6: 6 | M6: 26.18 | N6: 26.66 | O6: 39.29 | P6: =N6-M6 -> 0.48 | Q6: =P6/M6 -> 0.018334607 | R6: =P6/(9*2+3*17*4) -> 0.0021621622 | S6: =P6/153 -> 0.0031372549 | T6: =O6-N6 -> 12.63 | U6: =T6/N6 -> 0.47374344 | V6: =T6/153 -> 0.08254902
A7: 5 | B7: 4.51 | C7: 4.75 | D7: 7.2 | E7: =C7-B7 -> 0.24 | F7: =E7/B7 -> 0.053215078 | G7: =E7/(9*6) -> 0.0044444444 | H7: =E7/27 -> 0.0088888889 | I7: =D7-C7 -> 2.45 | J7: =I7/C7 -> 0.51578947 | K7: =I7/27 -> 0.090740741 | L7: 38 | M7: 27.4 | N7: 28.7 | O7: 43.99 | P7: =N7-M7 -> 1.3 | Q7: =P7/M7 -> 0.047445255 | R7: =P7/(9*2+3*17*4) -> 0.0058558559 | S7: =P7/153 -> 0.008496732 | T7: =O7-N7 -> 15.29 | U7: =T7/N7 -> 0.53275261 | V7: =T7/153 -> 0.099934641
A8: 6 | B8: 4.73 | C8: 4.99 | D8: 7.19 | E8: =C8-B8 -> 0.26 | F8: =E8/B8 -> 0.054968288 | G8: =E8/(9*6) -> 0.0048148148 | H8: =E8/27 -> 0.0096296296 | I8: =D8-C8 -> 2.2 | J8: =I8/C8 -> 0.44088176 | K8: =I8/27 -> 0.081481481 | L8: 45 | M8: 27.52 | N8: 28.49 | O8: 45.09 | P8: =N8-M8 -> 0.97 | Q8: =P8/M8 -> 0.035247093 | R8: =P8/(9*2+3*17*4) -> 0.0043693694 | S8: =P8/153 -> 0.0063398693 | T8: =O8-N8 -> 16.6 | U8: =T8/N8 -> 0.58266058 | V8: =T8/153 -> 0.10849673
A9: 10 | B9: 4.72 | C9: 5.02 | D9: 7.3 | E9: =C9-B9 -> 0.3 | F9: =E9/B9 -> 0.063559322 | G9: =E9/(9*6) -> 0.0055555556 | H9: =E9/27 -> 0.011111111 | I9: =D9-C9 -> 2.28 | J9: =I9/C9 -> 0.45418327 | K9: =I9/27 -> 0.084444444 | L9: 68 | M9: 18.91 | N9: 19.61 | O9: 34.04 | P9: =N9-M9 -> 0.7 | Q9: =P9/M9 -> 0.037017451 | R9: =P9/(9*2+3*17*4) -> 0.0031531532 | S9: =P9/153 -> 0.0045751634 | T9: =O9-N9 -> 14.43 | U9: =T9/N9 -> 0.73584906 | V9: =T9/153 -> 0.094313725
A10: 11 | B10: 4.76 | C10: 5 | D10: 6.91 | E10: =C10-B10 -> 0.24 | F10: =E10/B10 -> 0.050420168 | G10: =E10/(9*6) -> 0.0044444444 | H10: =E10/27 -> 0.0088888889 | I10: =D10-C10 -> 1.91 | J10: =I10/C10 -> 0.382 | K10: =I10/27 -> 0.070740741 | L10: 71 | M10: 18.82 | N10: 19.64 | O10: 34.67 | P10: =N10-M10 -> 0.82 | Q10: =P10/M10 -> 0.04357067 | R10: =P10/(9*2+3*17*4) -> 0.0036936937 | S10: =P10/153 -> 0.0053594771 | T10: =O10-N10 -> 15.03 | U10: =T10/N10 -> 0.76527495 | V10: =T10/153 -> 0.098235294
A11: 14 | B11: 4.65 | C11: 4.93 | D11: 7.19 | E11: =C11-B11 -> 0.28 | F11: =E11/B11 -> 0.060215054 | G11: =E11/(9*6) -> 0.0051851852 | H11: =E11/27 -> 0.01037037 | I11: =D11-C11 -> 2.26 | J11: =I11/C11 -> 0.45841785 | K11: =I11/27 -> 0.083703704 | L11: 82 | M11: 27.86 | N11: 28.65 | O11: 42.79 | P11: =N11-M11 -> 0.79 | Q11: =P11/M11 -> 0.028356066 | R11: =P11/(9*2+3*17*4) -> 0.0035585586 | S11: =P11/153 -> 0.0051633987 | T11: =O11-N11 -> 14.14 | U11: =T11/N11 -> 0.49354276 | V11: =T11/153 -> 0.092418301
A12: 16 | B12: 4.46 | C12: 4.67 | D12: 6.66 | E12: =C12-B12 -> 0.21 | F12: =E12/B12 -> 0.047085202 | G12: =E12/(9*6) -> 0.0038888889 | H12: =E12/27 -> 0.0077777778 | I12: =D12-C12 -> 1.99 | J12: =I12/C12 -> 0.4261242 | K12: =I12/27 -> 0.073703704 | L12: 85 | M12: 27.95 | N12: 28.22 | O12: 43.5 | P12: =N12-M12 -> 0.27 | Q12: =P12/M12 -> 0.0096601073 | R12: =P12/(9*2+3*17*4) -> 0.0012162162 | S12: =P12/153 -> 0.0017647059 | T12: =O12-N12 -> 15.28 | U12: =T12/N12 -> 0.54145996 | V12: =T12/153 -> 0.099869281
A13: 17 | B13: 4.35 | C13: 4.59 | D13: 7.18 | E13: =C13-B13 -> 0.24 | F13: =E13/B13 -> 0.055172414 | G13: =E13/(9*6) -> 0.0044444444 | H13: =E13/27 -> 0.0088888889 | I13: =D13-C13 -> 2.59 | J13: =I13/C13 -> 0.56427015 | K13: =I13/27 -> 0.095925926
A14: 19 | B14: 4.58 | C14: 4.82 | D14: 7.3 | E14: =C14-B14 -> 0.24 | F14: =E14/B14 -> 0.052401747 | G14: =E14/(9*6) -> 0.0044444444 | H14: =E14/27 -> 0.0088888889 | I14: =D14-C14 -> 2.48 | J14: =I14/C14 -> 0.51452282 | K14: =I14/27 -> 0.091851852
A15: 20 | B15: 4.83 | C15: 5.07 | D15: 6.97 | E15: =C15-B15 -> 0.24 | F15: =E15/B15 -> 0.049689441 | G15: =E15/(9*6) -> 0.0044444444 | H15: =E15/27 -> 0.0088888889 | I15: =D15-C15 -> 1.9 | J15: =I15/C15 -> 0.37475345 | K15: =I15/27 -> 0.07037037
A16: 24 | B16: 4.33 | C16: 4.57 | D16: 6.94 | E16: =C16-B16 -> 0.24 | F16: =E16/B16 -> 0.055427252 | G16: =E16/(9*6) -> 0.0044444444 | H16: =E16/27 -> 0.0088888889 | I16: =D16-C16 -> 2.37 | J16: =I16/C16 -> 0.51859956 | K16: =I16/27 -> 0.087777778 | L16: Sl1
A17: 26 | B17: 4.59 | C17: 4.85 | D17: 7.41 | E17: =C17-B17 -> 0.26 | F17: =E17/B17 -> 0.05664488 | G17: =E17/(9*6) -> 0.0048148148 | H17: =E17/27 -> 0.0096296296 | I17: =D17-C17 -> 2.56 | J17: =I17/C17 -> 0.52783505 | K17: =I17/27 -> 0.094814815 | L17: Sl2
A18: 29 | B18: 4.3 | C18: 4.55 | D18: 6.69 | E18: =C18-B18 -> 0.25 | F18: =E18/B18 -> 0.058139535 | G18: =E18/(9*6) -> 0.0046296296 | H18: =E18/27 -> 0.0092592593 | I18: =D18-C18 -> 2.14 | J18: =I18/C18 -> 0.47032967 | K18: =I18/27 -> 0.079259259 | L18: Sl3
A19: 31 | B19: 3.42 | C19: 3.7 | D19: 5.93 | E19: =C19-B19 -> 0.28 | F19: =E19/B19 -> 0.081871345 | G19: =E19/(9*6) -> 0.0051851852 | H19: =E19/27 -> 0.01037037 | I19: =D19-C19 -> 2.23 | J19: =I19/C19 -> 0.6027027 | K19: =I19/27 -> 0.082592593 | L19: Sl4
A20: 32 | B20: 3.41 | C20: 3.69 | D20: 6.13 | E20: =C20-B20 -> 0.28 | F20: =E20/B20 -> 0.082111437 | G20: =E20/(9*6) -> 0.0051851852 | H20: =E20/27 -> 0.01037037 | I20: =D20-C20 -> 2.44 | J20: =I20/C20 -> 0.66124661 | K20: =I20/27 -> 0.09037037
A21: 35 | B21: 3.43 | C21: 3.72 | D21: 6.04 | E21: =C21-B21 -> 0.29 | F21: =E21/B21 -> 0.084548105 | G21: =E21/(9*6) -> 0.0053703704 | H21: =E21/27 -> 0.010740741 | I21: =D21-C21 -> 2.32 | J21: =I21/C21 -> 0.62365591 | K21: =I21/27 -> 0.085925926
A22: 37 | B22: 3.25 | C22: 3.51 | D22: 5.67 | E22: =C22-B22 -> 0.26 | F22: =E22/B22 -> 0.08 | G22: =E22/(9*6) -> 0.0048148148 | H22: =E22/27 -> 0.0096296296 | I22: =D22-C22 -> 2.16 | J22: =I22/C22 -> 0.61538462 | K22: =I22/27 -> 0.08
A23: 44 | B23: 3.25 | C23: 3.55 | D23: 5.95 | E23: =C23-B23 -> 0.3 | F23: =E23/B23 -> 0.092307692 | G23: =E23/(9*6) -> 0.0055555556 | H23: =E23/27 -> 0.011111111 | I23: =D23-C23 -> 2.4 | J23: =I23/C23 -> 0.67605634 | K23: =I23/27 -> 0.088888889
A24: 47 | B24: 3.32 | C24: 3.67 | D24: 6.15 | E24: =C24-B24 -> 0.35 | F24: =E24/B24 -> 0.10542169 | G24: =E24/(9*6) -> 0.0064814815 | H24: =E24/27 -> 0.012962963 | I24: =D24-C24 -> 2.48 | J24: =I24/C24 -> 0.67574932 | K24: =I24/27 -> 0.091851852
A25: 49 | B25: 3.23 | C25: 3.77 | D25: 6.12 | E25: =C25-B25 -> 0.54 | F25: =E25/B25 -> 0.16718266 | G25: =E25/(9*6) -> 0.01 | H25: =E25/27 -> 0.02 | I25: =D25-C25 -> 2.35 | J25: =I25/C25 -> 0.62334218 | K25: =I25/27 -> 0.087037037
A26: 50 | B26: 3.31 | C26: 3.79 | D26: 6.15 | E26: =C26-B26 -> 0.48 | F26: =E26/B26 -> 0.14501511 | G26: =E26/(9*6) -> 0.0088888889 | H26: =E26/27 -> 0.017777778 | I26: =D26-C26 -> 2.36 | J26: =I26/C26 -> 0.62269129 | K26: =I26/27 -> 0.087407407
A27: 53 | B27: 3.37 | C27: 3.92 | D27: 6.17 | E27: =C27-B27 -> 0.55 | F27: =E27/B27 -> 0.16320475 | G27: =E27/(9*6) -> 0.010185185 | H27: =E27/27 -> 0.02037037 | I27: =D27-C27 -> 2.25 | J27: =I27/C27 -> 0.57397959 | K27: =I27/27 -> 0.083333333
A28: 57 | B28: 3.41 | C28: 3.93 | D28: 6.29 | E28: =C28-B28 -> 0.52 | F28: =E28/B28 -> 0.15249267 | G28: =E28/(9*6) -> 0.0096296296 | H28: =E28/27 -> 0.019259259 | I28: =D28-C28 -> 2.36 | J28: =I28/C28 -> 0.60050891 | K28: =I28/27 -> 0.087407407
A29: 59 | B29: 3.21 | C29: 4.1 | D29: 6.17 | E29: =C29-B29 -> 0.89 | F29: =E29/B29 -> 0.27725857 | G29: =E29/(9*6) -> 0.016481481 | H29: =E29/27 -> 0.032962963 | I29: =D29-C29 -> 2.07 | J29: =I29/C29 -> 0.50487805 | K29: =I29/27 -> 0.076666667
A30: 62 | B30: 3.2 | C30: 3.7 | D30: 5.96 | E30: =C30-B30 -> 0.5 | F30: =E30/B30 -> 0.15625 | G30: =E30/(9*6) -> 0.0092592593 | H30: =E30/27 -> 0.018518519 | I30: =D30-C30 -> 2.26 | J30: =I30/C30 -> 0.61081081 | K30: =I30/27 -> 0.083703704
A31: 64 | B31: 4.51 | C31: 4.83 | D31: 7.15 | E31: =C31-B31 -> 0.32 | F31: =E31/B31 -> 0.070953437 | G31: =E31/(9*6) -> 0.0059259259 | H31: =E31/27 -> 0.011851852 | I31: =D31-C31 -> 2.32 | J31: =I31/C31 -> 0.48033126 | K31: =I31/27 -> 0.085925926
... A78: 194 | B78: 4.37 | C78: 4.55 | D78: 7.22 | E78: =C78-B78 -> 0.18 | F78: =E78/B78 -> 0.041189931 | G78: =E78/(9*6) -> 0.0033333333 | H78: =E78/27 -> 0.0066666667 | I78: =D78-C78 -> 2.67 | J78: =I78/C78 -> 0.58681319 | K78: =I78/27 -> 0.098888889

Sheet Sl Hito
A1: m1 = 30s dip. hito + 100 oC 30 min
A2: stieņa nr | B2: mo* | C2: m1 | D2: uzņemtais hito | E2: hito g/g MK | F2: hito g/cm2 | G2: hto g/cm3 | H2: m2, kond 20/65
A3: 13 | B3: 18.9 | C3: 19.65 | D3: =C3-B3 -> 0.75 | E3: =D3/B3 -> 0.03968254 | F3: =D3/(9*2+3*17*4) -> 0.0033783784 | G3: =D3/153 -> 0.0049019608
A4: 17 | B4: 19.18 | C4: 20.13 | D4: =C4-B4 -> 0.95 | E4: =D4/B4 -> 0.049530761 | F4: =D4/(9*2+3*17*4) -> 0.0042792793 | G4: =D4/153 -> 0.0062091503
A5: 33 | B5: 25.93 | C5: 26.51 | D5: =C5-B5 -> 0.58 | E5: =D5/B5 -> 0.022367914 | F5: =D5/(9*2+3*17*4) -> 0.0026126126 | G5: =D5/153 -> 0.0037908497
A6: 42salūzis | B6: 24.23 | C6: 27.09 | D6: =C6-B6 -> 2.86 | E6: =D6/B6 -> 0.11803549 | F6: =D6/(9*2+3*17*4) -> 0.012882883 | G6: =D6/153 -> 0.01869281
A7: 59 | B7: 26.13 | C7: 27.05 | D7: =C7-B7 -> 0.92 | E7: =D7/B7 -> 0.035208573 | F7: =D7/(9*2+3*17*4) -> 0.0041441441 | G7: =D7/153 -> 0.0060130719
A8: 61 | B8: 25.27 | C8: 26.41 | D8: =C8-B8 -> 1.14 | E8: =D8/B8 -> 0.045112782 | F8: =D8/(9*2+3*17*4) -> 0.0051351351 | G8: =D8/153 -> 0.0074509804
A9: 67 | B9: 24.68 | C9: 25.27 | D9: =C9-B9 -> 0.59 | E9: =D9/B9 -> 0.023905997 | F9: =D9/(9*2+3*17*4) -> 0.0026576577 | G9: =D9/153 -> 0.0038562092
A10: 74 | B10: 19.45 | C10: 20.11 | D10: =C10-B10 -> 0.66 | E10: =D10/B10 -> 0.033933162 | F10: =D10/(9*2+3*17*4) -> 0.002972973 | G10: =D10/153 -> 0.0043137255
A11: 79 | B11: 27.23 | C11: 28.25 | D11: =C11-B11 -> 1.02 | E11: =D11/B11 -> 0.037458685 | F11: =D11/(9*2+3*17*4) -> 0.0045945946 | G11: =D11/153 -> 0.0066666667
A12: 87 | B12: 28.05 | C12: 28.68 | D12: =C12-B12 -> 0.63 | E12: =D12/B12 -> 0.022459893 | F12: =D12/(9*2+3*17*4) -> 0.0028378378 | G12: =D12/153 -> 0.0041176471
A13: 89 | B13: 25.06 | C13: 25.7 | D13: =C13-B13 -> 0.64 | E13: =D13/B13 -> 0.025538707 | F13: =D13/(9*2+3*17*4) -> 0.0028828829 | G13: =D13/153 -> 0.0041830065
A14: 93 | B14: 25.94 | C14: 26.49 | D14: =C14-B14 -> 0.55 | E14: =D14/B14 -> 0.021202776 | F14: =D14/(9*2+3*17*4) -> 0.0024774775 | G14: =D14/153 -> 0.0035947712

Sheet Sa suberīnskābe
A1: 1 | J1: Sl1
B2: 29.07.2025 | J2: Sl2
B3: suberīnskabe | D3: m1 = 30s dip + 100 oC līdz konst. m. + 150 oC 15 min | J3: Sl3
B4: 78 gab | H4: 20 gab | J4: Sl4
A5: substrats | B5: kubiņa nr | C5: mo* | D5: m1 | E5: uzņemtā sub. Sk. | F5: sub. sk. g/g MK | G5: sub. sk. g/cm3 | H5: stieņa nr | I5: mo* | J5: m1 | K5: uzņemtā sub. Sk. | L5: sub. sk. g/g MK | M5: sub. sk. g/cm3
A6: Sa1 | B6: 101 | C6: 1.87 | D6: 3.63 | E6: =D6-C6 -> 1.76 | F6: =E6/C6 -> 0.94117647 | G6: =E6/27 -> 0.065185185 | H6: 1 | I6: 12.26 | J6: 24.02 | K6: =J6-I6 -> 11.76 | L6: =K6/I6 -> 0.95921697 | M6: =K6/153 -> 0.076862745
A7: Sa1 | B7: 102 | C7: 1.98 | D7: 3.76 | E7: =D7-C7 -> 1.78 | F7: =E7/C7 -> 0.8989899 | G7: =E7/27 -> 0.065925926 | H7: 5
A8: Sa1 | B8: 103 | C8: 2 | D8: 3.89 | E8: =D8-C8 -> 1.89 | F8: =E8/C8 -> 0.945 | G8: =E8/27 -> 0.07 | H8: 51 | I8: 12.69 | J8: 23.88 | K8: =J8-I8 -> 11.19 | L8: =K8/I8 -> 0.88179669 | M8: =K8/153 -> 0.073137255
A9: Sa1 | B9: 104 | C9: 1.99 | D9: 3.76 | E9: =D9-C9 -> 1.77 | F9: =E9/C9 -> 0.88944724 | G9: =E9/27 -> 0.065555556 | H9: 57 | I9: 12.29 | J9: 24.73 | K9: =J9-I9 -> 12.44 | L9: =K9/I9 -> 1.012205 | M9: =K9/153 -> 0.08130719
A10: Sa1 | B10: 105 | C10: 2.08 | D10: 4.02 | E10: =D10-C10 -> 1.94 | F10: =E10/C10 -> 0.93269231 | G10: =E10/27 -> 0.071851852 | H10: 68 | I10: 13.51 | J10: 25.44 | K10: =J10-I10 -> 11.93 | L10: =K10/I10 -> 0.88304959 | M10: =K10/153 -> 0.077973856
A11: Sa1 | B11: 291 | C11: 2.02 | D11: 3.94 | E11: =D11-C11 -> 1.92 | F11: =E11/C11 -> 0.95049505 | G11: =E11/27 -> 0.071111111 | H11: 6 | I11: 14.95 | J11: 27.62 | K11: =J11-I11 -> 12.67 | L11: =K11/I11 -> 0.84749164 | M11: =K11/153 -> 0.082810458
A12: Sa1 | B12: 292 | C12: 2.24 | D12: 4.27 | E12: =D12-C12 -> 2.03 | F12: =E12/C12 -> 0.90625 | G12: =E12/27 -> 0.075185185 | H12: 9 | I12: 15.35 | J12: 28.75 | K12: =J12-I12 -> 13.4 | L12: =K12/I12 -> 0.87296417 | M12: =K12/153 -> 0.087581699
A13: Sa1 | B13: 293 | C13: 2.31 | D13: 4.37 | E13: =D13-C13 -> 2.06 | F13: =E13/C13 -> 0.89177489 | G13: =E13/27 -> 0.076296296 | H13: 45 | I13: 16.09 | J13: 29.51 | K13: =J13-I13 -> 13.42 | L13: =K13/I13 -> 0.83405842 | M13: =K13/153 -> 0.087712418
A14: Sa1 | B14: 294 | C14: 2.05 | D14: 3.76 | E14: =D14-C14 -> 1.71 | F14: =E14/C14 -> 0.83414634 | G14: =E14/27 -> 0.063333333 | H14: 48 | I14: 15.71 | J14: 28.95 | K14: =J14-I14 -> 13.24 | L14: =K14/I14 -> 0.8427753 | M14: =K14/153 -> 0.086535948
A15: Sa1 | B15: 295 | C15: 2.19 | D15: 4.12 | E15: =D15-C15 -> 1.93 | F15: =E15/C15 -> 0.88127854 | G15: =E15/27 -> 0.071481481 | H15: 62 | I15: 15.76 | J15: 28.09 | K15: =J15-I15 -> 12.33 | L15: =K15/I15 -> 0.78236041 | M15: =K15/153 -> 0.080588235
A16: Sa1 | B16: 281 | C16: 2.19 | D16: 4.02 | E16: =D16-C16 -> 1.83 | F16: =E16/C16 -> 0.83561644 | G16: =E16/27 -> 0.067777778 | H16: 17 | I16: 19.14 | J16: 31.15 | K16: =J16-I16 -> 12.01 | L16: =K16/I16 -> 0.62748171 | M16: =K16/153 -> 0.078496732
A17: Sa1 | B17: 282 | C17: 1.99 | D17: 3.71 | E17: =D17-C17 -> 1.72 | F17: =E17/C17 -> 0.86432161 | G17: =E17/27 -> 0.063703704 | H17: 71 | I17: 21.44 | J17: 33.31 | K17: =J17-I17 -> 11.87 | L17: =K17/I17 -> 0.55363806 | M17: =K17/153 -> 0.077581699
A18: Sa1 | B18: 283 | C18: 2.08 | D18: 3.77 | E18: =D18-C18 -> 1.69 | F18: =E18/C18 -> 0.8125 | G18: =E18/27 -> 0.062592593 | H18: 35 | I18: 19.12 | J18: 31.3 | K18: =J18-I18 -> 12.18 | L18: =K18/I18 -> 0.63702929 | M18: =K18/153 -> 0.079607843
A19: Sa1 | B19: 284 | C19: 2.02 | D19: 3.76 | E19: =D19-C19 -> 1.74 | F19: =E19/C19 -> 0.86138614 | G19: =E19/27 -> 0.064444444 | H19: 121 | I19: 20.81 | J19: 32.86 | K19: =J19-I19 -> 12.05 | L19: =K19/I19 -> 0.57904853 | M19: =K19/153 -> 0.07875817
... A25: Sa1 | B25: 325 | C25: 2.38 | D25: 4.36 | E25: =D25-C25 -> 1.98 | F25: =E25/C25 -> 0.83193277 | G25: =E25/27 -> 0.073333333 | H25: 112 | I25: 13.08 | J25: 23.97 | K25: =J25-I25 -> 10.89 | L25: =K25/I25 -> 0.83256881 | M25: =K25/153 -> 0.071176471
A26: Sa2 | B26: 201 | C26: 2.73 | D26: 4.96 | E26: =D26-C26 -> 2.23 | F26: =E26/C26 -> 0.81684982 | G26: =E26/27 -> 0.082592593
A27: Sa2 | B27: 202 | C27: 2.65 | D27: 4.89 | E27: =D27-C27 -> 2.24 | F27: =E27/C27 -> 0.84528302 | G27: =E27/27 -> 0.082962963
A28: Sa2 | B28: 203 | C28: 2.7 | D28: 4.92 | E28: =D28-C28 -> 2.22 | F28: =E28/C28 -> 0.82222222 | G28: =E28/27 -> 0.082222222
A29: Sa2 | B29: 204 | C29: 2.64 | D29: 4.82 | E29: =D29-C29 -> 2.18 | F29: =E29/C29 -> 0.82575758 | G29: =E29/27 -> 0.080740741
A30: Sa2 | B30: 205 | C30: 2.59 | D30: 4.8 | E30: =D30-C30 -> 2.21 | F30: =E30/C30 -> 0.85328185 | G30: =E30/27 -> 0.081851852
A31: Sa2 | B31: 316 | C31: 2.71 | D31: 4.88 | E31: =D31-C31 -> 2.17 | F31: =E31/C31 -> 0.80073801 | G31: =E31/27 -> 0.08037037
A32: Sa2 | B32: 317 | C32: 2.72 | D32: 4.88 | E32: =D32-C32 -> 2.16 | F32: =E32/C32 -> 0.79411765 | G32: =E32/27 -> 0.08
A33: Sa2 | B33: 318 | C33: 2.79 | D33: 4.96 | E33: =D33-C33 -> 2.17 | F33: =E33/C33 -> 0.77777778 | G33: =E33/27 -> 0.08037037
A34: Sa2 | B34: 319 | C34: 2.83 | D34: 5.02 | E34: =D34-C34 -> 2.19 | F34: =E34/C34 -> 0.77385159 | G34: =E34/27 -> 0.081111111
A35: Sa2 | B35: 320 | C35: 2.82 | D35: 5.06 | E35: =D35-C35 -> 2.24 | F35: =E35/C35 -> 0.79432624 | G35: =E35/27 -> 0.082962963
A36: Sa2 | B36: 271 | C36: 2.82 | D36: 5.07 | E36: =D36-C36 -> 2.25 | F36: =E36/C36 -> 0.79787234 | G36: =E36/27 -> 0.083333333
A37: Sa2 | B37: 272 | C37: 2.8 | D37: 5.08 | E37: =D37-C37 -> 2.28 | F37: =E37/C37 -> 0.81428571 | G37: =E37/27 -> 0.084444444
... A83: Sa4 | B83: 214 | C83: 1.89 | D83: 3.83 | E83: =D83-C83 -> 1.94 | F83: =E83/C83 -> 1.026455 | G83: =E83/27 -> 0.071851852

Sheet Sa hito + sub
R1: Sl1
B2: 29.07.2025 | R2: Sl2
B3: hito +suberīnskabe | E3: m1 = 30s dip. hito + 100 oC 30 min | K3: m2 = 30s dip. suber. + 100 oC līdz konst. m. + 150 oC 15 min | R3: Sl3
B4: 80gab | M4: 8 gab | R4: Sl4
B5: kubiņa nr | C5: mo* | D5: m1 | E5: m2 | F5: Uzņemtais hito. | G5: hito g/g MK | H5: hito g/cm2 | I5: hito g/cm3 | J5: uzņemtā sub. Sk. | K5: sub. sk. g/g MK | L5: sub. sk. g/cm3 | M5: stieņa nr | N5: mo* | O5: m1 | P5: m2 | Q5: Uzņemtais hito. | R5: hito g/g MK | S5: hito g/cm2 | T5: hito g/cm3 | U5: uzņemtā sub. Sk. | V5: sub. sk. g/g MK | W5: sub. sk. g/cm3
A6: Sa1 | B6: 106 | C6: 1.81 | D6: 1.86 | E6: 3.78 | F6: =D6-C6 -> 0.05 | G6: =F6/C6 -> 0.027624309 | H6: =F6/(9*6) -> 0.00092592593 | I6: =F6/27 -> 0.0018518519 | J6: =E6-D6 -> 1.92 | K6: =J6/D6 -> 1.0322581 | L6: =J6/27 -> 0.071111111 | M6: 2 | N6: 12.03
A7: Sa1 | B7: 107 | C7: 1.86 | D7: 1.85 | E7: 3.66 | F7: =D7-C7 -> -0.01 | G7: =F7/C7 -> -0.0053763441 | H7: =F7/(9*6) -> -0.00018518519 | I7: =F7/27 -> -0.00037037037 | J7: =E7-D7 -> 1.81 | K7: =J7/D7 -> 0.97837838 | L7: =J7/27 -> 0.067037037 | M7: 52 | N7: 12.79
A8: Sa1 | B8: 108 | C8: 1.9 | D8: 1.96 | E8: 4 | F8: =D8-C8 -> 0.06 | G8: =F8/C8 -> 0.031578947 | H8: =F8/(9*6) -> 0.0011111111 | I8: =F8/27 -> 0.0022222222 | J8: =E8-D8 -> 2.04 | K8: =J8/D8 -> 1.0408163 | L8: =J8/27 -> 0.075555556 | M8: 58 | N8: 12.15
A9: Sa1 | B9: 109 | C9: 1.97 | D9: 1.99 | E9: 4.06 | F9: =D9-C9 -> 0.02 | G9: =F9/C9 -> 0.010152284 | H9: =F9/(9*6) -> 0.00037037037 | I9: =F9/27 -> 0.00074074074 | J9: =E9-D9 -> 2.07 | K9: =J9/D9 -> 1.040201 | L9: =J9/27 -> 0.076666667 | M9: 65 | N9: 14.16 | O9: 14.82 | P9: 27.48 | Q9: =O9-N9 -> 0.66 | R9: =Q9/N9 -> 0.046610169 | S9: =Q9/(9*2+3*17*4) -> 0.002972973 | T9: =Q9/153 -> 0.0043137255 | U9: =P9-O9 -> 12.66 | V9: =U9/O9 -> 0.85425101 | W9: =U9/153 -> 0.082745098
A10: Sa1 | B10: 110 | C10: 2.12 | D10: 2.17 | E10: 4.42 | F10: =D10-C10 -> 0.05 | G10: =F10/C10 -> 0.023584906 | H10: =F10/(9*6) -> 0.00092592593 | I10: =F10/27 -> 0.0018518519 | J10: =E10-D10 -> 2.25 | K10: =J10/D10 -> 1.0368664 | L10: =J10/27 -> 0.083333333 | M10: 69 | N10: 13.99 | O10: 14.22 | P10: 27.001 | Q10: =O10-N10 -> 0.23 | R10: =Q10/N10 -> 0.016440315 | S10: =Q10/(9*2+3*17*4) -> 0.001036036 | T10: =Q10/153 -> 0.001503268 | U10: =P10-O10 -> 12.781 | V10: =U10/O10 -> 0.8988045 | W10: =U10/153 -> 0.083535948
A11: Sa1 | B11: 306 | C11: 2.23 | D11: 2.41 | E11: 5.02 | F11: =D11-C11 -> 0.18 | G11: =F11/C11 -> 0.080717489 | H11: =F11/(9*6) -> 0.0033333333 | I11: =F11/27 -> 0.0066666667 | J11: =E11-D11 -> 2.61 | K11: =J11/D11 -> 1.0829876 | L11: =J11/27 -> 0.096666667 | M11: 7 | N11: 14.92 | O11: 15.6 | P11: 29.64 | Q11: =O11-N11 -> 0.68 | R11: =Q11/N11 -> 0.045576408 | S11: =Q11/(9*2+3*17*4) -> 0.0030630631 | T11: =Q11/153 -> 0.0044444444 | U11: =P11-O11 -> 14.04 | V11: =U11/O11 -> 0.9 | W11: =U11/153 -> 0.091764706
A12: Sa1 | B12: 307 | C12: 2.21 | D12: 2.39 | E12: 4.77 | F12: =D12-C12 -> 0.18 | G12: =F12/C12 -> 0.081447964 | H12: =F12/(9*6) -> 0.0033333333 | I12: =F12/27 -> 0.0066666667 | J12: =E12-D12 -> 2.38 | K12: =J12/D12 -> 0.9958159 | L12: =J12/27 -> 0.088148148 | M12: 10 | N12: 15.44 | O12: 16.25 | P12: 30.03 | Q12: =O12-N12 -> 0.81 | R12: =Q12/N12 -> 0.05246114 | S12: =Q12/(9*2+3*17*4) -> 0.0036486486 | T12: =Q12/153 -> 0.0052941176 | U12: =P12-O12 -> 13.78 | V12: =U12/O12 -> 0.848 | W12: =U12/153 -> 0.090065359
A13: Sa1 | B13: 308 | C13: 2.05 | D13: 2.09 | E13: 4.14 | F13: =D13-C13 -> 0.04 | G13: =F13/C13 -> 0.019512195 | H13: =F13/(9*6) -> 0.00074074074 | I13: =F13/27 -> 0.0014814815 | J13: =E13-D13 -> 2.05 | K13: =J13/D13 -> 0.98086124 | L13: =J13/27 -> 0.075925926 | M13: 46 | N13: 15.99 | O13: 16.99 | P13: 30.33 | Q13: =O13-N13 -> 1 | R13: =Q13/N13 -> 0.062539087 | S13: =Q13/(9*2+3*17*4) -> 0.0045045045 | T13: =Q13/153 -> 0.0065359477 | U13: =P13-O13 -> 13.34 | V13: =U13/O13 -> 0.78516775 | W13: =U13/153 -> 0.087189542
A14: Sa1 | B14: 309 | C14: 1.96 | D14: 2.09 | E14: 4.22 | F14: =D14-C14 -> 0.13 | G14: =F14/C14 -> 0.066326531 | H14: =F14/(9*6) -> 0.0024074074 | I14: =F14/27 -> 0.0048148148 | J14: =E14-D14 -> 2.13 | K14: =J14/D14 -> 1.0191388 | L14: =J14/27 -> 0.078888889 | M14: 49 | N14: 15.96 | O14: 16.27 | P14: 29.35 | Q14: =O14-N14 -> 0.31 | R14: =Q14/N14 -> 0.019423559 | S14: =Q14/(9*2+3*17*4) -> 0.0013963964 | T14: =Q14/153 -> 0.0020261438 | U14: =P14-O14 -> 13.08 | V14: =U14/O14 -> 0.80393362 | W14: =U14/153 -> 0.085490196
A15: Sa1 | B15: 310 | C15: 2 | D15: 2.12 | E15: 4.32 | F15: =D15-C15 -> 0.12 | G15: =F15/C15 -> 0.06 | H15: =F15/(9*6) -> 0.0022222222 | I15: =F15/27 -> 0.0044444444 | J15: =E15-D15 -> 2.2 | K15: =J15/D15 -> 1.0377358 | L15: =J15/27 -> 0.081481481 | M15: 63 | N15: 15.72 | O15: 16.38 | P15: 29.43 | Q15: =O15-N15 -> 0.66 | R15: =Q15/N15 -> 0.041984733 | S15: =Q15/(9*2+3*17*4) -> 0.002972973 | T15: =Q15/153 -> 0.0043137255 | U15: =P15-O15 -> 13.05 | V15: =U15/O15 -> 0.7967033 | W15: =U15/153 -> 0.085294118
A16: Sa1 | B16: 286 | C16: 2.02 | D16: 2.19 | E16: 4.47 | F16: =D16-C16 -> 0.17 | G16: =F16/C16 -> 0.084158416 | H16: =F16/(9*6) -> 0.0031481481 | I16: =F16/27 -> 0.0062962963 | J16: =E16-D16 -> 2.28 | K16: =J16/D16 -> 1.0410959 | L16: =J16/27 -> 0.084444444 | M16: 18 | N16: 19.29 | O16: 19.35 | P16: 32.57 | Q16: =O16-N16 -> 0.06 | R16: =Q16/N16 -> 0.0031104199 | S16: =Q16/(9*2+3*17*4) -> 0.00027027027 | T16: =Q16/153 -> 0.00039215686 | U16: =P16-O16 -> 13.22 | V16: =U16/O16 -> 0.68320413 | W16: =U16/153 -> 0.086405229
A17: Sa1 | B17: 287 | C17: 2.14 | D17: 2.31 | E17: 4.65 | F17: =D17-C17 -> 0.17 | G17: =F17/C17 -> 0.079439252 | H17: =F17/(9*6) -> 0.0031481481 | I17: =F17/27 -> 0.0062962963 | J17: =E17-D17 -> 2.34 | K17: =J17/D17 -> 1.012987 | L17: =J17/27 -> 0.086666667 | M17: 72 | N17: 21.34 | O17: 21.39 | P17: 33.81 | Q17: =O17-N17 -> 0.05 | R17: =Q17/N17 -> 0.0023430178 | S17: =Q17/(9*2+3*17*4) -> 0.00022522523 | T17: =Q17/153 -> 0.00032679739 | U17: =P17-O17 -> 12.42 | V17: =U17/O17 -> 0.58064516 | W17: =U17/153 -> 0.081176471
A18: Sa1 | B18: 288 | C18: 2.18 | D18: 2.28 | E18: 4.41 | F18: =D18-C18 -> 0.1 | G18: =F18/C18 -> 0.04587156 | H18: =F18/(9*6) -> 0.0018518519 | I18: =F18/27 -> 0.0037037037 | J18: =E18-D18 -> 2.13 | K18: =J18/D18 -> 0.93421053 | L18: =J18/27 -> 0.078888889 | M18: 36 | N18: 20.47 | O18: 20.84 | P18: 32.89 | Q18: =O18-N18 -> 0.37 | R18: =Q18/N18 -> 0.018075232 | S18: =Q18/(9*2+3*17*4) -> 0.0016666667 | T18: =Q18/153 -> 0.0024183007 | U18: =P18-O18 -> 12.05 | V18: =U18/O18 -> 0.57821497 | W18: =U18/153 -> 0.07875817
A19: Sa1 | B19: 289 | C19: 1.99 | D19: 2.22 | E19: 4.44 | F19: =D19-C19 -> 0.23 | G19: =F19/C19 -> 0.11557789 | H19: =F19/(9*6) -> 0.0042592593 | I19: =F19/27 -> 0.0085185185 | J19: =E19-D19 -> 2.22 | K19: =J19/D19 -> 1 | L19: =J19/27 -> 0.082222222 | M19: 123 | N19: 22.18 | O19: 22.21 | P19: 36.46 | Q19: =O19-N19 -> 0.03 | R19: =Q19/N19 -> 0.0013525699 | S19: =Q19/(9*2+3*17*4) -> 0.00013513514 | T19: =Q19/153 -> 0.00019607843 | U19: =P19-O19 -> 14.25 | V19: =U19/O19 -> 0.64160288 | W19: =U19/153 -> 0.093137255
A20: Sa1 | B20: 290 | C20: 2.19 | D20: 2.22 | E20: 4.16 | F20: =D20-C20 -> 0.03 | G20: =F20/C20 -> 0.01369863 | H20: =F20/(9*6) -> 0.00055555556 | I20: =F20/27 -> 0.0011111111 | J20: =E20-D20 -> 1.94 | K20: =J20/D20 -> 0.87387387 | L20: =J20/27 -> 0.071851852 | M20: 124 | N20: 20.77 | O20: 20.73 | P20: 34.73 | Q20: =O20-N20 -> -0.04 | R20: =Q20/N20 -> -0.0019258546 | S20: =Q20/(9*2+3*17*4) -> -0.00018018018 | T20: =Q20/153 -> -0.00026143791 | U20: =P20-O20 -> 14 | V20: =U20/O20 -> 0.67534973 | W20: =U20/153 -> 0.091503268
... A23: Sa1 | B23: 328 | C23: 1.96 | D23: 2.42 | E23: 4.24 | F23: =D23-C23 -> 0.46 | G23: =F23/C23 -> 0.23469388 | H23: =F23/(9*6) -> 0.0085185185 | I23: =F23/27 -> 0.017037037 | J23: =E23-D23 -> 1.82 | K23: =J23/D23 -> 0.75206612 | L23: =J23/27 -> 0.067407407 | M23: 42 | N23: 12.54 | O23: 12.52 | P23: 25.53 | Q23: =O23-N23 -> -0.02 | R23: =Q23/N23 -> -0.0015948963 | S23: =Q23/(9*2+3*17*4) -> -9.009009e-05 | T23: =Q23/153 -> -0.00013071895 | U23: =P23-O23 -> 13.01 | V23: =U23/O23 -> 1.0391374 | W23: =U23/153 -> 0.08503268
A24: Sa1 | B24: 329 | C24: 2.08 | D24: 2.1 | E24: 4.41 | F24: =D24-C24 -> 0.02 | G24: =F24/C24 -> 0.0096153846 | H24: =F24/(9*6) -> 0.00037037037 | I24: =F24/27 -> 0.00074074074 | J24: =E24-D24 -> 2.31 | K24: =J24/D24 -> 1.1 | L24: =J24/27 -> 0.085555556 | M24: 16 | N24: 12.59
A25: Sa1 | B25: 330 | C25: 2.02 | D25: 2.14 | E25: 4.15 | F25: =D25-C25 -> 0.12 | G25: =F25/C25 -> 0.059405941 | H25: =F25/(9*6) -> 0.0022222222 | I25: =F25/27 -> 0.0044444444 | J25: =E25-D25 -> 2.01 | K25: =J25/D25 -> 0.93925234 | L25: =J25/27 -> 0.074444444 | M25: 98 | N25: 13.56 | O25: 13.93 | P25: 27.45 | Q25: =O25-N25 -> 0.37 | R25: =Q25/N25 -> 0.027286136 | S25: =Q25/(9*2+3*17*4) -> 0.0016666667 | T25: =Q25/153 -> 0.0024183007 | U25: =P25-O25 -> 13.52 | V25: =U25/O25 -> 0.97056712 | W25: =U25/153 -> 0.088366013
A26: Sa2 | B26: 206 | C26: 2.64 | D26: 2.83 | E26: 5.22 | F26: =D26-C26 -> 0.19 | G26: =F26/C26 -> 0.071969697 | H26: =F26/(9*6) -> 0.0035185185 | I26: =F26/27 -> 0.007037037 | J26: =E26-D26 -> 2.39 | K26: =J26/D26 -> 0.84452297 | L26: =J26/27 -> 0.088518519
A27: Sa2 | B27: 207 | C27: 2.68 | D27: 2.89 | E27: 5.26 | F27: =D27-C27 -> 0.21 | G27: =F27/C27 -> 0.078358209 | H27: =F27/(9*6) -> 0.0038888889 | I27: =F27/27 -> 0.0077777778 | J27: =E27-D27 -> 2.37 | K27: =J27/D27 -> 0.8200692 | L27: =J27/27 -> 0.087777778
A28: Sa2 | B28: 208 | C28: 2.7 | D28: 2.9 | E28: 5.38 | F28: =D28-C28 -> 0.2 | G28: =F28/C28 -> 0.074074074 | H28: =F28/(9*6) -> 0.0037037037 | I28: =F28/27 -> 0.0074074074 | J28: =E28-D28 -> 2.48 | K28: =J28/D28 -> 0.85517241 | L28: =J28/27 -> 0.091851852
A29: Sa2 | B29: 209 | C29: 2.65 | D29: 2.88 | E29: 5.38 | F29: =D29-C29 -> 0.23 | G29: =F29/C29 -> 0.086792453 | H29: =F29/(9*6) -> 0.0042592593 | I29: =F29/27 -> 0.0085185185 | J29: =E29-D29 -> 2.5 | K29: =J29/D29 -> 0.86805556 | L29: =J29/27 -> 0.092592593
A30: Sa2 | B30: 210 | C30: 2.59 | D30: 2.82 | E30: 5.21 | F30: =D30-C30 -> 0.23 | G30: =F30/C30 -> 0.088803089 | H30: =F30/(9*6) -> 0.0042592593 | I30: =F30/27 -> 0.0085185185 | J30: =E30-D30 -> 2.39 | K30: =J30/D30 -> 0.84751773 | L30: =J30/27 -> 0.088518519
A31: Sa2 | B31: 311 | C31: 2.73 | D31: 2.94 | E31: 5.36 | F31: =D31-C31 -> 0.21 | G31: =F31/C31 -> 0.076923077 | H31: =F31/(9*6) -> 0.0038888889 | I31: =F31/27 -> 0.0077777778 | J31: =E31-D31 -> 2.42 | K31: =J31/D31 -> 0.82312925 | L31: =J31/27 -> 0.08962963
A32: Sa2 | B32: 312 | C32: 2.66 | D32: 2.8 | E32: 5.29 | F32: =D32-C32 -> 0.14 | G32: =F32/C32 -> 0.052631579 | H32: =F32/(9*6) -> 0.0025925926 | I32: =F32/27 -> 0.0051851852 | J32: =E32-D32 -> 2.49 | K32: =J32/D32 -> 0.88928571 | L32: =J32/27 -> 0.092222222
A33: Sa2 | B33: 313 | C33: 2.71 | D33: 2.86 | E33: 5.31 | F33: =D33-C33 -> 0.15 | G33: =F33/C33 -> 0.055350554 | H33: =F33/(9*6) -> 0.0027777778 | I33: =F33/27 -> 0.0055555556 | J33: =E33-D33 -> 2.45 | K33: =J33/D33 -> 0.85664336 | L33: =J33/27 -> 0.090740741
A34: Sa2 | B34: 314 | C34: 2.71 | D34: 2.86 | E34: 5.41 | F34: =D34-C34 -> 0.15 | G34: =F34/C34 -> 0.055350554 | H34: =F34/(9*6) -> 0.0027777778 | I34: =F34/27 -> 0.0055555556 | J34: =E34-D34 -> 2.55 | K34: =J34/D34 -> 0.89160839 | L34: =J34/27 -> 0.094444444
A35: Sa2 | B35: 315 | C35: 2.72 | D35: 2.9 | E35: 5.48 | F35: =D35-C35 -> 0.18 | G35: =F35/C35 -> 0.066176471 | H35: =F35/(9*6) -> 0.0033333333 | I35: =F35/27 -> 0.0066666667 | J35: =E35-D35 -> 2.58 | K35: =J35/D35 -> 0.88965517 | L35: =J35/27 -> 0.095555556
A36: Sa2 | B36: 276 | C36: 2.72 | D36: 2.87 | E36: 5.2 | F36: =D36-C36 -> 0.15 | G36: =F36/C36 -> 0.055147059 | H36: =F36/(9*6) -> 0.0027777778 | I36: =F36/27 -> 0.0055555556 | J36: =E36-D36 -> 2.33 | K36: =J36/D36 -> 0.81184669 | L36: =J36/27 -> 0.086296296
A37: Sa2 | B37: 277 | C37: 2.78 | D37: 2.94 | E37: 5.24 | F37: =D37-C37 -> 0.16 | G37: =F37/C37 -> 0.057553957 | H37: =F37/(9*6) -> 0.002962963 | I37: =F37/27 -> 0.0059259259 | J37: =E37-D37 -> 2.3 | K37: =J37/D37 -> 0.78231293 | L37: =J37/27 -> 0.085185185
... A71: Sa4 | B71: 159 | C71: 2.41 | D71: 2.47 | E71: 4.79 | F71: =D71-C71 -> 0.06 | G71: =F71/C71 -> 0.024896266 | H71: =F71/(9*6) -> 0.0011111111 | I71: =F71/27 -> 0.0022222222 | J71: =E71-D71 -> 2.32 | K71: =J71/D71 -> 0.93927126 | L71: =J71/27 -> 0.085925926
A72: Sa4 | B72: 160 | C72: 2.33 | D72: 2.19 | F72: =D72-C72 -> -0.14 | G72: =F72/C72 -> -0.060085837 | H72: =F72/(9*6) -> -0.0025925926 | I72: =F72/27 -> -0.0051851852
A73: Sa4 | B73: 251 | C73: 2.08 | D73: 2.36 | E73: 4.42 | F73: =D73-C73 -> 0.28 | G73: =F73/C73 -> 0.13461538 | H73: =F73/(9*6) -> 0.0051851852 | I73: =F73/27 -> 0.01037037 | J73: =E73-D73 -> 2.06 | K73: =J73/D73 -> 0.87288136 | L73: =J73/27 -> 0.076296296
A74: Sa4 | B74: 252 | C74: 2.22 | D74: 2.15 | E74: 4.71 | F74: =D74-C74 -> -0.07 | G74: =F74/C74 -> -0.031531532 | H74: =F74/(9*6) -> -0.0012962963 | I74: =F74/27 -> -0.0025925926 | J74: =E74-D74 -> 2.56 | K74: =J74/D74 -> 1.1906977 | L74: =J74/27 -> 0.094814815
A75: Sa4 | B75: 253 | C75: 2.16 | D75: 2.09 | E75: 4.43 | F75: =D75-C75 -> -0.07 | G75: =F75/C75 -> -0.032407407 | H75: =F75/(9*6) -> -0.0012962963 | I75: =F75/27 -> -0.0025925926 | J75: =E75-D75 -> 2.34 | K75: =J75/D75 -> 1.1196172 | L75: =J75/27 -> 0.086666667
...

Sheet tab videjie
C1: 80 | H1: 20 | O1: 74 | X1: 8
B2: SA | C2: n=80 | H2: n=20 | N2: hit+SA | O2: n=76 | X2: n=20
B3: kubiņa nr | C3: uzņemtā sub. Sk. | D3: sub. sk. g/g MK | E3: sub. sk. g/cm3 | H3: stieņa nr | I3: uzņemtā sub. Sk. | J3: sub. sk. g/g MK | K3: sub. sk. g/cm3 | N3: kubiņa nr | O3: Uzņemtais hito. | P3: hito g/g MK | Q3: hito g/cm2 | R3: hito g/cm3 | S3: uzņemtā sub. Sk. | T3: sub. sk. g/g MK | U3: sub. sk. g/cm3 | W3: stieņa nr | X3: Uzņemtais hito. | Y3: hito g/g MK | Z3: hito g/cm2 | AA3: hito h/cm3 | AB3: uzņemtā sub. Sk. | AC3: sub. sk. g/g MK | AD3: sub. sk. g/cm3
A4: Sl1 | B4: 3 | C4: 2.62 | D4: 0.58222222 | E4: 0.097037037 | M4: Sl1 | N4: 1 | O4: 0.28 | P4: 0.058577406 | Q4: 0.0051851852 | R4: 0.01037037 | S4: 1.91 | T4: 0.37747036 | U4: 0.070740741 | V4: Sl1 | W4: 2 | X4: 0.56 | Y4: 0.02173913 | Z4: 0.0025225225 | AA4: 0.0036601307 | AB4: 11.71 | AC4: 0.44490881 | AD4: 0.076535948
B5: 4 | C5: 2.57 | D5: 0.55150215 | E5: 0.095185185 | G5: Sl1 | H5: 1 | I5: 13.65 | J5: 0.53257901 | K5: 0.089215686 | N5: 2 | O5: 0.25 | P5: 0.057077626 | Q5: 0.0046296296 | R5: 0.0092592593 | S5: 2.26 | T5: 0.48812095 | U5: 0.083703704 | W5: 6 | X5: 0.48 | Y5: 0.018334607 | Z5: 0.0021621622 | AA5: 0.0031372549 | AB5: 12.63 | AC5: 0.47374344 | AD5: 0.08254902
B6: 7 | C6: 2.68 | D6: 0.6036036 | E6: 0.099259259 | H6: 8 | I6: 14.65 | J6: 0.5869391 | K6: 0.095751634 | N6: 5 | O6: 0.24 | P6: 0.053215078 | Q6: 0.0044444444 | R6: 0.0088888889 | S6: 2.45 | T6: 0.51578947 | U6: 0.090740741 | X6: =AVERAGE(X4:X5) -> 0.52 | Y6: =AVERAGE(Y4:Y5) -> 0.020036869 | Z6: =AVERAGE(Z4:Z5) -> 0.0023423423 | AA6: =AVERAGE(AA4:AA5) -> 0.0033986928 | AB6: =AVERAGE(AB4:AB5) -> 12.17 | AC6: =AVERAGE(AC4:AC5) -> 0.45932613 | AD6: =AVERAGE(AD4:AD5) -> 0.079542484
B7: 8 | C7: 2.55 | D7: 0.56919643 | E7: 0.094444444 | H7: 58 | I7: 12.24 | J7: 0.48842777 | K7: 0.08 | N7: 6 | O7: 0.26 | P7: 0.054968288 | Q7: 0.0048148148 | R7: 0.0096296296 | S7: 2.2 | T7: 0.44088176 | U7: 0.081481481 | V7: Sl2 | W7: 68 | X7: 0.7 | Y7: 0.037017451 | Z7: 0.0031531532 | AA7: 0.0045751634 | AB7: 14.43 | AC7: 0.73584906 | AD7: 0.094313725
B8: 9 | C8: 2.22 | D8: 0.48051948 | E8: 0.082222222 | H8: 63 | I8: 13.46 | J8: 0.54405821 | K8: 0.087973856 | N8: 10 | O8: 0.3 | P8: 0.063559322 | Q8: 0.0055555556 | R8: 0.011111111 | S8: 2.28 | T8: 0.45418327 | U8: 0.084444444 | W8: 71 | X8: 0.82 | Y8: 0.04357067 | Z8: 0.0036936937 | AA8: 0.0053594771 | AB8: 15.03 | AC8: 0.76527495 | AD8: 0.098235294
B9: 12 | C9: 2.39 | D9: 0.52643172 | E9: 0.088518519 | H9: 65 | I9: 14.63 | J9: 0.60404624 | K9: 0.095620915 | N9: 11 | O9: 0.24 | P9: 0.050420168 | Q9: 0.0044444444 | R9: 0.0088888889 | S9: 1.91 | T9: 0.382 | U9: 0.070740741 | X9: =AVERAGE(X7:X8) -> 0.76 | Y9: =AVERAGE(Y7:Y8) -> 0.04029406 | Z9: =AVERAGE(Z7:Z8) -> 0.0034234234 | AA9: =AVERAGE(AA7:AA8) -> 0.0049673203 | AB9: =AVERAGE(AB7:AB8) -> 14.73 | AC9: =AVERAGE(AC7:AC8) -> 0.750562 | AD9: =AVERAGE(AD7:AD8) -> 0.09627451
B10: 13 | C10: 2.38 | D10: 0.52078775 | E10: 0.088148148 | I10: =AVERAGE(I5:I9) -> 13.726 | J10: =AVERAGE(J5:J9) -> 0.55121007 | K10: =AVERAGE(K5:K9) -> 0.089712418 | N10: 14 | O10: 0.28 | P10: 0.060215054 | Q10: 0.0051851852 | R10: 0.01037037 | S10: 2.26 | T10: 0.45841785 | U10: 0.083703704 | V10: Sl3 | W10: 82 | X10: 0.79 | Y10: 0.028356066 | Z10: 0.0035585586 | AA10: 0.0051633987 | AB10: 14.14 | AC10: 0.49354276 | AD10: 0.092418301
B11: 18 | C11: 2.71 | D11: 0.43993506 | E11: 0.10037037 | G11: Sl2 | H11: 11 | I11: 13.09 | J11: 0.69295924 | K11: 0.085555556 | N11: 16 | O11: 0.21 | P11: 0.047085202 | Q11: 0.0038888889 | R11: 0.0077777778 | S11: 1.99 | T11: 0.4261242 | U11: 0.073703704 | W11: 85 | X11: 0.27 | Y11: 0.0096601073 | Z11: 0.0012162162 | AA11: 0.0017647059 | AB11: 15.28 | AC11: 0.54145996 | AD11: 0.099869281
B12: 21 | C12: 2.61 | D12: 0.61556604 | E12: 0.096666667 | H12: 19 | I12: 13.73 | J12: 0.70374167 | K12: 0.089738562 | N12: 17 | O12: 0.24 | P12: 0.055172414 | Q12: 0.0044444444 | R12: 0.0088888889 | S12: 2.59 | T12: 0.56427015 | U12: 0.095925926 | X12: =AVERAGE(X10:X11) -> 0.53 | Y12: =AVERAGE(Y10:Y11) -> 0.019008087 | Z12: =AVERAGE(Z10:Z11) -> 0.0023873874 | AA12: =AVERAGE(AA10:AA11) -> 0.0034640523 | AB12: =AVERAGE(AB10:AB11) -> 14.71 | AC12: =AVERAGE(AC10:AC11) -> 0.51750136 | AD12: =AVERAGE(AD10:AD11) -> 0.096143791
B13: 22 | C13: 2.65 | D13: 0.6206089 | E13: 0.098148148 | H13: 69 | I13: 14.38 | J13: 0.74662513 | K13: 0.093986928 | N13: 19 | O13: 0.24 | P13: 0.052401747 | Q13: 0.0044444444 | R13: 0.0088888889 | S13: 2.48 | T13: 0.51452282 | U13: 0.091851852 | V13: Sl4 | W13: 38 | X13: 1.3 | Y13: 0.047445255 | Z13: 0.0058558559 | AA13: 0.008496732 | AB13: 15.29 | AC13: 0.53275261 | AD13: 0.099934641
B14: 23 | C14: 2.47 | D14: 0.56392694 | E14: 0.091481481 | H14: 73 | I14: 15.49 | J14: 0.8092999 | K14: 0.10124183 | N14: 20 | O14: 0.24 | P14: 0.049689441 | Q14: 0.0044444444 | R14: 0.0088888889 | S14: 1.9 | T14: 0.37475345 | U14: 0.07037037 | W14: 45 | X14: 0.97 | Y14: 0.035247093 | Z14: 0.0043693694 | AA14: 0.0063398693 | AB14: 16.6 | AC14: 0.58266058 | AD14: 0.10849673
